Workbook

Sheet GESTION MOMENTUM
A1: FONDOS COMUNES DE INVERSION
A2: 30/10/2026
A3: 10:19:45
A4: Informe de Gestión al 29/10/2026 | K4: MOMENTUM
A5: FCI ABIERTO MOMENTUM PYMES | K5: COMAFI $ Nº 24148/3
A6: Todos los importes están expresados en Pesos | K6: BANCO DEL SOL
C7: (4) | D7: (1) | L7: 46325 | M7: =WORKDAY(L7,1,$R:$R) -> 46328 | N7: =WORKDAY(M7,1,$R:$R) -> 46329 | R7: 45719 | S7: Lista de feriados 2025
A8: ACTIVO | B8: 8.2418646e+10 | C8: 100 | K8: Caucion MAV | L8: 2.0011378e+09 | R8: 45720
A9: INVERSIONES | B9: 7.9614068e+10 | C9: 96.6 | D9: 97.44 | K9: Caucion Byma | R9: 45740
A10: TITULOS PUBLICOS | B10: 1097044698 | C10: 1.33 | D10: 1.34 | K10: Plazo Fijo | L10: =SUMIFS(F:F,A:A,$K$10,B:B,L7) -> 0 | M10: =SUMIFS(G:G,B:B,$K$10,C:C,M7) -> 0 | N10: =SUMIFS(H:H,C:C,$K$10,D:D,N7) -> 0 | R10: 45749
A11: FUTUROS | B11: -8017217500 | C11: -9.73 | D11: -9.81 | K11: Vto. Cheques | L11: =SUMIF($B$101:$B$2996,L7,$D$101:$D$2996) -> 1.7197252e+09 | M11: =SUMIF($B$101:$B$2996,M7,$D$101:$D$2996) -> 1.5761027e+09 | N11: =SUMIF($B$101:$B$2996,N7,$D$101:$D$2996) -> 2.3416412e+09 | P11: =SUMIF($B$99:$B$1878,P7,$D$99:$D$1878) -> 0 | Q11: =SUMIF($B$99:$B$1878,Q7,$D$99:$D$1878) -> 0 | R11: =SUMIF($B$99:$B$1878,R7,$D$99:$D$1878) -> 0 | S11: =SUMIF($B$99:$B$1878,S7,$D$99:$D$1878) -> 0 | T11: =SUMIF($B$99:$B$1878,T7,$D$99:$D$1878) -> 0
A12: DISPONIBILIDADES | B12: 22697507 | C12: 0.03 | D12: 0.03 | K12: Vto. Pagarés/FCE Dollar Linked | L12: =+SUMIF($B$3000:$B$3040,L7,$F$3000:$F$3040) -> 0 | M12: =+SUMIF($B$3000:$B$3040,M7,$F$3000:$F$3040) -> 0 | N12: =+SUMIF($B$3000:$B$3040,N7,$F$3000:$F$3040) -> 0 | R12: 45778
A13: EN PESOS | B13: 22697815 | C13: 0.03 | D13: 0.03 | J13: 0.1914 | K13: FCI IEB Ahorro - Clase E | L13: =SUMIF(A:A,K13,E:E)*(1+(J13/365)*1) -> 2.1241133e+09 | R13: 45779
A14: EN DOLARES | B14: -307.92 | C14: 0 | D14: 0 | K14: COMAFI $ Nº 24148/3 | L14: =+B13 -> 22697815 | R14: 45802
A15: CREDITOS | B15: 2.7818804e+09 | C15: 3.38 | D15: 3.4 | K15: Ctte Momentum | L15: 19578500 | R15: 45824
A16: PASIVO | B16: -7.1025901e+08 | K16: Cheques pendientes | R16: 45828
A17: PROVISIONES | B17: -1.7881313e+08 | K17: Compra/Venta Bonos | R17: 45847
A18: PROV. HONORARIOS SOC. DEPOSITARIA | B18: -10375743 | K18: TOTAL | L18: =SUM(L8:L17) -> 5.8872526e+09 | R18: 45884
A19: PROV. HONORARIOS SOCIEDAD GERENTE | B19: -1.5312489e+08 | K19: Neg. Cheques / Pagare | R19: 45886
A20: PROV. GASTOS SOCIEDAD DEPOSITARIA | B20: -15312489 | K20: Coloca caucion MAV | R20: 45942
A21: DEUDAS EN PESOS | B21: -5.2622709e+08 | K21: Compra/Venta de Bonos | R21: 45982
A22: RESCATES | B22: -84000000 | J22: EGRESOS EN EL DIA Clase B | K22: Suscripciones | R22: 45985
A23: PREVISIÓN INCOBRABLES | B23: -4.4018937e+08 | K23: Rescates | L23: =SUMIF(A:A,K23,B:B) -> -84000000 | R23: 45999
A24: Valor Patrimonial del Fondo | B24: 8.1708387e+10 | K24: Pase | R24: 46016
A25: Liquidez Efectiva (2) | B25: 2.273132e+09 | D25: 2.78 | K25: Rentas y Amortizaciones
A26: Liquidez Corriente (3) | B26: 2.0943189e+09 | D26: 2.56 | K26: Pago de honorarios ACDI
K27: Caja cierre | L27: =SUM(L18:L26) -> 5.8032526e+09 | M27: =SUM(M8:M26) -> 1.5761027e+09 | N27: =SUM(N8:N26) -> 2.3416412e+09
A41: Inversiones
A42: TITULO PUBLICO en Pesos
A43: Denominación | B43: IsinCode | C43: Cantidad | D43: Cierre | E43: Total | F43: % (1) | G43: Costo | H43: Var | I43: Vencimiento
A44: Lecap S30N6 | B44: AR0451031345 | C44: 500000000 | D44: 1.2745 | E44: 637261975 | F44: 0.78 | G44: 0 | I44: 30/11/2026
A45: TMG28 - Bono del Tesoro Nacional | B45: AR0175438917 | C45: 600000000 | D45: 1.1025 | E45: 661501302 | F45: 0.81 | G45: 0 | I45: 31/01/2028
C46: 1100000000 | E46: 1298763277 | F46: 1.59
A48: OBLIGACIONES NEGOCIABLES en Pesos
A49: Denominación | B49: IsinCode | C49: Cantidad | D49: Cierre | E49: Total | F49: % (1) | G49: Costo | H49: Var | I49: Vencimiento
A50: LR8AO - ON Laboratorios Richmond Serie 8 Clase A | B50: AR0266435707 | C50: 300000000 | D50: 1.1273 | E50: 338192253 | F50: 0.41 | G50: 0 | I50: 31/07/2028
A51: MTC3O - ON Mastellone Clase 3 | B51: AR0494875476 | C51: 250000000 | D51: 1.016 | E51: 253988325 | F51: 0.31 | G51: 1 | H51: 1.6 | I51: 22/06/2027
C52: 550000000 | E52: 592180578 | F52: 0.72
A54: FIDEICOMISOS FINANCIEROS en Pesos
A55: Denominación | B55: IsinCode | C55: Cantidad | D55: Cierre | E55: Total | F55: % (1) | G55: Costo | H55: Var | I55: Vencimiento
...

Sheet Parametros
A1: Min | B1: 0.75 | C1: en Pymes | D1: =+B1*(VLOOKUP($E$1,'GESTION MOMENTUM'!$A$8:$B$32,2,0)) -> 6.128129e+10 | E1: Valor Patrimonial del Fondo | G1: PN actual | H1: P&L | I1: PN reservado
A2: Max | B2: 0.05 | C2: Money Market | D2: =+B2*(VLOOKUP($E$1,'GESTION MOMENTUM'!$A$8:$B$32,2,0)) -> 4.0854193e+09 | G2: =VLOOKUP(E1,'GESTION MOMENTUM'!A8:B32,2,0) -> 8.1708387e+10 | H2: -0.002 | I2: =+G2*(1+H2) -> 8.154497e+10
A3: Max | B3: 0.2 | C3: PFRemuneradasCaucion | D3: =+B3*(VLOOKUP($E$1,'GESTION MOMENTUM'!$A$8:$B$32,2,0)) -> 1.6341677e+10 | G3: Money Market | H3: 0.05 | I3: =+I2*H3 -> 4.0772485e+09
A4: Max | B4: 0.2 | C4: cheques x librador | D4: =+B4*(VLOOKUP($E$1,'GESTION MOMENTUM'!$A$8:$B$32,2,0)) -> 1.6341677e+10
A5: Max | B5: 0.25 | C5: x titulo en Pymes | D5: =+B5*(VLOOKUP($E$1,'GESTION MOMENTUM'!$A$8:$B$32,2,0)) -> 2.0427097e+10
B8: Garantías RFX (MOMENTUM)
B9: Bono | C9: VN | D9: Precio | E9: Aforo | F9: $
B10: TMG28 - Bono del Tesoro Nacional | C10: 600000000 | D10: =+VLOOKUP(B10,'GESTION MOMENTUM'!A:D,4,0) -> 1.1025 | E10: 0.8 | F10: =C10*D10*E10 -> 529200000
B11: Lecap S30N6 | C11: 500000000 | D11: =+VLOOKUP(B11,'GESTION MOMENTUM'!A:D,4,0) -> 1.2745 | E11: 0.8 | F11: =C11*D11*E11 -> 509800000
E13: Garantia | F13: =SUM(F10:F12) -> 1039000000
B15: Garantías | C15: Total $ por contrato | D15: Contratos a shortear | E15: Contratos Shorteados | F15: Garantia Requerida
A16: Fut Rofex DLR102026 | B16: Octubre | C16: 155000 | D16: 0 | E16: =_xlfn.IFNA(-VLOOKUP(A16,'GESTION MOMENTUM'!A:C,3,0)/1000,0) -> 1357 | F16: =+C16*(E16+D16) -> 210335000
A17: Fut Rofex DLR112026 | B17: Noviembre | C17: 160000 | D17: 0 | E17: =_xlfn.IFNA(-VLOOKUP(A17,'GESTION MOMENTUM'!A:C,3,0)/1000,0) -> 750 | F17: =+C17*(E17+D17) -> 120000000
A18: Fut Rofex DLR122026 | B18: Diciembre | C18: 165000 | E18: =_xlfn.IFNA(-VLOOKUP(A18,'GESTION MOMENTUM'!A:C,3,0)/1000,0) -> 923 | F18: =+C18*(E18+D18) -> 152295000
B19: Enero
B20: Febrero
B21: Marzo
A22: Fut Rofex DLR042027 | B22: Abril | C22: 180000 | D22: 0 | E22: =_xlfn.IFNA(-VLOOKUP(A22,'GESTION MOMENTUM'!A:C,3,0)/1000,0) -> 1800 | F22: =+C22*(E22+D22) -> 324000000
F23: =+SUM(F16:F22) -> 806630000
B24: Saldo de Garantias | C24: =F13-F23 -> 232370000

Sheet Cheques pendientes
A1: FONDO | B1: CHPD | C1: VTO | D1: MONEDA | E1: MONTO | F1: MONTO $ | G1: ESTADO | H1: LIBRADOR | I1: DIAS DE MORA
A2: AMOMPY | B2: *MAV030300645 | C2: 45723 | D2: $ | E2: 3406250 | G2: PREVISIONADO | H2: UKUMARI SOCIEDAD ANONIMA. | I2: =+TODAY()-C2 -> 602 | U2: LIBRADORES PENDIENTES
A3: AMOMPY | B3: *MAV100300802 | C3: 45728 | D3: $ | E3: 3406250 | G3: PREVISIONADO | H3: UKUMARI SOCIEDAD ANONIMA. | I3: =+TODAY()-C3 -> 597 | U3: {=+_xlfn.UNIQUE(H2:H78)} -> UKUMARI SOCIEDAD ANONIMA. | V3: =+SUMIF(H:H,U3,E:E) -> 6812500
A4: AMOMPY | B4: *MAV200500842 | C4: 45799 | D4: $ | E4: 129185000 | G4: PENDIENTE | H4: NIRO CONSTRUYE S. A. | I4: =+TODAY()-C4 -> 526 | U4: NIRO CONSTRUYE S. A. | V4: =+SUMIF(H:H,U4,E:E) -> 258370000
A5: AMOMPY | B5: *MAV300500862 | C5: 45811 | D5: $ | E5: 129185000 | G5: PREVISIONADO | H5: NIRO CONSTRUYE S. A. | I5: =+TODAY()-C5 -> 514 | U5: MERCOL RAUL ALBERTO Y MERCOL MAURICIO EDUARDO. | V5: =+SUMIF(H:H,U5,E:E) -> 62500000
A6: AMOMPY | B6: *MAV091000727 | C6: 45943 | D6: $ | E6: 12500000 | G6: PENDIENTE | H6: MERCOL RAUL ALBERTO Y MERCOL MAURICIO EDUARDO. | I6: =+TODAY()-C6 -> 382 | U6: AKAI ENERGY LED SRL | V6: =+SUMIF(H:H,U6,E:E) -> 44963000
A7: AMOMPY | B7: *MAV031100940 | C7: 45966 | D7: $ | E7: 4400000 | G7: PREVISIONADO | H7: AKAI ENERGY LED SRL | I7: =+TODAY()-C7 -> 359 | U7: FRIGORIFICO GENERAL PICO S A | V7: =+SUMIF(H:H,U7,E:E) -> 70000000
A8: AMOMPY | B8: *MAV041100892 | C8: 45968 | D8: $ | E8: 4400000 | G8: PREVISIONADO | H8: AKAI ENERGY LED SRL | I8: =+TODAY()-C8 -> 357 | K8: Valor Patrimonial del Fondo | L8: =+VLOOKUP(K8,'GESTION MOMENTUM'!A:B,2,0) -> 8.1708387e+10 | U8: MIANI CLARA A Y MIANI ADA CLELIA | V8: =+SUMIF(H:H,U8,E:E) -> 3125000
A9: AMOMPY | B9: *MAV051100567 | C9: 45971 | D9: $ | E9: 25000000 | G9: PENDIENTE | H9: MERCOL RAUL ALBERTO Y MERCOL MAURICIO EDUARDO. | I9: =+TODAY()-C9 -> 354 | U9: PORT PLA S.R.L. | V9: =+SUMIF(H:H,U9,E:E) -> 150000000
A10: AMOMPY | B10: *MAV051100722 | C10: 45971 | D10: $ | E10: 4400000 | G10: PREVISIONADO | H10: AKAI ENERGY LED SRL | I10: =+TODAY()-C10 -> 354 | L10: $ | M10: % PN | U10: MASTER DESIGN HOME SRL | V10: =+SUMIF(H:H,U10,E:E) -> 24000000
A11: AMOMPY | B11: *MAV071100935 | C11: 45972 | D11: $ | E11: 4400000 | G11: PREVISIONADO | H11: AKAI ENERGY LED SRL | I11: =+TODAY()-C11 -> 353 | K11: PREVISIÓN INCOBRABLES | L11: =+VLOOKUP(K11,'GESTION MOMENTUM'!A:B,2,0) -> -4.4018937e+08 | M11: =+L11/L8 -> -0.0053873217 | U11: GROCAL S.A. | V11: =+SUMIF(H:H,U11,E:E) -> 15000000
A12: AMOMPY | B12: *MAV111100890 | C12: 45974 | D12: $ | E12: 963000 | G12: PREVISIONADO | H12: AKAI ENERGY LED SRL | I12: =+TODAY()-C12 -> 351 | K12: PREVISIONADO | L12: =+SUMIF(G:G,K12,E:E) -> 391310500 | U12: Paccioli Group Sociedad Anonima | V12: =+SUMIF(H:H,U12,E:E) -> 13958000
A13: AMOMPY | B13: *MAV121100854 | C13: 45975 | D13: $ | E13: 4400000 | G13: PREVISIONADO | H13: AKAI ENERGY LED SRL | I13: =+TODAY()-C13 -> 350 | K13: Prevision a aplicar | L13: =+L11+L12 -> -48878868 | U13: FINEX CABA S. A. | V13: =+SUMIF(H:H,U13,E:E) -> 55300000
A14: AMOMPY | B14: *MAV121100675 | C14: 45975 | D14: $ | E14: 25000000 | G14: PENDIENTE | H14: MERCOL RAUL ALBERTO Y MERCOL MAURICIO EDUARDO. | I14: =+TODAY()-C14 -> 350 | U14: TRADICION VALORES S.A. | V14: =+SUMIF(H:H,U14,E:E) -> 25000000
A15: AMOMPY | B15: *MAV141101053 | C15: 45979 | D15: $ | E15: 4400000 | G15: PREVISIONADO | H15: AKAI ENERGY LED SRL | I15: =+TODAY()-C15 -> 346 | K15: PENDIENTE | L15: =+SUMIF(G:G,K15,E:E)+E2 -> 2332411780 | M15: =+SUMIF(G:G,K15,E:E)/$L$8 -> 0.028503874 | U15: Maradona Wines | V15: =+SUMIF(H:H,U15,E:E) -> 119500000
A16: AMOMPY | B16: *MAV141101054 | C16: 45979 | D16: $ | E16: 4400000 | G16: PREVISIONADO | H16: AKAI ENERGY LED SRL | I16: =+TODAY()-C16 -> 346 | U16: LOPEZ LUCIA SOLEDAD | V16: =+SUMIF(H:H,U16,E:E) -> 995000
A17: AMOMPY | B17: *MAV171100932 | C17: 45980 | D17: $ | E17: 4400000 | G17: PREVISIONADO | H17: AKAI ENERGY LED SRL | I17: =+TODAY()-C17 -> 345 | U17: RABU INVERSIONES SRL | V17: =+SUMIF(H:H,U17,E:E) -> 7194300
A18: AMOMPY | B18: *MAV151101337 | C18: 45980 | D18: $ | E18: 4400000 | G18: PREVISIONADO | H18: AKAI ENERGY LED SRL | I18: =+TODAY()-C18 -> 345 | U18: GROUP DIEZ S.A. | V18: =+SUMIF(H:H,U18,E:E) -> 425000000
A19: AMOMPY | B19: *MAV181100869 | C19: 45981 | D19: $ | E19: 4400000 | G19: PREVISIONADO | H19: AKAI ENERGY LED SRL | I19: =+TODAY()-C19 -> 344 | U19: INVLAC CONSTRUCCIONES S.R.L | V19: =+SUMIF(H:H,U19,E:E) -> 4000000
A20: AMOMPY | B20: *MAV181100773 | C20: 45981 | D20: $ | E20: 20000000 | G20: PREVISIONADO | H20: FRIGORIFICO GENERAL PICO S A | I20: =+TODAY()-C20 -> 344 | K20: LIBRADOR PENDIENTE | L20: $ | M20: % PN | O20: VIGENTE | U20: I-LED ARGENTINA S.A. | V20: =+SUMIF(H:H,U20,E:E) -> 93100000
A21: AMOMPY | B21: *MAV191100661 | C21: 45986 | D21: $ | E21: 20000000 | G21: PREVISIONADO | H21: FRIGORIFICO GENERAL PICO S A | I21: =+TODAY()-C21 -> 339 | K21: {=+_xlfn._xlws.SORT(U3:V34,2,-1)} -> GROUP DIEZ S.A. | L21: 425000000 | M21: =+L21/$L$8 -> 0.0052014244 | O21: =+SUMIF('Reporte de Cheques'!A:A,'Cheques pendientes'!K21,'Reporte de Cheques'!I:I) -> 0 | V21: =+SUMIF(H:H,U21,E:E) -> 0
A22: AMOMPY | B22: *MAV201100887 | C22: 45987 | D22: $ | E22: 10000000 | G22: PREVISIONADO | H22: FRIGORIFICO GENERAL PICO S A | I22: =+TODAY()-C22 -> 338 | K22: NIRO CONSTRUYE S. A. | L22: 258370000 | M22: =+L22/$L$8 -> 0.0031620989 | O22: =+SUMIF('Reporte de Cheques'!A:A,'Cheques pendientes'!K22,'Reporte de Cheques'!I:I) -> 0 | V22: =+SUMIF(H:H,U22,E:E) -> 0
A23: AMOMPY | B23: *MAV211100687 | C23: 45988 | D23: $ | E23: 10000000 | G23: PREVISIONADO | H23: FRIGORIFICO GENERAL PICO S A | I23: =+TODAY()-C23 -> 337 | K23: PORT PLA S.R.L. | L23: 150000000 | M23: =+L23/$L$8 -> 0.0018357969 | O23: =+SUMIF('Reporte de Cheques'!A:A,'Cheques pendientes'!K23,'Reporte de Cheques'!I:I) -> 0 | V23: =+SUMIF(H:H,U23,E:E) -> 0
A24: AMOMPY | B24: *MAV221100992 | C24: 45988 | D24: $ | E24: 10000000 | G24: PREVISIONADO | H24: FRIGORIFICO GENERAL PICO S A | I24: =+TODAY()-C24 -> 337 | K24: Maradona Wines | L24: 119500000 | M24: =+L24/$L$8 -> 0.0014625182 | O24: =+SUMIF('Reporte de Cheques'!A:A,'Cheques pendientes'!K24,'Reporte de Cheques'!I:I) -> 0 | V24: =+SUMIF(H:H,U24,E:E) -> 0
A25: AMOMPY | B25: *MAV271100809 | C25: 45992 | D25: $ | E25: 3125000 | G25: PENDIENTE | H25: MIANI CLARA A Y MIANI ADA CLELIA | I25: =+TODAY()-C25 -> 333 | K25: I-LED ARGENTINA S.A. | L25: 93100000 | M25: =+L25/$L$8 -> 0.0011394179 | O25: =+SUMIF('Reporte de Cheques'!A:A,'Cheques pendientes'!K25,'Reporte de Cheques'!I:I) -> 0 | V25: =+SUMIF(H:H,U25,E:E) -> 0
A26: AMOMPY | B26: *MAV291101201 | C26: 45994 | D26: $ | E26: 25000000 | G26: PENDIENTE | H26: PORT PLA S.R.L. | I26: =+TODAY()-C26 -> 331 | K26: FRIGORIFICO GENERAL PICO S A | L26: 70000000 | M26: =+L26/$L$8 -> 0.0008567052 | O26: =+SUMIF('Reporte de Cheques'!A:A,'Cheques pendientes'!K26,'Reporte de Cheques'!I:I) -> 0 | V26: =+SUMIF(H:H,U26,E:E) -> 0
A27: AMOMPY | B27: *MAV171200694 | C27: 46010 | D27: $ | E27: 6000000 | G27: PREVISIONADO | H27: MASTER DESIGN HOME SRL | I27: =+TODAY()-C27 -> 315 | K27: MERCOL RAUL ALBERTO Y MERCOL MAURICIO EDUARDO. | L27: 62500000 | M27: =+L27/$L$8 -> 0.00076491536 | O27: =+SUMIF('Reporte de Cheques'!A:A,'Cheques pendientes'!K27,'Reporte de Cheques'!I:I) -> 0 | V27: =+SUMIF(H:H,U27,E:E) -> 0
A28: AMOMPY | B28: *MAV291200938 | C28: 46024 | D28: $ | E28: 25000000 | G28: PENDIENTE | H28: PORT PLA S.R.L. | I28: =+TODAY()-C28 -> 301 | K28: FINEX CABA S. A. | L28: 55300000 | M28: =+L28/$L$8 -> 0.00067679711 | O28: =+SUMIF('Reporte de Cheques'!A:A,'Cheques pendientes'!K28,'Reporte de Cheques'!I:I) -> 0 | V28: =+SUMIF(H:H,U28,E:E) -> 0
A29: AMOMPY | B29: *MAV020100774 | C29: 46028 | D29: $ | E29: 10000000 | G29: PENDIENTE | H29: PORT PLA S.R.L. | I29: =+TODAY()-C29 -> 297 | K29: AKAI ENERGY LED SRL | L29: 44963000 | M29: =+L29/$L$8 -> 0.00055028623 | O29: =+SUMIF('Reporte de Cheques'!A:A,'Cheques pendientes'!K29,'Reporte de Cheques'!I:I) -> 0 | V29: =+SUMIF(H:H,U29,E:E) -> 0
A30: AMOMPY | B30: *MAV311200688 | C30: 46028 | D30: $ | E30: 6000000 | G30: PREVISIONADO | H30: MASTER DESIGN HOME SRL | I30: =+TODAY()-C30 -> 297 | K30: TRADICION VALORES S.A. | L30: 25000000 | M30: =+L30/$L$8 -> 0.00030596614 | O30: =+SUMIF('Reporte de Cheques'!A:A,'Cheques pendientes'!K30,'Reporte de Cheques'!I:I) -> 0 | V30: =+SUMIF(H:H,U30,E:E) -> 0
A31: AMOMPY | B31: *MAV050100914 | C31: 46029 | D31: $ | E31: 10000000 | G31: PENDIENTE | H31: PORT PLA S.R.L. | I31: =+TODAY()-C31 -> 296 | K31: MASTER DESIGN HOME SRL | L31: 24000000 | M31: =+L31/$L$8 -> 0.0002937275 | O31: =+SUMIF('Reporte de Cheques'!A:A,'Cheques pendientes'!K31,'Reporte de Cheques'!I:I) -> 0 | V31: =+SUMIF(H:H,U31,E:E) -> 0
A32: AMOMPY | B32: *MAV090100782 | C32: 46035 | D32: $ | E32: 10000000 | G32: PENDIENTE | H32: PORT PLA S.R.L. | I32: =+TODAY()-C32 -> 290 | K32: GROCAL S.A. | L32: 15000000 | M32: =+L32/$L$8 -> 0.00018357969 | O32: =+SUMIF('Reporte de Cheques'!A:A,'Cheques pendientes'!K32,'Reporte de Cheques'!I:I) -> 0 | V32: =+SUMIF(H:H,U32,E:E) -> 0
A33: AMOMPY | B33: *MAV120100963 | C33: 46036 | D33: $ | E33: 10000000 | G33: PENDIENTE | H33: PORT PLA S.R.L. | I33: =+TODAY()-C33 -> 289 | K33: Paccioli Group Sociedad Anonima | L33: 13958000 | M33: =+L33/$L$8 -> 0.00017082702 | O33: =+SUMIF('Reporte de Cheques'!A:A,'Cheques pendientes'!K33,'Reporte de Cheques'!I:I) -> 0 | V33: =+SUMIF(H:H,U33,E:E) -> 0
A34: AMOMPY | B34: *MAV120101031 | C34: 46036 | D34: $ | E34: 5000000 | G34: PENDIENTE | H34: GROCAL S.A. | I34: =+TODAY()-C34 -> 289 | K34: RABU INVERSIONES SRL | L34: 7194300 | M34: =+L34/$L$8 -> 8.8048489e-05 | O34: =+SUMIF('Reporte de Cheques'!A:A,'Cheques pendientes'!K34,'Reporte de Cheques'!I:I) -> 0 | V34: =+SUMIF(H:H,U34,E:E) -> 0
A35: AMOMPY | B35: *MAV140100871 | C35: 46038 | D35: $ | E35: 5000000 | G35: PENDIENTE | H35: GROCAL S.A. | I35: =+TODAY()-C35 -> 287 | K35: UKUMARI SOCIEDAD ANONIMA. | L35: 6812500 | M35: =+L35/$L$8 -> 8.3375774e-05 | O35: =+SUMIF('Reporte de Cheques'!A:A,'Cheques pendientes'!K35,'Reporte de Cheques'!I:I) -> 0
A36: AMOMPY | B36: *MAV160100849 | C36: 46042 | D36: $ | E36: 10000000 | G36: PENDIENTE | H36: PORT PLA S.R.L. | I36: =+TODAY()-C36 -> 283 | K36: INVLAC CONSTRUCCIONES S.R.L | L36: 4000000 | M36: =+L36/$L$8 -> 4.8954583e-05 | O36: =+SUMIF('Reporte de Cheques'!A:A,'Cheques pendientes'!K36,'Reporte de Cheques'!I:I) -> 0
A37: AMOMPY | B37: *MAV160100806 | C37: 46042 | D37: $ | E37: 4000000 | G37: PREVISIONADO | H37: MASTER DESIGN HOME SRL | I37: =+TODAY()-C37 -> 283 | K37: MIANI CLARA A Y MIANI ADA CLELIA | L37: 3125000 | M37: =+L37/$L$8 -> 3.8245768e-05 | O37: =+SUMIF('Reporte de Cheques'!A:A,'Cheques pendientes'!K37,'Reporte de Cheques'!I:I) -> 0
A38: AMOMPY | B38: *MAV190100896 | C38: 46043 | D38: $ | E38: 10000000 | G38: PENDIENTE | H38: PORT PLA S.R.L. | I38: =+TODAY()-C38 -> 282 | K38: LOPEZ LUCIA SOLEDAD | L38: 995000 | M38: =+L38/$L$8 -> 1.2177453e-05 | O38: =+SUMIF('Reporte de Cheques'!A:A,'Cheques pendientes'!K38,'Reporte de Cheques'!I:I) -> 0
A39: AMOMPY | B39: *MAV200101319 | C39: 46044 | D39: $ | E39: 1395800 | G39: PENDIENTE | H39: Paccioli Group Sociedad Anonima | I39: =+TODAY()-C39 -> 281 | K39: 0 | L39: 0 | M39: =+L39/$L$8 -> 0 | O39: =+SUMIF('Reporte de Cheques'!A:A,'Cheques pendientes'!K39,'Reporte de Cheques'!I:I) -> 0
A40: AMOMPY | B40: *MAV200101320 | C40: 46044 | D40: $ | E40: 1395800 | G40: PENDIENTE | H40: Paccioli Group Sociedad Anonima | I40: =+TODAY()-C40 -> 281 | K40: 0 | L40: 0 | M40: =+L40/$L$8 -> 0 | O40: =+SUMIF('Reporte de Cheques'!A:A,'Cheques pendientes'!K40,'Reporte de Cheques'!I:I) -> 0
...

Sheet Concentración
A4: Suma de %
A5: Sociedad de Garantía Recíproca / Librador | B5: Total
A6: A M F A Y S ASOCIACION MUTUAL | B6: 0.042441666
A7: SES SA | B7: 0.040831459
A8: SIGMA AGRO S.A. | B8: 0.036845088
A9: FIDEICOMISO DORREGO Y LIBERTADOR | B9: 0.032352861
A10: AUTOPISTAS URBANAS SA | B10: 0.029617112
A11: COM & LOG SA | B11: 0.02820532
A12: AESA ASEO Y ECOLOGIA SA | B12: 0.024601958
A13: ESPECIALIDADES AGROPECUARIAS S.A. | B13: 0.022141538
A14: KOMPASS SRL | B14: 0.021048406
A15: SUPERLIGA PROFESIONAL DEL FUTBOL ARGENTINO ASOCIACION CIVIL | B15: 0.01933571
A16: WTS DEL SUR SRL | B16: 0.017023679
A17: TEXTUM SA | B17: 0.014744776
... A545: Total general | B545: 0.8935522

Sheet Reporte de Cheques
A1: Reporte de Cheques de Pago Diferido | W1: Valor Patrimonial del Fondo
A2: Cheque de Pago Diferido y Pagaré | B2: Moneda | C2: Cheque de Pago Diferido y Pagaré | D2: Fecha | E2: Precio | F2: Tipo de Cambio (Cheque/Fondo) | G2: Moneda Cheque | H2: Moneda Cheque | I2: Moneda Fondo | J2: Moneda Fondo | K2: Compra | L2: Fondo | M2: Compra | N2: Compra | O2: Compra | P2: Compra | Q2: Vendido | R2: Venta | S2: Venta | T2: Venta | U2: Cheque de Pago Diferido y Pagaré | V2: Cheque de Pago Diferido y Pagaré | W2: =+VLOOKUP(W1,'GESTION MOMENTUM'!A:B,2,0) -> 8.1708387e+10
A3: Sociedad de Garantía Recíproca / Librador | B3: Descripción | C3: Fecha de Vencimiento | D3: Fecha | E3: Precio | F3: Tipo de Cambio (Cheque/Fondo) | G3: Importe Nominal | H3: Importe Actual | I3: Importe Nominal | J3: Importe Actual | K3: Nro. de Operación | L3: Nombre | M3: Agente | N3: Fecha Concertación | O3: Fecha Liquidación | P3: Tasa de Descuento | Q3: Vendido | R3: Nro. de Operación | S3: Fecha Concertación | T3: Fecha Liquidación | U3: Abreviatura | V3: Código CAFCI | W3: %
A4: TREND SGR | B4: Pesos | C4: 46324 | D4: 29/10/2026 | E4: 1 | G4: 15000000 | H4: 15000000 | I4: 15000000 | J4: 15000000 | K4: 69911131 | L4: AMOMPY | M4: Momentum Capital Investment S.A. | N4: 23/09/2026 | O4: 23/09/2026 | P4: 25 | Q4: No | U4: *TRD271000035 | V4: *TRD271000035 | W4: =+J4/$W$2 -> 0.00018357969
A5: Vinculos S.G.R. | B5: Pesos | C5: 46324 | D5: 29/10/2026 | E5: 1 | G5: 3000000 | H5: 3000000 | I5: 3000000 | J5: 3000000 | K5: 3792078 | L5: AMOMPY | M5: Momentum Capital Investment S.A. | N5: 18/08/2026 | O5: 18/08/2026 | P5: 30 | Q5: No | U5: *AFB271000007 | V5: *AFB271000007 | W5: =+J5/$W$2 -> 3.6715937e-05
A6: Vinculos S.G.R. | B6: Pesos | C6: 46324 | D6: 29/10/2026 | E6: 1 | G6: 31628756 | H6: 31628756 | I6: 31628756 | J6: 31628756 | K6: 22295 | L6: AMOMPY | M6: Momentum Capital Investment S.A. | N6: 15/09/2026 | O6: 15/09/2026 | P6: 30 | Q6: No | U6: *AFB271000013 | V6: *AFB271000013 | W6: =+J6/$W$2 -> 0.00038709314
A7: PAMPA VIDA S.R.L. | B7: Pesos | C7: 46324 | D7: 29/10/2026 | E7: 1 | G7: 3625698.8 | H7: 3625698.8 | I7: 3625698.8 | J7: 3625698.8 | K7: 3346 | L7: AMOMPY | M7: Momentum Capital Investment S.A. | N7: 28/08/2026 | O7: 28/08/2026 | P7: 36 | Q7: No | U7: *MAV271001495 | V7: *MAV271001495 | W7: =+J7/$W$2 -> 4.4373643e-05
A8: PAMPA VIDA S.R.L. | B8: Pesos | C8: 46324 | D8: 29/10/2026 | E8: 1 | G8: 2502550.4 | H8: 2502550.4 | I8: 2502550.4 | J8: 2502550.4 | K8: 3140 | L8: AMOMPY | M8: Momentum Capital Investment S.A. | N8: 23/07/2026 | O8: 23/07/2026 | P8: 33 | Q8: No | U8: *MAV271001362 | V8: *MAV271001362 | W8: =+J8/$W$2 -> 3.0627827e-05
A9: PAMPA VIDA S.R.L. | B9: Pesos | C9: 46324 | D9: 29/10/2026 | E9: 1 | G9: 2502550.4 | H9: 2502550.4 | I9: 2502550.4 | J9: 2502550.4 | K9: 3130 | L9: AMOMPY | M9: Momentum Capital Investment S.A. | N9: 23/07/2026 | O9: 23/07/2026 | P9: 33 | Q9: No | U9: *MAV271001363 | V9: *MAV271001363 | W9: =+J9/$W$2 -> 3.0627827e-05
A10: PAMPA VIDA S.R.L. | B10: Pesos | C10: 46324 | D10: 29/10/2026 | E10: 1 | G10: 1020845.7 | H10: 1020845.7 | I10: 1020845.7 | J10: 1020845.7 | K10: 2906 | L10: AMOMPY | M10: Momentum Capital Investment S.A. | N10: 15/07/2026 | O10: 15/07/2026 | P10: 34 | Q10: No | U10: *MAV271001341 | V10: *MAV271001341 | W10: =+J10/$W$2 -> 1.2493768e-05
A11: PAMPA VIDA S.R.L. | B11: Pesos | C11: 46324 | D11: 29/10/2026 | E11: 1 | G11: 990902.64 | H11: 990902.64 | I11: 990902.64 | J11: 990902.64 | K11: 2956 | L11: AMOMPY | M11: Momentum Capital Investment S.A. | N11: 15/07/2026 | O11: 15/07/2026 | P11: 34 | Q11: No | U11: *MAV271001342 | V11: *MAV271001342 | W11: =+J11/$W$2 -> 1.2127306e-05
A12: Movil SGR | B12: Pesos | C12: 46324 | D12: 29/10/2026 | E12: 1 | G12: 20000000 | H12: 20000000 | I12: 20000000 | J12: 20000000 | K12: 22803 | L12: AMOMPY | M12: Momentum Capital Investment S.A. | N12: 28/09/2026 | O12: 28/09/2026 | P12: 26 | Q12: No | U12: *MOV271000087 | V12: *MOV271000087 | W12: =+J12/$W$2 -> 0.00024477292
A13: Movil SGR | B13: Pesos | C13: 46324 | D13: 29/10/2026 | E13: 1 | G13: 2500000 | H13: 2500000 | I13: 2500000 | J13: 2500000 | K13: 90031823 | L13: AMOMPY | M13: Momentum Capital Investment S.A. | N13: 22/04/2026 | O13: 22/04/2026 | P13: 28 | Q13: No | U13: *MOV271000069 | V13: *MOV271000069 | W13: =+J13/$W$2 -> 3.0596614e-05
A14: TREND SGR | B14: Pesos | C14: 46324 | D14: 29/10/2026 | E14: 1 | G14: 1572269.7 | H14: 1572269.7 | I14: 1572269.7 | J14: 1572269.7 | K14: 22513 | L14: AMOMPY | M14: Momentum Capital Investment S.A. | N14: 25/09/2026 | O14: 25/09/2026 | P14: 26 | Q14: No | U14: *TRD271000036 | V14: *TRD271000036 | W14: =+J14/$W$2 -> 1.9242452e-05
A15: ELI SA | B15: Pesos | C15: 46324 | D15: 29/10/2026 | E15: 1 | G15: 6535955.2 | H15: 6535955.2 | I15: 6535955.2 | J15: 6535955.2 | K15: 30000338 | L15: AMOMPY | M15: Momentum Capital Investment S.A. | N15: 04/09/2026 | O15: 04/09/2026 | P15: 32 | Q15: No | U15: *MAV271001542 | V15: *MAV271001542 | W15: =+J15/$W$2 -> 7.999124e-05
... A274: METALFOR SA | B274: Pesos | C274: 46330 | D274: 29/10/2026 | E274: 0.99590724 | G274: 12000000 | H274: 11950887 | I274: 12000000 | J274: 11950887 | K274: 34562 | L274: AMOMPY | M274: Momentum Capital Investment S.A. | N274: 31/07/2026 | O274: 31/07/2026 | P274: 25 | Q274: No | U274: *MAV011101206 | V274: *MAV011101206 | W274: =+J274/$W$2 -> 0.00014626267
A275: ALLIANCE ONE TOBACCO ARGENTINA | B275: Dolar 3500 | C275: 46330 | D275: 29/10/2026 | E275: 0.99868666 | F275: 1 US3 = 1539,5930209017 $ | G275: 500000 | H275: 499343.33 | I275: 7.6979651e+08 | J275: 7.6878551e+08 | K275: 152502 | L275: AMOMPY | M275: Momentum Capital Investment S.A. | N275: 04/06/2026 | O275: 04/06/2026 | P275: 8 | Q275: No | U275: #UMV021160025 | V275: #UMV021160025 | W275: =+J275/$W$2 -> 0.0094088935
A276: TEXTUM SA | B276: Pesos | C276: 46330 | D276: 29/10/2026 | E276: 0.99444203 | G276: 10000000 | H276: 9944420.3 | I276: 10000000 | J276: 9944420.3 | K276: 14284512 | L276: AMOMPY | M276: Momentum Capital Investment S.A. | N276: 24/08/2026 | O276: 24/08/2026 | P276: 34 | Q276: No | U276: *MAV021100898 | V276: *MAV021100898 | W276: =+J276/$W$2 -> 0.00012170624
A277: TEXTUM SA | B277: Pesos | C277: 46330 | D277: 29/10/2026 | E277: 0.99476729 | G277: 11000000 | H277: 10942440 | I277: 11000000 | J277: 10942440 | K277: 14651796 | L277: AMOMPY | M277: Momentum Capital Investment S.A. | N277: 01/10/2026 | O277: 01/10/2026 | P277: 32 | Q277: No | U277: *MAV311001979 | V277: *MAV311001979 | W277: =+J277/$W$2 -> 0.00013392065
A278: GHEZZI CARLOS ALBERTO | B278: Pesos | C278: 46330 | D278: 29/10/2026 | E278: 0.9952556 | G278: 2289494 | H278: 2278631.7 | I278: 2289494 | J278: 2278631.7 | K278: 11273460 | L278: AMOMPY | M278: Momentum Capital Investment S.A. | N278: 23/10/2026 | O278: 23/10/2026 | P278: 29 | Q278: No | U278: *MAV011101481 | V278: *MAV011101481 | W278: =+J278/$W$2 -> 2.7887366e-05
A279: SALTAPOR S.R.L. | B279: Pesos | C279: 46330 | D279: 29/10/2026 | E279: 0.99476727 | G279: 2749536.5 | H279: 2735148.9 | I279: 2749536.5 | J279: 2735148.9 | K279: 74760911 | L279: AMOMPY | M279: Momentum Capital Investment S.A. | N279: 04/09/2026 | O279: 04/09/2026 | P279: 32 | Q279: No | U279: *MAV021100999 | V279: *MAV021100999 | W279: =+J279/$W$2 -> 3.3474518e-05
A280: Union S.G.R. | B280: Pesos | C280: 46330 | D280: 29/10/2026 | E280: 0.99558128 | G280: 33170000 | H280: 33023431 | I280: 33170000 | J280: 33023431 | K280: 32240 | L280: AMOMPY | M280: Momentum Capital Investment S.A. | N280: 17/09/2026 | O280: 17/09/2026 | P280: 27 | Q280: No | U280: *NIO021100025 | V280: *NIO021100025 | W280: =+J280/$W$2 -> 0.00040416208
A281: NOVA FUSION SRL | B281: Pesos | C281: 46330 | D281: 29/10/2026 | E281: 0.99509276 | G281: 161938.32 | H281: 161143.65 | I281: 161938.32 | J281: 161143.65 | K281: 70489487 | L281: AMOMPY | M281: Momentum Capital Investment S.A. | N281: 19/10/2026 | O281: 19/10/2026 | P281: 30 | Q281: No | U281: *MAV311002169 | V281: *MAV311002169 | W281: =+J281/$W$2 -> 1.97218e-06
A282: PREMECOL SRL | B282: Pesos | C282: 46330 | D282: 29/10/2026 | E282: 0.99476732 | G282: 5000000 | H282: 4973836.6 | I282: 5000000 | J282: 4973836.6 | K282: 40981968 | L282: AMOMPY | M282: Momentum Capital Investment S.A. | N282: 19/10/2026 | O282: 19/10/2026 | P282: 32 | Q282: No | U282: *MAV311002171 | V282: *MAV311002171 | W282: =+J282/$W$2 -> 6.0873024e-05
A283: BSP LARTI SA | B283: Dolar 3500 | C283: 46330 | D283: 29/10/2026 | E283: 0.9985227 | F283: 1 US3 = 1539,5930209017 $ | G283: 100000 | H283: 99852.27 | I283: 1.539593e+08 | J283: 1.5373186e+08 | K283: 155821 | L283: AMOMPY | M283: Momentum Capital Investment S.A. | N283: 02/07/2026 | O283: 02/07/2026 | P283: 9 | Q283: No | U283: #UMV021160028 | V283: #UMV021160028 | W283: =+J283/$W$2 -> 0.0018814698
A284: COOPERATIVA DE TABACALEROS DE JUJUY LTDA | B284: Dolar 3500 | C284: 46330 | D284: 29/10/2026 | E284: 0.9986866 | F284: 1 US3 = 1539,5930209017 $ | G284: 188100 | H284: 187852.95 | I284: 2.8959745e+08 | J284: 2.8921709e+08 | K284: 160722 | L284: AMOMPY | M284: Momentum Capital Investment S.A. | N284: 12/08/2026 | O284: 12/08/2026 | P284: 8 | Q284: No | U284: #UMV021160035 | V284: #UMV021160035 | W284: =+J284/$W$2 -> 0.0035396255
A285: COOPERATIVA DE TABACALEROS DE JUJUY LTDA | B285: Dolar 3500 | C285: 46330 | D285: 29/10/2026 | E285: 0.9983589 | F285: 1 US3 = 1539,5930209017 $ | G285: 100000 | H285: 99835.89 | I285: 1.539593e+08 | J285: 1.5370664e+08 | K285: 165199 | L285: AMOMPY | M285: Momentum Capital Investment S.A. | N285: 15/09/2026 | O285: 15/09/2026 | P285: 10 | Q285: No | U285: #UMV021160051 | V285: #UMV021160051 | W285: =+J285/$W$2 -> 0.0018811611
A286: SURSEM SOCIEDAD ANONIMA | B286: Pesos | C286: 46330 | D286: 29/10/2026 | E286: 0.99460467 | G286: 363101.32 | H286: 361142.27 | I286: 363101.32 | J286: 361142.27 | K286: 7241 | L286: AMOMPY | M286: Momentum Capital Investment S.A. | N286: 09/10/2026 | O286: 09/10/2026 | P286: 33 | Q286: No | U286: *MAV021101384 | V286: *MAV021101384 | W286: =+J286/$W$2 -> 4.4198923e-06
A287: ESPECIALIDADES AGROPECUARIAS S.A. | B287: Pesos | C287: 46330 | D287: 29/10/2026 | E287: 0.99509273 | G287: 5000000 | H287: 4975463.7 | I287: 5000000 | J287: 4975463.7 | K287: 1347 | L287: AMOMPY | M287: Momentum Capital Investment S.A. | N287: 01/10/2026 | O287: 01/10/2026 | P287: 30 | Q287: No | U287: *MAV021101248 | V287: *MAV021101248 | W287: =+J287/$W$2 -> 6.0892937e-05
A288: ESPECIALIDADES AGROPECUARIAS S.A. | B288: Pesos | C288: 46330 | D288: 29/10/2026 | E288: 0.99509275 | G288: 5000000 | H288: 4975463.7 | I288: 5000000 | J288: 4975463.7 | K288: 1350 | L288: AMOMPY | M288: Momentum Capital Investment S.A. | N288: 02/10/2026 | O288: 02/10/2026 | P288: 30 | Q288: No | U288: *MAV021101283 | V288: *MAV021101283 | W288: =+J288/$W$2 -> 6.0892938e-05
A289: ESPECIALIDADES AGROPECUARIAS S.A. | B289: Pesos | C289: 46330 | D289: 29/10/2026 | E289: 0.99509272 | G289: 4000000 | H289: 3980370.9 | I289: 4000000 | J289: 3980370.9 | K289: 1289 | L289: AMOMPY | M289: Momentum Capital Investment S.A. | N289: 23/09/2026 | O289: 23/09/2026 | P289: 30 | Q289: No | U289: *MAV021101170 | V289: *MAV021101170 | W289: =+J289/$W$2 -> 4.8714349e-05
A290: ESPECIALIDADES AGROPECUARIAS S.A. | B290: Pesos | C290: 46330 | D290: 29/10/2026 | E290: 0.9950927 | G290: 5000000 | H290: 4975463.5 | I290: 5000000 | J290: 4975463.5 | K290: 1307 | L290: AMOMPY | M290: Momentum Capital Investment S.A. | N290: 29/09/2026 | O290: 29/09/2026 | P290: 30 | Q290: No | U290: *MAV021101220 | V290: *MAV021101220 | W290: =+J290/$W$2 -> 6.0892935e-05
A291: GOMEZ ROCO Y CIA SRL | B291: Pesos | C291: 46330 | D291: 29/10/2026 | E291: 0.9947673 | G291: 22929530 | H291: 22809546 | I291: 22929530 | J291: 22809546 | K291: 82628359 | L291: AMOMPY | M291: Momentum Capital Investment S.A. | N291: 05/10/2026 | O291: 02/10/2026 | P291: 32 | Q291: No | U291: *MAV011101364 | V291: *MAV011101364 | W291: =+J291/$W$2 -> 0.00027915796
A292: LW GROUP SRL | B292: Pesos | C292: 46330 | D292: 29/10/2026 | E292: 0.99460462 | G292: 2000000 | H292: 1989209.2 | I292: 2000000 | J292: 1989209.2 | K292: 42 | L292: AMOMPY | M292: Momentum Capital Investment S.A. | N292: 13/08/2026 | O292: 13/08/2026 | P292: 33 | Q292: No | U292: *MAV311001718 | V292: *MAV311001718 | W292: =+J292/$W$2 -> 2.4345227e-05
A293: BROADBANDTECH SA | B293: Pesos | C293: 46330 | D293: 29/10/2026 | E293: 0.99476729 | G293: 20000000 | H293: 19895346 | I293: 20000000 | J293: 19895346 | K293: 724 | L293: AMOMPY | M293: Momentum Capital Investment S.A. | N293: 21/09/2026 | O293: 21/09/2026 | P293: 32 | Q293: No | U293: *MAV021101140 | V293: *MAV021101140 | W293: =+J293/$W$2 -> 0.00024349209
A294: PINTURAS SAN AGUSTIN SRL | B294: Pesos | C294: 46330 | D294: 29/10/2026 | E294: 0.99476731 | G294: 6000000 | H294: 5968603.8 | I294: 6000000 | J294: 5968603.8 | K294: 70158555 | L294: AMOMPY | M294: Momentum Capital Investment S.A. | N294: 02/10/2026 | O294: 02/10/2026 | P294: 32 | Q294: No | U294: *MAV311002021 | V294: *MAV311002021 | W294: =+J294/$W$2 -> 7.3047628e-05
A295: RUBBO GUSTAVO ALEJANDRO MARIO | B295: Pesos | C295: 46330 | D295: 29/10/2026 | E295: 0.9947673 | G295: 1000000 | H295: 994767.3 | I295: 1000000 | J295: 994767.3 | K295: 70161997 | L295: AMOMPY | M295: Momentum Capital Investment S.A. | N295: 02/10/2026 | O295: 02/10/2026 | P295: 32 | Q295: No | U295: *MAV311002020 | V295: *MAV311002020 | W295: =+J295/$W$2 -> 1.2174605e-05
A296: NELIO RAUL PIGNATTA Y CIA SA | B296: Pesos | C296: 46330 | D296: 29/10/2026 | E296: 0.9947673 | G296: 18485149 | H296: 18388422 | I296: 18485149 | J296: 18388422 | K296: 4478 | L296: AMOMPY | M296: Momentum Capital Investment S.A. | N296: 05/10/2026 | O296: 05/10/2026 | P296: 32 | Q296: No | U296: *MAV311002023 | V296: *MAV311002023 | W296: =+J296/$W$2 -> 0.00022504939
A297: DE DOMINGO FRANCISCO JORGE ESTEBAN | B297: Pesos | C297: 46330 | D297: 29/10/2026 | E297: 0.99476729 | G297: 363375.5 | H297: 361474.06 | I297: 363375.5 | J297: 361474.06 | K297: 304 | L297: AMOMPY | M297: Momentum Capital Investment S.A. | N297: 06/10/2026 | O297: 06/10/2026 | P297: 32 | Q297: No | U297: *MAV011101362 | V297: *MAV011101362 | W297: =+J297/$W$2 -> 4.423953e-06
... A311: DE LAS MISIONES S.A. | B311: Pesos | C311: 46330 | D311: 29/10/2026 | E311: 0.9950927 | G311: 2700000 | H311: 2686750.3 | I311: 2700000 | J311: 2686750.3 | K311: 6910 | L311: AMOMPY | M311: Momentum Capital Investment S.A. | N311: 11/09/2026 | O311: 11/09/2026 | P311: 30 | Q311: No | U311: *MAV311001868 | V311: *MAV311001868 | W311: =+J311/$W$2 -> 3.2882185e-05
...

Sheet Posicion cuotapartista
A1: Posición de Cuotapartista
A2: Fondo | B2: Cuotapartista | C2: Tipo de Valor Cuotaparte | D2: Cuotapartes | E2: Inversión | F2: Moneda | G2: Fondo | H2: Tipo de Inversor | I2: Fondo | J2: Porcentaje
A3: Nombre | B3: Nombre | F3: Símbolo | G3: Fecha Valor Cuotaparte | I3: Valor Cuotaparte
A4: AMOMPY | B4: ZOFINGEN SECURITIES S.A. (ACDI) | C4: C | D4: 1.7003547e+09 | E4: 3.1799166e+09 | F4: $ | G4: 29/10/2026 | H4: Agentes de Colocación y Distribución Integral de FCIs | I4: 1.870149 | J4: 5.0185449
A5: AMOMPY | B5: BANCO DE LA CIUDAD DE BUENOS AIRES | C5: C | D5: 1.8078341e+09 | E5: 3380919138 | F5: $ | G5: 29/10/2026 | H5: Agentes de Colocación y Distribución Integral de FCIs | I5: 1.870149 | J5: 5.3357672
A6: AMOMPY | B6: MOMENTUM CAPITAL INVESTMENT S.A. (ACDI) | C6: C | D6: 2.8082279e+10 | E6: 5.2518046e+10 | F6: $ | G6: 29/10/2026 | H6: Agentes de Colocación y Distribución Integral de FCIs | I6: 1.870149 | J6: 82.88399
A7: AMOMPY | B7: ALYCBUR S.A. (ACDI) | C7: C | D7: 3.1629211e+08 | E7: 5.9151337e+08 | F7: $ | G7: 29/10/2026 | H7: Agentes de Colocación y Distribución Integral de FCIs | I7: 1.870149 | J7: 0.9335265
A8: AMOMPY | B8: BANCO DE SAN JUAN SA ( ACDI ) | C8: C | D8: 1.683916e+09 | E8: 3.1491738e+09 | F8: $ | G8: 29/10/2026 | H8: Agentes de Colocación y Distribución Integral de FCIs | I8: 1.870149 | J8: 4.9700267
A9: AMOMPY | B9: BANCO DE SANTA CRUZ SA (ACDI) | C9: C | D9: 2.9075177e+08 | E9: 5.4374913e+08 | F9: $ | G9: 29/10/2026 | H9: Agentes de Colocación y Distribución Integral de FCIs | I9: 1.870149 | J9: 0.85814497
A10: AMOMPY | B10: MOMENTUM CAPITAL INVESTMENT S.A. (ACDI) | C10: A | D10: 4.2098672e+09 | E10: 6.5219389e+09 | F10: $ | G10: 29/10/2026 | H10: Agentes de Colocación y Distribución Integral de FCIs | I10: 1.549203 | J10: 93.866975
A11: AMOMPY | B11: ALYCBUR S.A. (ACDI) | C11: A | D11: 2.7506183e+08 | E11: 4.2612661e+08 | F11: $ | G11: 29/10/2026 | H11: Agentes de Colocación y Distribución Integral de FCIs | I11: 1.549203 | J11: 6.1330252
A12: AMOMPY | B12: MOMENTUM CAPITAL INVESTMENT S.A. (ACDI) | C12: B | D12: 5.9702873e+09 | E12: 1.1083008e+10 | F12: $ | G12: 29/10/2026 | H12: Agentes de Colocación y Distribución Integral de FCIs | I12: 1.856361 | J12: 97.245008
A13: AMOMPY | B13: ALYCBUR S.A. (ACDI) | C13: B | D13: 1.6914077e+08 | E13: 3.1398634e+08 | F13: $ | G13: 29/10/2026 | H13: Agentes de Colocación y Distribución Integral de FCIs | I13: 1.856361 | J13: 2.7549924
D14: 4.4505785e+10 | E14: 8.1708379e+10
