Workbook

Sheet GESTION MOMENTUM
A1: FONDOS COMUNES DE INVERSION
A2: 6/7/2026
A3: 09:52:13
A4: Informe de Gestión al 3/7/2026
A5: FCI ABIERTO MOMENTUM PYMES | K5: COMAFI $ Nº 24148/3
A6: Todos los importes están expresados en Pesos | K6: BANCO DEL SOL
C7: (4) | D7: (1) | L7: 46209 | M7: =WORKDAY(L7,1,$R:$R) -> 46210 | N7: =WORKDAY(M7,1,$R:$R) -> 46211 | R7: 45719 | S7: Lista de feriados 2025
A8: ACTIVO | B8: 4.9215866e+10 | C8: 100 | K8: Caucion MAV | L8: 3.504411e+09 | R8: 45720
A9: INVERSIONES | B9: 4.7433111e+10 | C9: 96.38 | D9: 97.03 | K9: Vto Pase | R9: 45740
A10: TITULOS PUBLICOS | B10: 295167942 | C10: 0.6 | D10: 0.6 | K10: Plazo Fijo | L10: =SUMIFS(F:F,A:A,$K$10,B:B,L7) -> 0 | M10: =SUMIFS(G:G,B:B,$K$10,C:C,M7) -> 0 | N10: =SUMIFS(H:H,C:C,$K$10,D:D,N7) -> 0 | R10: 45749
A11: FUTUROS | B11: -1224725000 | C11: -2.49 | D11: -2.51 | K11: Vto. Cheques | L11: =SUMIF($B$95:$B$1441,L7,$D$95:$D$1441) -> 73381630 | M11: =SUMIF($B$95:$B$1441,M7,$D$95:$D$1441) -> 1034833880 | N11: =SUMIF($B$95:$B$1441,N7,$D$95:$D$1441) -> 3.4646107e+08 | R11: 45765
A12: DISPONIBILIDADES | B12: 2914404.2 | C12: 0.01 | D12: 0.01 | K12: Vto. Pagarés Dollar Linked | L12: =+SUMIF($B$1446:$B$1472,L7,$F$1446:$F$1472) -> 0 | M12: =+SUMIF($B$1428:$B$1454,M7,$F$1428:$F$1454) -> 0 | N12: =+SUMIF($B$1428:$B$1454,N7,$F$1428:$F$1454) -> 0 | R12: 45778
A13: EN PESOS | B13: 2914463.7 | C13: 0.01 | D13: 0.01 | K13: FCI IEB Ahorro - Clase E | L13: =SUMIF(A:A,K13,E:E) -> 3179000000 | R13: 45779
A14: EN DOLARES | B14: -59.54 | C14: 0 | D14: 0 | K14: COMAFI $ Nº 24148/3 | L14: =+B13 -> 2914463.7 | R14: 45802
A15: CREDITOS | B15: 1.7798403e+09 | C15: 3.62 | D15: 3.64 | K15: Ctte Momentum | L15: 5100000 | R15: 45824
A16: PASIVO | B16: -3.3047503e+08 | K16: Cheques pendientes | R16: 45828
A17: PROVISIONES | B17: -11501078 | K17: Compra/Venta Bonos | R17: 45847
A18: PROV. HONORARIOS SOC. DEPOSITARIA | B18: -667357.16 | K18: TOTAL | L18: =SUM(L8:L17) -> 6764807090 | R18: 45884
A19: PROV. HONORARIOS SOCIEDAD GERENTE | B19: -9848836.8 | K19: Neg. Cheques / Pagare | L19: =-607698546.5 -> -6.0769855e+08 | R19: 45886
A20: PROV. GASTOS SOCIEDAD DEPOSITARIA | B20: -984883.69 | K20: Coloca caucion MAV | R20: 45942
A21: DEUDAS EN PESOS | B21: -2.9410995e+08 | K21: Compra/Venta de Bonos | R21: 45982
A22: RESCATES | B22: -8056027 | J22: EGRESOS EN EL DIA Clase B | K22: Suscripciones | R22: 45985
A23: PREVISIÓN INCOBRABLES | B23: -2.4492492e+08 | K23: Rescates | L23: =SUMIF(A:A,K23,B:B) -> -8056027 | R23: 45999
A24: Valor Patrimonial del Fondo | B24: 4.8885391e+10 | K24: Pase | R24: 46016
A25: Liquidez Efectiva (2) | B25: 1463780795 | D25: 2.99 | K25: Rentas y Amortizaciones
A26: Liquidez Corriente (3) | B26: 1.4522797e+09 | D26: 2.97 | K26: Pago Gastos Banco Comafi
K27: Caja cierre | L27: =SUM(L18:L26) -> 6149052516 | M27: =SUM(M8:M26) -> 1034833880 | N27: =SUM(N8:N26) -> 3.4646107e+08
K31: Activos Pyme | L31: 3.3186984e+10
K32: % Pyme | L32: =L31/B24 -> 0.67887325
K40: PN ACTUAL | L40: =VLOOKUP("Valor Patrimonial del Fondo",A:B,2,0)+L22+L23 -> 48877334847
A41: Inversiones | K41: 5% MM | L41: =+L40*0.05 -> 2443866742
A42: TITULO PUBLICO en Pesos | K42: 20% CAUCION | L42: =+L40*0.2 -> 9775466969
A43: Denominación | B43: IsinCode | C43: Cantidad | D43: Cierre | E43: Total | F43: % (1) | G43: Costo | H43: Var | I43: Vencimiento
A44: Lecap S30N6 | B44: AR0451031345 | C44: 200000000 | D44: 1.1909 | E44: 238183006 | F44: 0.49 | G44: 0 | I44: 30/11/2026
C45: 200000000 | E45: 238183006 | F45: 0.49
A47: OBLIGACIONES NEGOCIABLES en Pesos
A48: Denominación | B48: IsinCode | C48: Cantidad | D48: Cierre | E48: Total | F48: % (1) | G48: Costo | H48: Var | I48: Vencimiento
A49: LR7AO - ON Laboratorios Richmond Serie 7 Cl A Vto 10/12/26 | B49: AR0905777444 | C49: 300000000 | D49: 1.0379 | E49: 311382795 | F49: 0.64 | G49: 1 | H49: 3.79 | I49: 10/12/2026
A50: MTC3O - ON Mastellone Clase 3 | B50: AR0494875476 | C50: 250000000 | D50: 0.9973 | E50: 249320315 | F50: 0.51 | G50: 1 | H50: -0.27 | I50: 22/06/2027
A51: VBC3O - ON BANCO DE VALORES CL.3 24/10/26 $ | B51: AR0531585807 | C51: 300000000 | D51: 1.0476 | E51: 314281872 | F51: 0.64 | G51: 1 | H51: 4.76 | I51: 24/10/2026
...

Sheet Parametros
A1: Min | B1: 0.75 | C1: en Pymes | D1: =+B1*(VLOOKUP($E$1,'GESTION MOMENTUM'!$A$8:$B$32,2,0)) -> 36664043156 | E1: Valor Patrimonial del Fondo | G1: PN actual | H1: P&L | I1: PN reservado
A2: Max | B2: 0.05 | C2: Money Market | D2: =+B2*(VLOOKUP($E$1,'GESTION MOMENTUM'!$A$8:$B$32,2,0)) -> 2444269544 | G2: =VLOOKUP(E1,'GESTION MOMENTUM'!A8:B32,2,0) -> 48885390874 | H2: -0.002 | I2: =+G2*(1+H2) -> 48787620093
A3: Max | B3: 0.2 | C3: PFRemuneradasCaucion | D3: =+B3*(VLOOKUP($E$1,'GESTION MOMENTUM'!$A$8:$B$32,2,0)) -> 9777078175 | G3: Money Market | H3: 0.05 | I3: =+I2*H3 -> 2439381005
A4: Max | B4: 0.2 | C4: cheques x librador | D4: =+B4*(VLOOKUP($E$1,'GESTION MOMENTUM'!$A$8:$B$32,2,0)) -> 9777078175
A5: Max | B5: 0.25 | C5: x titulo en Pymes | D5: =+B5*(VLOOKUP($E$1,'GESTION MOMENTUM'!$A$8:$B$32,2,0)) -> 12221347719
B8: Garantías RFX (MOMENTUM)
B9: Bono | C9: VN | D9: Precio | E9: Aforo | F9: $
B10: Lecap S30N6 | C10: 200000000 | D10: =+VLOOKUP(B10,'GESTION MOMENTUM'!A:D,4,0) -> 1.1909 | E10: 0.85 | F10: =C10*D10*E10 -> 202453000
B11: CO2D7 - Título provincia de Córdoba 05/12/27 | C11: 300000000 | D11: =+VLOOKUP(B11,'GESTION MOMENTUM'!A:D,4,0) -> 0.9839 | E11: 0.6 | F11: =C11*D11*E11 -> 177102000
E13: Garantia | F13: =SUM(F10:F12) -> 379555000
B15: Garantías | C15: Total $ por contrato | D15: Contratos a shortear | E15: Contratos Shorteados | F15: Garantia Requerida
A16: Fut Rofex DLR052026 | B16: Mayo | C16: 150000 | D16: 0 | E16: =IFNA(-VLOOKUP(A16,'GESTION MOMENTUM'!A:C,3,0)/1000,0) -> 0 | F16: =+C16*(E16+D16) -> 0
A17: Fut Rofex DLR062026 | B17: Junio | C17: 155000 | D17: 0 | E17: =IFNA(-VLOOKUP(A17,'GESTION MOMENTUM'!A:C,3,0)/1000,0) -> 0 | F17: =+C17*(E17+D17) -> 0
A18: Fut Rofex DLR072026 | B18: Julio | C18: 160000 | D18: 0 | E18: =IFNA(-VLOOKUP(A18,'GESTION MOMENTUM'!A:C,3,0)/1000,0) -> 225 | F18: =+C18*(E18+D18) -> 36000000
A19: Fut Rofex DLR082026 | B19: Agosto | C19: 165000 | D19: 0 | E19: =IFNA(-VLOOKUP(A19,'GESTION MOMENTUM'!A:C,3,0)/1000,0) -> 475 | F19: =+C19*(E19+D19) -> 78375000
A20: Fut Rofex DLR092026 | B20: Septiembre | C20: 170000 | D20: 0 | E20: =IFNA(-VLOOKUP(A20,'GESTION MOMENTUM'!A:C,3,0)/1000,0) -> 575 | F20: =+C20*(E20+D20) -> 97750000
C21: 175000 | D21: 0 | E21: =IFNA(-VLOOKUP(A21,'GESTION MOMENTUM'!A:C,3,0)/1000,0) -> 0 | F21: =+C21*(E21+D21) -> 0
F22: =+SUM(F16:F21) -> 212125000
B23: Saldo de Garantias | C23: =F13-F22 -> 167430000

Sheet Cheques pendientes
A1: FONDO | B1: CHPD | C1: VTO | D1: MONEDA | E1: MONTO | F1: MONTO $ | G1: ESTADO | H1: LIBRADOR | I1: DIAS DE MORA
A2: AMOMPY | B2: *MAV030300645 | C2: 45723 | D2: $ | E2: 3406250 | G2: PREVISIONADO | H2: UKUMARI SOCIEDAD ANONIMA. | I2: =+TODAY()-C2 -> 486 | U2: LIBRADORES PENDIENTES
A3: AMOMPY | B3: *MAV100300802 | C3: 45728 | D3: $ | E3: 3406250 | G3: PREVISIONADO | H3: UKUMARI SOCIEDAD ANONIMA. | I3: =+TODAY()-C3 -> 481 | U3: {=+UNIQUE(H2:H91)} -> UKUMARI SOCIEDAD ANONIMA. | V3: =+SUMIF(H:H,U3,E:E) -> 6812500
A4: AMOMPY | B4: *MAV200500842 | C4: 45799 | D4: $ | E4: 129185000 | G4: PENDIENTE | H4: NIRO CONSTRUYE S. A. | I4: =+TODAY()-C4 -> 410 | U4: NIRO CONSTRUYE S. A. | V4: =+SUMIF(H:H,U4,E:E) -> 258370000
A5: AMOMPY | B5: *MAV300500862 | C5: 45811 | D5: $ | E5: 129185000 | G5: PENDIENTE | H5: NIRO CONSTRUYE S. A. | I5: =+TODAY()-C5 -> 398 | U5: MERCOL RAUL ALBERTO Y MERCOL MAURICIO EDUARDO. | V5: =+SUMIF(H:H,U5,E:E) -> 62500000
A6: AMOMPY | B6: *MAV091000727 | C6: 45943 | D6: $ | E6: 12500000 | G6: PENDIENTE | H6: MERCOL RAUL ALBERTO Y MERCOL MAURICIO EDUARDO. | I6: =+TODAY()-C6 -> 266 | U6: F G SANITARIOS S R L | V6: =+SUMIF(H:H,U6,E:E) -> 35000000
A7: AMOMPY | B7: *MAV151000873 | C7: 45947 | D7: $ | E7: 5000000 | G7: PREVISIONADO | H7: F G SANITARIOS S R L | I7: =+TODAY()-C7 -> 262 | U7: AKAI ENERGY LED SRL | V7: =+SUMIF(H:H,U7,E:E) -> 44963000
A8: AMOMPY | B8: *MAV201001014 | C8: 45952 | D8: $ | E8: 5000000 | G8: PREVISIONADO | H8: F G SANITARIOS S R L | I8: =+TODAY()-C8 -> 257 | K8: Valor Patrimonial del Fondo | L8: =+VLOOKUP(K8,'GESTION MOMENTUM'!A:B,2,0) -> 48885390874 | U8: FRIGORIFICO GENERAL PICO S A | V8: =+SUMIF(H:H,U8,E:E) -> 70000000
A9: AMOMPY | B9: *MAV231000788 | C9: 45957 | D9: $ | E9: 5000000 | G9: PREVISIONADO | H9: F G SANITARIOS S R L | I9: =+TODAY()-C9 -> 252 | U9: MIANI CLARA A Y MIANI ADA CLELIA | V9: =+SUMIF(H:H,U9,E:E) -> 3125000
A10: AMOMPY | B10: *MAV271000879 | C10: 45959 | D10: $ | E10: 5000000 | G10: PREVISIONADO | H10: F G SANITARIOS S R L | I10: =+TODAY()-C10 -> 250 | L10: $ | M10: % PN | U10: PORT PLA S.R.L. | V10: =+SUMIF(H:H,U10,E:E) -> 150000000
A11: AMOMPY | B11: *MAV301000860 | C11: 45964 | D11: $ | E11: 5000000 | G11: PREVISIONADO | H11: F G SANITARIOS S R L | I11: =+TODAY()-C11 -> 245 | K11: PREVISIÓN INCOBRABLES | L11: =+VLOOKUP(K11,'GESTION MOMENTUM'!A:B,2,0) -> -2.4492492e+08 | M11: =+L11/L8 -> -0.0050101863 | U11: CONEXION SALUD SRL | V11: =+SUMIF(H:H,U11,E:E) -> 27000000
A12: AMOMPY | B12: *MAV031100816 | C12: 45966 | D12: $ | E12: 5000000 | G12: PREVISIONADO | H12: F G SANITARIOS S R L | I12: =+TODAY()-C12 -> 243 | K12: PREVISIONADO | L12: =+SUMIF(G:G,K12,E:E) -> 187612500 | U12: MASTER DESIGN HOME SRL | V12: =+SUMIF(H:H,U12,E:E) -> 24000000
A13: AMOMPY | B13: *MAV031100940 | C13: 45966 | D13: $ | E13: 4400000 | G13: PENDIENTE | H13: AKAI ENERGY LED SRL | I13: =+TODAY()-C13 -> 243 | K13: Prevision a aplicar | L13: =+L11+L12 -> -57312416 | U13: BUNYAR S.R.L. | V13: =+SUMIF(H:H,U13,E:E) -> 24800000
A14: AMOMPY | B14: *MAV041100892 | C14: 45968 | D14: $ | E14: 4400000 | G14: PENDIENTE | H14: AKAI ENERGY LED SRL | I14: =+TODAY()-C14 -> 241 | U14: GROCAL S.A. | V14: =+SUMIF(H:H,U14,E:E) -> 15000000
A15: AMOMPY | B15: *MAV051100567 | C15: 45971 | D15: $ | E15: 25000000 | G15: PENDIENTE | H15: MERCOL RAUL ALBERTO Y MERCOL MAURICIO EDUARDO. | I15: =+TODAY()-C15 -> 238 | K15: PENDIENTE | L15: =+SUMIF(G:G,K15,E:E)+E2 -> 1564111550 | M15: =+SUMIF(G:G,K15,E:E)/$L$8 -> 0.031925802 | U15: Paccioli Group Sociedad Anonima | V15: =+SUMIF(H:H,U15,E:E) -> 13958000
A16: AMOMPY | B16: *MAV051100722 | C16: 45971 | D16: $ | E16: 4400000 | G16: PENDIENTE | H16: AKAI ENERGY LED SRL | I16: =+TODAY()-C16 -> 238 | U16: FINEX CABA S. A. | V16: =+SUMIF(H:H,U16,E:E) -> 55300000
A17: AMOMPY | B17: *MAV071100935 | C17: 45972 | D17: $ | E17: 4400000 | G17: PENDIENTE | H17: AKAI ENERGY LED SRL | I17: =+TODAY()-C17 -> 237 | U17: TRADICION VALORES S.A. | V17: =+SUMIF(H:H,U17,E:E) -> 25000000
A18: AMOMPY | B18: *MAV061100646 | C18: 45972 | D18: $ | E18: 5000000 | G18: PREVISIONADO | H18: F G SANITARIOS S R L | I18: =+TODAY()-C18 -> 237 | U18: Maradona Wines | V18: =+SUMIF(H:H,U18,E:E) -> 119500000
A19: AMOMPY | B19: *MAV111100890 | C19: 45974 | D19: $ | E19: 963000 | G19: PENDIENTE | H19: AKAI ENERGY LED SRL | I19: =+TODAY()-C19 -> 235 | U19: LOPEZ LUCIA SOLEDAD | V19: =+SUMIF(H:H,U19,E:E) -> 995000
A20: AMOMPY | B20: *MAV121100854 | C20: 45975 | D20: $ | E20: 4400000 | G20: PENDIENTE | H20: AKAI ENERGY LED SRL | I20: =+TODAY()-C20 -> 234 | K20: LIBRADOR PENDIENTE | L20: $ | M20: % PN | O20: VIGENTE | U20: RABU INVERSIONES SRL | V20: =+SUMIF(H:H,U20,E:E) -> 7194300
A21: AMOMPY | B21: *MAV121100675 | C21: 45975 | D21: $ | E21: 25000000 | G21: PENDIENTE | H21: MERCOL RAUL ALBERTO Y MERCOL MAURICIO EDUARDO. | I21: =+TODAY()-C21 -> 234 | K21: {=+_xlws.SORT(U3:V34,2,-1)} -> #NAME? | M21: =+L21/$L$8 -> 0 | O21: =+SUMIF('Reporte de Cheques'!A:A,'Cheques pendientes'!K21,'Reporte de Cheques'!I:I) -> 0 | U21: GROUP DIEZ S.A. | V21: =+SUMIF(H:H,U21,E:E) -> 425000000
A22: AMOMPY | B22: *MAV141101053 | C22: 45979 | D22: $ | E22: 4400000 | G22: PENDIENTE | H22: AKAI ENERGY LED SRL | I22: =+TODAY()-C22 -> 230 | M22: =+L22/$L$8 -> 0 | O22: =+SUMIF('Reporte de Cheques'!A:A,'Cheques pendientes'!K22,'Reporte de Cheques'!I:I) -> 0 | U22: INVLAC CONSTRUCCIONES S.R.L | V22: =+SUMIF(H:H,U22,E:E) -> 4000000
A23: AMOMPY | B23: *MAV141101054 | C23: 45979 | D23: $ | E23: 4400000 | G23: PENDIENTE | H23: AKAI ENERGY LED SRL | I23: =+TODAY()-C23 -> 230 | M23: =+L23/$L$8 -> 0 | O23: =+SUMIF('Reporte de Cheques'!A:A,'Cheques pendientes'!K23,'Reporte de Cheques'!I:I) -> 0 | U23: I-LED ARGENTINA S.A. | V23: =+SUMIF(H:H,U23,E:E) -> 21800000
A24: AMOMPY | B24: *MAV171100932 | C24: 45980 | D24: $ | E24: 4400000 | G24: PENDIENTE | H24: AKAI ENERGY LED SRL | I24: =+TODAY()-C24 -> 229 | M24: =+L24/$L$8 -> 0 | O24: =+SUMIF('Reporte de Cheques'!A:A,'Cheques pendientes'!K24,'Reporte de Cheques'!I:I) -> 0 | U24: INTANSIA S.R.L | V24: =+SUMIF(H:H,U24,E:E) -> 40000000
A25: AMOMPY | B25: *MAV151101337 | C25: 45980 | D25: $ | E25: 4400000 | G25: PENDIENTE | H25: AKAI ENERGY LED SRL | I25: =+TODAY()-C25 -> 229 | M25: =+L25/$L$8 -> 0 | O25: =+SUMIF('Reporte de Cheques'!A:A,'Cheques pendientes'!K25,'Reporte de Cheques'!I:I) -> 0 | U25: ASOCIACION ATLETICA ARGENTINOS JUNIORS | V25: =+SUMIF(H:H,U25,E:E) -> 300000000
A26: AMOMPY | B26: *MAV181100869 | C26: 45981 | D26: $ | E26: 4400000 | G26: PENDIENTE | H26: AKAI ENERGY LED SRL | I26: =+TODAY()-C26 -> 228 | M26: =+L26/$L$8 -> 0 | O26: =+SUMIF('Reporte de Cheques'!A:A,'Cheques pendientes'!K26,'Reporte de Cheques'!I:I) -> 0 | V26: =+SUMIF(H:H,U26,E:E) -> 0
A27: AMOMPY | B27: *MAV181100773 | C27: 45981 | D27: $ | E27: 20000000 | G27: PREVISIONADO | H27: FRIGORIFICO GENERAL PICO S A | I27: =+TODAY()-C27 -> 228 | M27: =+L27/$L$8 -> 0 | O27: =+SUMIF('Reporte de Cheques'!A:A,'Cheques pendientes'!K27,'Reporte de Cheques'!I:I) -> 0 | V27: =+SUMIF(H:H,U27,E:E) -> 0
A28: AMOMPY | B28: *MAV191100661 | C28: 45986 | D28: $ | E28: 20000000 | G28: PREVISIONADO | H28: FRIGORIFICO GENERAL PICO S A | I28: =+TODAY()-C28 -> 223 | M28: =+L28/$L$8 -> 0 | O28: =+SUMIF('Reporte de Cheques'!A:A,'Cheques pendientes'!K28,'Reporte de Cheques'!I:I) -> 0 | V28: =+SUMIF(H:H,U28,E:E) -> 0
A29: AMOMPY | B29: *MAV201100887 | C29: 45987 | D29: $ | E29: 10000000 | G29: PREVISIONADO | H29: FRIGORIFICO GENERAL PICO S A | I29: =+TODAY()-C29 -> 222 | M29: =+L29/$L$8 -> 0 | O29: =+SUMIF('Reporte de Cheques'!A:A,'Cheques pendientes'!K29,'Reporte de Cheques'!I:I) -> 0 | V29: =+SUMIF(H:H,U29,E:E) -> 0
A30: AMOMPY | B30: *MAV211100687 | C30: 45988 | D30: $ | E30: 10000000 | G30: PREVISIONADO | H30: FRIGORIFICO GENERAL PICO S A | I30: =+TODAY()-C30 -> 221 | M30: =+L30/$L$8 -> 0 | O30: =+SUMIF('Reporte de Cheques'!A:A,'Cheques pendientes'!K30,'Reporte de Cheques'!I:I) -> 0 | V30: =+SUMIF(H:H,U30,E:E) -> 0
A31: AMOMPY | B31: *MAV221100992 | C31: 45988 | D31: $ | E31: 10000000 | G31: PREVISIONADO | H31: FRIGORIFICO GENERAL PICO S A | I31: =+TODAY()-C31 -> 221 | M31: =+L31/$L$8 -> 0 | O31: =+SUMIF('Reporte de Cheques'!A:A,'Cheques pendientes'!K31,'Reporte de Cheques'!I:I) -> 0 | V31: =+SUMIF(H:H,U31,E:E) -> 0
A32: AMOMPY | B32: *MAV271100809 | C32: 45992 | D32: $ | E32: 3125000 | G32: PENDIENTE | H32: MIANI CLARA A Y MIANI ADA CLELIA | I32: =+TODAY()-C32 -> 217 | M32: =+L32/$L$8 -> 0 | O32: =+SUMIF('Reporte de Cheques'!A:A,'Cheques pendientes'!K32,'Reporte de Cheques'!I:I) -> 0 | V32: =+SUMIF(H:H,U32,E:E) -> 0
A33: AMOMPY | B33: *MAV291101201 | C33: 45994 | D33: $ | E33: 25000000 | G33: PENDIENTE | H33: PORT PLA S.R.L. | I33: =+TODAY()-C33 -> 215 | M33: =+L33/$L$8 -> 0 | O33: =+SUMIF('Reporte de Cheques'!A:A,'Cheques pendientes'!K33,'Reporte de Cheques'!I:I) -> 0 | V33: =+SUMIF(H:H,U33,E:E) -> 0
A34: AMOMPY | B34: *MAV151201389 | C34: 46008 | D34: $ | E34: 27000000 | G34: PREVISIONADO | H34: CONEXION SALUD SRL | I34: =+TODAY()-C34 -> 201 | M34: =+L34/$L$8 -> 0 | O34: =+SUMIF('Reporte de Cheques'!A:A,'Cheques pendientes'!K34,'Reporte de Cheques'!I:I) -> 0 | V34: =+SUMIF(H:H,U34,E:E) -> 0
A35: AMOMPY | B35: *MAV171200694 | C35: 46010 | D35: $ | E35: 6000000 | G35: PREVISIONADO | H35: MASTER DESIGN HOME SRL | I35: =+TODAY()-C35 -> 199 | M35: =+L35/$L$8 -> 0 | O35: =+SUMIF('Reporte de Cheques'!A:A,'Cheques pendientes'!K35,'Reporte de Cheques'!I:I) -> 0
A36: AMOMPY | B36: *MAV181201122 | C36: 46013 | D36: $ | E36: 24800000 | G36: PREVISIONADO | H36: BUNYAR S.R.L. | I36: =+TODAY()-C36 -> 196 | M36: =+L36/$L$8 -> 0 | O36: =+SUMIF('Reporte de Cheques'!A:A,'Cheques pendientes'!K36,'Reporte de Cheques'!I:I) -> 0
A37: AMOMPY | B37: *MAV291200938 | C37: 46024 | D37: $ | E37: 25000000 | G37: PENDIENTE | H37: PORT PLA S.R.L. | I37: =+TODAY()-C37 -> 185 | M37: =+L37/$L$8 -> 0 | O37: =+SUMIF('Reporte de Cheques'!A:A,'Cheques pendientes'!K37,'Reporte de Cheques'!I:I) -> 0
A38: AMOMPY | B38: *MAV020100774 | C38: 46028 | D38: $ | E38: 10000000 | G38: PENDIENTE | H38: PORT PLA S.R.L. | I38: =+TODAY()-C38 -> 181 | M38: =+L38/$L$8 -> 0 | O38: =+SUMIF('Reporte de Cheques'!A:A,'Cheques pendientes'!K38,'Reporte de Cheques'!I:I) -> 0
A39: AMOMPY | B39: *MAV311200688 | C39: 46028 | D39: $ | E39: 6000000 | G39: PREVISIONADO | H39: MASTER DESIGN HOME SRL | I39: =+TODAY()-C39 -> 181 | M39: =+L39/$L$8 -> 0 | O39: =+SUMIF('Reporte de Cheques'!A:A,'Cheques pendientes'!K39,'Reporte de Cheques'!I:I) -> 0
A40: AMOMPY | B40: *MAV050100914 | C40: 46029 | D40: $ | E40: 10000000 | G40: PENDIENTE | H40: PORT PLA S.R.L. | I40: =+TODAY()-C40 -> 180 | M40: =+L40/$L$8 -> 0 | O40: =+SUMIF('Reporte de Cheques'!A:A,'Cheques pendientes'!K40,'Reporte de Cheques'!I:I) -> 0
...

Sheet Concentración

Sheet Reporte de Cheques
A1: Reporte de Cheques de Pago Diferido | W1: Valor Patrimonial del Fondo
A2: Cheque de Pago Diferido y Pagaré | B2: Moneda | C2: Cheque de Pago Diferido y Pagaré | D2: Fecha | E2: Precio | F2: Tipo de Cambio (Cheque/Fondo) | G2: Moneda Cheque | H2: Moneda Cheque | I2: Moneda Fondo | J2: Moneda Fondo | K2: Compra | L2: Fondo | M2: Compra | N2: Compra | O2: Compra | P2: Compra | Q2: Vendido | R2: Venta | S2: Venta | T2: Venta | U2: Cheque de Pago Diferido y Pagaré | V2: Cheque de Pago Diferido y Pagaré | W2: =+VLOOKUP(W1,'GESTION MOMENTUM'!A:B,2,0) -> 48885390874
A3: Sociedad de Garantía Recíproca / Librador | B3: Descripción | C3: Fecha de Vencimiento | D3: Fecha | E3: Precio | F3: Tipo de Cambio (Cheque/Fondo) | G3: Importe Nominal | H3: Importe Actual | I3: Importe Nominal | J3: Importe Actual | K3: Nro. de Operación | L3: Nombre | M3: Agente | N3: Fecha Concertación | O3: Fecha Liquidación | P3: Tasa de Descuento | Q3: Vendido | R3: Nro. de Operación | S3: Fecha Concertación | T3: Fecha Liquidación | U3: Abreviatura | V3: Código CAFCI | W3: %
A4: ACINDAR PYMES SGR | B4: Pesos | C4: 46206 | D4: 03/07/2026 | E4: 1 | G4: 2500000 | H4: 2500000 | I4: 2500000 | J4: 2500000 | K4: 6119 | L4: AMOMPY | M4: Momentum Capital Investment S.A. | N4: 29/05/2026 | O4: 29/05/2026 | P4: 20 | Q4: =SUMPRODUCT(P4:P1392,I4:I1392)/SUM(I4:I1392) -> 31.870304 | U4: *ACI010700324 | V4: *ACI010700324 | W4: =+J4/$W$2 -> 5.1140023e-05
A5: LOGICA CONSULTING GROUP SAU | B5: Pesos | C5: 46206 | D5: 03/07/2026 | E5: 1 | G5: 4298084.2 | H5: 4298084.2 | I5: 4298084.2 | J5: 4298084.2 | K5: 533 | L5: AMOMPY | M5: Momentum Capital Investment S.A. | N5: 22/04/2026 | O5: 22/04/2026 | P5: 38 | Q5: No | U5: *MAV010701115 | V5: *MAV010701115 | W5: =+J5/$W$2 -> 8.7921649e-05
A6: DESDE EL MAR S.A. | B6: Pesos | C6: 46206 | D6: 03/07/2026 | E6: 1 | G6: 2000000 | H6: 2000000 | I6: 2000000 | J6: 2000000 | K6: 7744 | L6: AMOMPY | M6: Momentum Capital Investment S.A. | N6: 08/05/2026 | O6: 08/05/2026 | P6: 35 | Q6: No | U6: *MAV010701183 | V6: *MAV010701183 | W6: =+J6/$W$2 -> 4.0912018e-05
A7: EL TREBOL SRL | B7: Pesos | C7: 46206 | D7: 03/07/2026 | E7: 1 | G7: 9676723.3 | H7: 9676723.3 | I7: 9676723.3 | J7: 9676723.3 | K7: 263806 | L7: AMOMPY | M7: Momentum Capital Investment S.A. | N7: 27/05/2026 | O7: 27/05/2026 | P7: 33 | Q7: No | U7: *MAV010701315 | V7: *MAV010701315 | W7: =+J7/$W$2 -> 0.00019794714
A8: COOPERATIVA DE VIVIENDA CREDITO Y CONSUMO PARA EL DESARROLLO LIMITADA | B8: Pesos | C8: 46206 | D8: 03/07/2026 | E8: 1 | G8: 15000000 | H8: 15000000 | I8: 15000000 | J8: 15000000 | K8: 70219532 | L8: AMOMPY | M8: Momentum Capital Investment S.A. | N8: 05/05/2026 | O8: 05/05/2026 | P8: 31 | Q8: No | U8: *MAV010701150 | V8: *MAV010701150 | W8: =+J8/$W$2 -> 0.00030684014
A9: COOPERATIVA DE VIVIENDA CREDITO Y CONSUMO PARA EL DESARROLLO LIMITADA | B9: Pesos | C9: 46206 | D9: 03/07/2026 | E9: 1 | G9: 25000000 | H9: 25000000 | I9: 25000000 | J9: 25000000 | K9: 70219533 | L9: AMOMPY | M9: Momentum Capital Investment S.A. | N9: 07/05/2026 | O9: 07/05/2026 | P9: 31 | Q9: No | U9: *MAV010701178 | V9: *MAV010701178 | W9: =+J9/$W$2 -> 0.00051140023
A10: JUARROS JOSE LUIS | B10: Pesos | C10: 46206 | D10: 03/07/2026 | E10: 1 | G10: 6238663.2 | H10: 6238663.2 | I10: 6238663.2 | J10: 6238663.2 | K10: 9266641 | L10: AMOMPY | M10: Momentum Capital Investment S.A. | N10: 16/04/2026 | O10: 16/04/2026 | P10: 35 | Q10: No | U10: *MAV010701098 | V10: *MAV010701098 | W10: =+J10/$W$2 -> 0.00012761815
A11: VITALCAN S.A. | B11: Pesos | C11: 46206 | D11: 03/07/2026 | E11: 1 | G11: 100000000 | H11: 100000000 | I11: 100000000 | J11: 100000000 | K11: 7353 | L11: AMOMPY | M11: Momentum Capital Investment S.A. | N11: 31/03/2026 | O11: 31/03/2026 | P11: 37 | Q11: No | U11: *MAV010701052 | V11: *MAV010701052 | W11: =+J11/$W$2 -> 0.0020456009
A12: DEMAGRO SRL | B12: Pesos | C12: 46206 | D12: 03/07/2026 | E12: 1 | G12: 22500000 | H12: 22500000 | I12: 22500000 | J12: 22500000 | K12: 65800963 | L12: AMOMPY | M12: Momentum Capital Investment S.A. | N12: 26/03/2026 | O12: 26/03/2026 | P12: 38 | Q12: No | U12: *MAV010701039 | V12: *MAV010701039 | W12: =+J12/$W$2 -> 0.0004602602
A13: BiBank S.A. | B13: Pesos | C13: 46206 | D13: 03/07/2026 | E13: 1 | G13: 500000000 | H13: 500000000 | I13: 500000000 | J13: 500000000 | K13: 147165 | L13: AMOMPY | M13: Momentum Capital Investment S.A. | N13: 23/04/2026 | O13: 23/04/2026 | P13: 28 | Q13: No | U13: #INT020760001 | V13: #INT020760001 | W13: =+J13/$W$2 -> 0.010228005
Q14: No | U14: #UMV010760032 | V14: #UMV010760032 | W14: =+J14/$W$2 -> 0
A15: MILLS S.G.R. | B15: Pesos | C15: 46206 | D15: 03/07/2026 | E15: 1 | G15: 10000000 | H15: 10000000 | I15: 10000000 | J15: 10000000 | K15: 32529 | L15: AMOMPY | M15: Momentum Capital Investment S.A. | N15: 27/04/2026 | O15: 27/04/2026 | P15: 27 | Q15: No | U15: *MIL010700023 | V15: *MIL010700023 | W15: =+J15/$W$2 -> 0.00020456009
A16: ALLIANCE ONE TOBACCO ARGENTINA | B16: Pesos | C16: 46206 | D16: 03/07/2026 | E16: 1 | G16: 1000000000 | H16: 1000000000 | I16: 1000000000 | J16: 1000000000 | K16: 147160 | L16: AMOMPY | M16: Momentum Capital Investment S.A. | N16: 23/04/2026 | O16: 23/04/2026 | P16: 30 | Q16: No | U16: #MAV020760016 | V16: #MAV020760016 | W16: =+J16/$W$2 -> 0.020456009
A17: QUILMES | B17: Pesos | C17: 46206 | D17: 03/07/2026 | E17: 1 | G17: 8168237.9 | H17: 8168237.9 | I17: 8168237.9 | J17: 8168237.9 | K17: 40012237 | L17: AMOMPY | M17: Momentum Capital Investment S.A. | N17: 22/05/2026 | O17: 22/05/2026 | P17: 21 | Q17: No | U17: *MAV010701292 | V17: *MAV010701292 | W17: =+J17/$W$2 -> 0.00016708955
A18: INTEGRA PYMES SGR | B18: Pesos | C18: 46206 | D18: 03/07/2026 | E18: 1 | G18: 5000000 | H18: 5000000 | I18: 5000000 | J18: 5000000 | K18: 16779597 | L18: AMOMPY | M18: Momentum Capital Investment S.A. | N18: 30/04/2026 | O18: 30/04/2026 | P18: 29 | Q18: No | U18: *INP010700054 | V18: *INP010700054 | W18: =+J18/$W$2 -> 0.00010228005
A19: AVAL AR SGR | B19: Pesos | C19: 46206 | D19: 03/07/2026 | E19: 1 | G19: 15000000 | H19: 15000000 | I19: 15000000 | J19: 15000000 | K19: 801 | L19: AMOMPY | M19: Momentum Capital Investment S.A. | N19: 31/03/2026 | O19: 31/03/2026 | P19: 29 | Q19: No | U19: *AAR010700018 | V19: *AAR010700018 | W19: =+J19/$W$2 -> 0.00030684014
A20: AVAL AR SGR | B20: Pesos | C20: 46206 | D20: 03/07/2026 | E20: 1 | G20: 12500000 | H20: 12500000 | I20: 12500000 | J20: 12500000 | K20: 28996520 | L20: AMOMPY | M20: Momentum Capital Investment S.A. | N20: 31/03/2026 | O20: 31/03/2026 | P20: 29 | Q20: No | U20: *AAR010700017 | V20: *AAR010700017 | W20: =+J20/$W$2 -> 0.00025570011
A21: DESDE EL MAR S.A. | B21: Pesos | C21: 46209 | D21: 03/07/2026 | E21: 0.99713156 | G21: 2000000 | H21: 1994263.1 | I21: 2000000 | J21: 1994263.1 | K21: 7745 | L21: AMOMPY | M21: Momentum Capital Investment S.A. | N21: 08/05/2026 | O21: 08/05/2026 | P21: 35 | Q21: No | U21: *MAV020700893 | V21: *MAV020700893 | W21: =+J21/$W$2 -> 4.0794664e-05
A22: COOPERATIVA DE VIVIENDA CREDITO Y CONSUMO PARA EL DESARROLLO LIMITADA | B22: Pesos | C22: 46209 | D22: 03/07/2026 | E22: 0.99745853 | G22: 42000000 | H22: 41893258 | I22: 42000000 | J22: 41893258 | K22: 148257 | L22: AMOMPY | M22: Momentum Capital Investment S.A. | N22: 05/05/2026 | O22: 05/05/2026 | P22: 31 | Q22: No | U22: #MAV030760052 | V22: #MAV030760052 | W22: =+J22/$W$2 -> 0.00085696887
A23: CAMPO AVAL SGR | B23: Pesos | C23: 46209 | D23: 03/07/2026 | E23: 0.99786757 | G23: 10000000 | H23: 9978675.7 | I23: 10000000 | J23: 9978675.7 | K23: 1742541 | L23: AMOMPY | M23: Momentum Capital Investment S.A. | N23: 21/04/2026 | O23: 21/04/2026 | P23: 26 | Q23: No | U23: *CMP020700021 | V23: *CMP020700021 | W23: =+J23/$W$2 -> 0.00020412388
A24: BUROMAHTIK SA | B24: Pesos | C24: 46209 | D24: 03/07/2026 | E24: 0.99704984 | G24: 3000000 | H24: 2991149.5 | I24: 3000000 | J24: 2991149.5 | K24: 40743051 | L24: AMOMPY | M24: Momentum Capital Investment S.A. | N24: 26/05/2026 | O24: 26/05/2026 | P24: 36 | Q24: No | U24: *MAV020700980 | V24: *MAV020700980 | W24: =+J24/$W$2 -> 6.1186982e-05
A25: AVAL AR SGR | B25: Pesos | C25: 46209 | D25: 03/07/2026 | E25: 0.99762211 | G25: 15000000 | H25: 14964332 | I25: 15000000 | J25: 14964332 | K25: 802 | L25: AMOMPY | M25: Momentum Capital Investment S.A. | N25: 31/03/2026 | O25: 31/03/2026 | P25: 29 | Q25: No | U25: *AAR020700017 | V25: *AAR020700017 | W25: =+J25/$W$2 -> 0.0003061105
A26: TPS CONSTRUCTORA SA | B26: Pesos | C26: 46209 | D26: 03/07/2026 | E26: 0.99754035 | G26: 1381630.2 | H26: 1378231.9 | I26: 1381630.2 | J26: 1378231.9 | K26: 70386150 | L26: AMOMPY | M26: Momentum Capital Investment S.A. | N26: 17/06/2026 | O26: 17/06/2026 | P26: 30 | Q26: No | U26: *MAV020701143 | V26: *MAV020701143 | W26: =+J26/$W$2 -> 2.8193124e-05
... A545: MILLS S.G.R. | B545: Pesos | C545: 46239 | D545: 03/07/2026 | E545: 0.97617089 | G545: 5800000 | H545: 5661791.2 | I545: 5800000 | J545: 5661791.2 | K545: 121 | L545: AMOMPY | M545: Momentum Capital Investment S.A. | N545: 25/06/2026 | O545: 25/06/2026 | P545: 27 | Q545: No | U545: *MIL020800026 | V545: *MIL020800026 | W545: =+J545/$W$2 -> 0.00011581765
A546: BSP LARTI SA | Q546: No | U546: #UMV030860028 | V546: #UMV030860028 | W546: =+J546/$W$2 -> 0
A547: BSP LARTI SA | Q547: No | U547: #UMV030860027 | V547: #UMV030860027 | W547: =+J547/$W$2 -> 0
A548: COOPERATIVA DE TABACALEROS DE JUJUY LTDA | Q548: No | U548: #UMV030860029 | V548: #UMV030860029 | W548: =+J548/$W$2 -> 0
A549: COOPERATIVA DE TABACALEROS DE JUJUY LTDA | Q549: No | U549: #UMV030860035 | V549: #UMV030860035 | W549: =+J549/$W$2 -> 0
A550: MILLS S.G.R. | B550: Pesos | C550: 46239 | D550: 03/07/2026 | E550: 0.97445074 | G550: 4166666.7 | H550: 4060211.4 | I550: 4166666.7 | J550: 4060211.4 | K550: 13567710 | L550: AMOMPY | M550: Momentum Capital Investment S.A. | N550: 30/04/2026 | O550: 30/04/2026 | P550: 29 | Q550: No | U550: *MIL020800023 | V550: *MIL020800023 | W550: =+J550/$W$2 -> 8.3055721e-05
A551: BUROMAHTIK SA | B551: Pesos | C551: 46239 | D551: 03/07/2026 | E551: 0.96932685 | G551: 2000000 | H551: 1938653.7 | I551: 2000000 | J551: 1938653.7 | K551: 40751276 | L551: AMOMPY | M551: Momentum Capital Investment S.A. | N551: 02/06/2026 | O551: 02/06/2026 | P551: 35 | Q551: No | U551: *MAV030800905 | V551: *MAV030800905 | W551: =+J551/$W$2 -> 3.9657118e-05
A552: LAGAVULIN S.A. | B552: Pesos | C552: 46239 | D552: 03/07/2026 | E552: 0.97102888 | G552: 50000000 | H552: 48551444 | I552: 50000000 | J552: 48551444 | K552: 136 | L552: AMOMPY | M552: Momentum Capital Investment S.A. | N552: 13/05/2026 | O552: 13/05/2026 | P552: 33 | Q552: No | U552: *MAV030800838 | V552: *MAV030800838 | W552: =+J552/$W$2 -> 0.00099316878
A553: METALFOR SA | B553: Pesos | C553: 46239 | D553: 03/07/2026 | E553: 0.96847805 | G553: 16800000 | H553: 16270431 | I553: 16800000 | J553: 16270431 | K553: 32600 | L553: AMOMPY | M553: Momentum Capital Investment S.A. | N553: 29/04/2026 | O553: 29/04/2026 | P553: 36 | Q553: No | U553: *MAV030800746 | V553: *MAV030800746 | W553: =+J553/$W$2 -> 0.00033282809
A554: QUILMES | B554: Pesos | C554: 46239 | D554: 03/07/2026 | E554: 0.9813675 | G554: 8756337 | H554: 8593184.5 | I554: 8756337 | J554: 8593184.5 | K554: 40012226 | L554: AMOMPY | M554: Momentum Capital Investment S.A. | N554: 22/05/2026 | O554: 22/05/2026 | P554: 21 | Q554: No | U554: *MAV030800874 | V554: *MAV030800874 | W554: =+J554/$W$2 -> 0.00017578226
A555: QUILMES | B555: Pesos | C555: 46239 | D555: 03/07/2026 | E555: 0.97876223 | G555: 1484637.5 | H555: 1453107.1 | I555: 1484637.5 | J555: 1453107.1 | K555: 40012463 | L555: AMOMPY | M555: Momentum Capital Investment S.A. | N555: 29/05/2026 | O555: 29/05/2026 | P555: 24 | Q555: No | U555: *MAV030800891 | V555: *MAV030800891 | W555: =+J555/$W$2 -> 2.9724771e-05
A556: INTEGRA PYMES SGR | B556: Pesos | C556: 46239 | D556: 03/07/2026 | E556: 0.97359304 | G556: 15000000 | H556: 14603896 | I556: 15000000 | J556: 14603896 | K556: 90000127 | L556: AMOMPY | M556: Momentum Capital Investment S.A. | N556: 05/05/2026 | O556: 05/05/2026 | P556: 30 | Q556: No | U556: *INP030800027 | V556: *INP030800027 | W556: =+J556/$W$2 -> 0.00029873742
A557: SIGMA AGRO S.A. | B557: Pesos | C557: 46239 | D557: 03/07/2026 | E557: 0.97445081 | G557: 100000000 | H557: 97445081 | I557: 100000000 | J557: 97445081 | K557: 90003818 | L557: AMOMPY | M557: Momentum Capital Investment S.A. | N557: 03/06/2026 | O557: 03/06/2026 | P557: 29 | Q557: No | U557: *MAV030800921 | V557: *MAV030800921 | W557: =+J557/$W$2 -> 0.0019933375
A558: GRUB SA | B558: Pesos | C558: 46239 | D558: 03/07/2026 | E558: 0.98398667 | G558: 346128566 | H558: 3.405859e+08 | I558: 346128566 | J558: 3.405859e+08 | K558: 152123 | L558: AMOMPY | M558: Momentum Capital Investment S.A. | N558: 02/06/2026 | O558: 02/06/2026 | P558: 18 | Q558: No | U558: #MAV040860041 | V558: #MAV040860041 | W558: =+J558/$W$2 -> 0.0069670282
...

Sheet Posicion cuotapartista
A1: Posición de Cuotapartista
A2: Fondo | B2: Cuotapartista | C2: Tipo de Valor Cuotaparte | D2: Cuotapartes | E2: Inversión | F2: Moneda | G2: Fondo | H2: Tipo de Inversor | I2: Fondo | J2: Porcentaje
A3: Nombre | B3: Nombre | F3: Símbolo | G3: Fecha Valor Cuotaparte | I3: Valor Cuotaparte
A4: AMOMPY | B4: MOMENTUM CAPITAL INVESTMENT S.A. (ACDI) | C4: C | D4: 1.7869429e+10 | E4: 3.0799302e+10 | F4: $ | G4: 03/07/2026 | H4: Agentes de Colocación y Distribución Integral de FCIs | I4: 1.723575 | J4: 84.290188
A5: AMOMPY | B5: BANCO DE SAN JUAN SA | C5: C | D5: 5.8150354e+08 | E5: 1.002265e+09 | F5: $ | G5: 03/07/2026 | H5: Agentes de Colocación y Distribución Integral de FCIs | I5: 1.723575 | J5: 2.7429551
A6: AMOMPY | B6: ZOFINGEN SECURITIES S.A. (ACDI) | C6: C | D6: 3.3408168e+08 | E6: 5.7581483e+08 | F6: $ | G6: 03/07/2026 | H6: Agentes de Colocación y Distribución Integral de FCIs | I6: 1.723575 | J6: 1.575865
A7: AMOMPY | B7: MOMENTUM CAPITAL INVESTMENT S.A. (ACDI) | C7: B | D7: 3.2641096e+09 | E7: 5.5844639e+09 | F7: $ | G7: 03/07/2026 | H7: Agentes de Colocación y Distribución Integral de FCIs | I7: 1.710869 | J7: 95.073451
A8: AMOMPY | B8: BANCO DE LA CIUDAD DE BUENOS AIRES | C8: C | D8: 1.8078341e+09 | E8: 3.1159377e+09 | F8: $ | G8: 03/07/2026 | H8: Agentes de Colocación y Distribución Integral de FCIs | I8: 1.723575 | J8: 8.5275626
A9: AMOMPY | B9: MOMENTUM CAPITAL INVESTMENT S.A. (ACDI) | C9: A | D9: 4.0849927e+09 | E9: 5.8324831e+09 | F9: $ | G9: 03/07/2026 | H9: Agentes de Colocación y Distribución Integral de FCIs | I9: 1.427783 | J9: 90.119519
A10: AMOMPY | B10: ALYCBUR S.A. (ACDI) | C10: B | D10: 1.6914077e+08 | E10: 2.8937771e+08 | F10: $ | G10: 03/07/2026 | H10: Agentes de Colocación y Distribución Integral de FCIs | I10: 1.710869 | J10: 4.9265494
A11: AMOMPY | B11: ALYCBUR S.A. (ACDI) | C11: A | D11: 4.4786848e+08 | E11: 6.3945901e+08 | F11: $ | G11: 03/07/2026 | H11: Agentes de Colocación y Distribución Integral de FCIs | I11: 1.427783 | J11: 9.8804809
A12: AMOMPY | B12: BANCO DE SANTA CRUZ SA | C12: C | D12: 2.9075177e+08 | E12: 5.0113248e+08 | F12: $ | G12: 03/07/2026 | H12: Agentes de Colocación y Distribución Integral de FCIs | I12: 1.723575 | J12: 1.3714776
A13: AMOMPY | B13: ALYCBUR S.A. (ACDI) | C13: C | D13: 3.1629211e+08 | E13: 5.4515317e+08 | F13: $ | G13: 03/07/2026 | H13: Agentes de Colocación y Distribución Integral de FCIs | I13: 1.723575 | J13: 1.4919515
D14: 2.9166004e+10 | E14: 4.8885388e+10
