Workbook

Sheet GESTION MOMENTUM
A1: FONDOS COMUNES DE INVERSION
A2: 15/5/2026
A3: 10:22:06
A4: Informe de Gestión al 14/5/2026
A5: FCI ABIERTO MOMENTUM PYMES | K5: COMAFI $ Nº 24148/3
A6: Todos los importes están expresados en Pesos | K6: BANCO DEL SOL
C7: (4) | D7: (1) | L7: 46157 | M7: =WORKDAY(L7,1,$R:$R) -> 46160 | N7: =WORKDAY(M7,1,$R:$R) -> 46161 | R7: 45719 | S7: Lista de feriados 2025
A8: ACTIVO | B8: 3.8267482e+10 | C8: 100 | K8: Caucion MAV | R8: 45720
A9: INVERSIONES | B9: 3.6016156e+10 | C9: 94.12 | D9: 94.92 | K9: Vto Pase | R9: 45740
A10: TITULOS PUBLICOS | B10: 5.6938407e+08 | C10: 1.49 | D10: 1.5 | K10: Plazo Fijo | L10: =SUMIFS(F:F,A:A,$K$10,B:B,L7) -> 0 | M10: =SUMIFS(G:G,B:B,$K$10,C:C,M7) -> 0 | N10: =SUMIFS(H:H,C:C,$K$10,D:D,N7) -> 0 | R10: 45749
A11: FUTUROS | B11: -1054249000 | C11: -2.75 | D11: -2.78 | K11: Vto. Cheques | L11: =SUMIF($B$91:$B$1225,L7,$D$91:$D$1225) -> 2.8318299e+08 | M11: =SUMIF($B$91:$B$1225,M7,$D$91:$D$1225) -> 2.2010609e+08 | N11: =SUMIF($B$91:$B$1225,N7,$D$91:$D$1225) -> 2.7483551e+08 | R11: 45765
A12: DISPONIBILIDADES | B12: 1973761.5 | C12: 0.01 | D12: 0.01 | K12: Vto. Pagarés Dollar Linked | L12: =+SUMIF($B$1230:$B$1250,L7,$F$1230:$F$1250) -> 0 | M12: =+SUMIF($B$1230:$B$1250,M7,$F$1230:$F$1250) -> 0 | N12: =+SUMIF($B$1230:$B$1250,N7,$F$1230:$F$1250) -> 0 | R12: 45778
A13: EN PESOS | B13: 1973719.7 | C13: 0.01 | D13: 0.01 | K13: FCI IEB Ahorro - Clase E | L13: =SUMIF($A:$A,K13,$E:$E) -> 1670000000 | R13: 45779
A14: EN DOLARES | B14: 41.8 | C14: 0 | D14: 0 | K14: COMAFI $ Nº 24148/3 | L14: =+B13 -> 1973719.7 | R14: 45802
A15: CREDITOS | B15: 2.2493527e+09 | C15: 5.88 | D15: 5.93 | K15: Ctte Momentum | L15: 2626000 | R15: 45824
A16: PASIVO | B16: -3.255195e+08 | K16: Cheques pendientes | R16: 45828
A17: PROVISIONES | B17: -41621110 | K17: Compra/Venta Bonos | R17: 45847
A18: PROV. HONORARIOS SOC. DEPOSITARIA | B18: -2415090.8 | K18: TOTAL | L18: =SUM(L8:L17) -> 1.9577827e+09 | R18: 45884
A19: PROV. HONORARIOS SOCIEDAD GERENTE | B19: -35641836 | K19: Neg. Cheques / Pagare | L19: =-32380754.09 -> -32380754 | R19: 45886
A20: PROV. GASTOS SOCIEDAD DEPOSITARIA | B20: -3564183.6 | K20: Coloca caucion MAV | R20: 45942
A21: DEUDAS EN PESOS | B21: -2.7185579e+08 | K21: Compra/Venta de Bonos | R21: 45982
A22: RESCATES | B22: -50000000 | J22: EGRESOS EN EL DIA Clase B | K22: Suscripciones | R22: 45985
A23: PREVISIÓN INCOBRABLES | B23: -1.6900272e+08 | K23: Rescates | L23: =SUMIF(A:A,K23,B:B) -> -50000000 | R23: 45999
A24: Valor Patrimonial del Fondo | B24: 3.7941963e+10 | K24: Pase | R24: 46016
A25: Liquidez Efectiva (2) | B25: 1.9674281e+09 | D25: 5.19 | K25: Rentas y Amortizaciones
A26: Liquidez Corriente (3) | B26: 1.925807e+09 | D26: 5.08 | K26: Pago Gastos SG y SD
K27: Caja cierre | L27: =SUM(L18:L26) -> 1.875402e+09 | M27: =SUM(M8:M26) -> 2.2010609e+08 | N27: =SUM(N8:N26) -> 2.7483551e+08
K31: Activos Pyme | L31: 2.6702326e+10
K32: % Pyme | L32: =L31/B24 -> 0.70376766
K40: PN ACTUAL | L40: =VLOOKUP("Valor Patrimonial del Fondo",A:B,2,0)+L22+L23 -> 3.7891963e+10
A41: Inversiones | K41: 5% MM | L41: =+L40*0.05 -> 1.8945981e+09
A42: TITULO PUBLICO en Pesos | K42: 20% CAUCION | L42: =+L40*0.2 -> 7.5783925e+09
A43: Denominación | B43: IsinCode | C43: Cantidad | D43: Cierre | E43: Total | F43: % (1) | G43: Costo | H43: Var | I43: Vencimiento
A44: Lecap S30N6 | B44: AR0451031345 | C44: 200000000 | D44: 1.1518 | E44: 230366940 | F44: 0.61 | G44: 0 | I44: 30/11/2026
A45: S29Y6 - Lecap S29Y6 | B45: AR0716680340 | C45: 197919126 | D45: 1.3098 | E45: 2.5923868e+08 | F45: 0.68 | G45: 0 | I45: 29/05/2026
C46: 397919126 | E46: 4.8960562e+08 | F46: 1.29
A48: OBLIGACIONES NEGOCIABLES en Pesos
A49: Denominación | B49: IsinCode | C49: Cantidad | D49: Cierre | E49: Total | F49: % (1) | G49: Costo | H49: Var | I49: Vencimiento
A50: LR7AO - ON Laboratorios Richmond Serie 7 Cl A Vto 10/12/26 | B50: AR0905777444 | C50: 300000000 | D50: 1.0732 | E50: 321969276 | F50: 0.85 | G50: 1 | H50: 7.32 | I50: 10/12/2026
A51: VBC3O - ON BANCO DE VALORES CL.3 24/10/26 $ | B51: AR0531585807 | C51: 300000000 | D51: 1.013 | E51: 303895314 | F51: 0.8 | G51: 1 | H51: 1.3 | I51: 24/10/2026
...

Sheet Parametros
A1: Min | B1: 0.75 | C1: en Pymes | D1: =+B1*(VLOOKUP($E$1,'GESTION MOMENTUM'!$A$8:$B$32,2,0)) -> 2.8456472e+10 | E1: Valor Patrimonial del Fondo | G1: PN actual | H1: P&L | I1: PN reservado
A2: Max | B2: 0.05 | C2: Money Market | D2: =+B2*(VLOOKUP($E$1,'GESTION MOMENTUM'!$A$8:$B$32,2,0)) -> 1.8970981e+09 | G2: =VLOOKUP(E1,'GESTION MOMENTUM'!A8:B32,2,0) -> 3.7941963e+10 | H2: -0.002 | I2: =+G2*(1+H2) -> 3.7866079e+10
A3: Max | B3: 0.2 | C3: PFRemuneradasCaucion | D3: =+B3*(VLOOKUP($E$1,'GESTION MOMENTUM'!$A$8:$B$32,2,0)) -> 7.5883925e+09 | G3: Money Market | H3: 0.05 | I3: =+I2*H3 -> 1.8933039e+09
A4: Max | B4: 0.2 | C4: cheques x librador | D4: =+B4*(VLOOKUP($E$1,'GESTION MOMENTUM'!$A$8:$B$32,2,0)) -> 7.5883925e+09
A5: Max | B5: 0.25 | C5: x titulo en Pymes | D5: =+B5*(VLOOKUP($E$1,'GESTION MOMENTUM'!$A$8:$B$32,2,0)) -> 9.4854907e+09
B8: Garantías RFX (MOMENTUM)
B9: Bono | C9: VN | D9: Precio | E9: Aforo | F9: $
B10: Lecap S30N6 | C10: 200000000 | D10: =+VLOOKUP(B10,'GESTION MOMENTUM'!A:D,4,0) -> 1.1518 | E10: 0.8 | F10: =C10*D10*E10 -> 184288000
B11: CO2D7 - Título provincia de Córdoba 05/12/27 | C11: 300000000 | D11: =+VLOOKUP(B11,'GESTION MOMENTUM'!A:D,4,0) -> 1.0338 | E11: 0.6 | F11: =C11*D11*E11 -> 186084000
E13: Garantia | F13: =SUM(F10:F12) -> 370372000
B15: Garantías | C15: Total $ por contrato | D15: Contratos a shortear | E15: Contratos Shorteados | F15: Garantia Requerida
A16: Fut Rofex DLR042026 | B16: Abril | C16: 150000 | D16: 0 | E16: =_xlfn.IFNA(-VLOOKUP(A16,'GESTION MOMENTUM'!A:C,3,0)/1000,0) -> 0 | F16: =+C16*(E16+D16) -> 0
A17: Fut Rofex DLR052026 | B17: Mayo | C17: 155000 | D17: 0 | E17: =_xlfn.IFNA(-VLOOKUP(A17,'GESTION MOMENTUM'!A:C,3,0)/1000,0) -> 40 | F17: =+C17*(E17+D17) -> 6200000
A18: Fut Rofex DLR062026 | B18: Junio | C18: 160000 | D18: 0 | E18: =_xlfn.IFNA(-VLOOKUP(A18,'GESTION MOMENTUM'!A:C,3,0)/1000,0) -> 314 | F18: =+C18*(E18+D18) -> 50240000
A19: Fut Rofex DLR072026 | B19: Julio | C19: 165000 | D19: 0 | E19: =_xlfn.IFNA(-VLOOKUP(A19,'GESTION MOMENTUM'!A:C,3,0)/1000,0) -> 276 | F19: =+C19*(E19+D19) -> 45540000
C20: 170000 | D20: 0 | E20: =_xlfn.IFNA(-VLOOKUP(A20,'GESTION MOMENTUM'!A:C,3,0)/1000,0) -> 0 | F20: =+C20*(E20+D20) -> 0
C21: 175000 | D21: 0 | E21: =_xlfn.IFNA(-VLOOKUP(A21,'GESTION MOMENTUM'!A:C,3,0)/1000,0) -> 0 | F21: =+C21*(E21+D21) -> 0
F22: =+SUM(F16:F21) -> 101980000
B23: Saldo de Garantias | C23: =+F13-F22 -> 268392000

Sheet Cheques pendientes
A1: FONDO | B1: CHPD | C1: VTO | D1: MONEDA | E1: MONTO | F1: MONTO $ | G1: ESTADO | H1: LIBRADOR | I1: DIAS DE MORA
A2: AMOMPY | B2: *MAV030300645 | C2: 45723 | D2: $ | E2: 3406250 | G2: PREVISIONADO | H2: UKUMARI SOCIEDAD ANONIMA. | I2: =+TODAY()-C2 -> 434 | U2: LIBRADORES PENDIENTES
A3: AMOMPY | B3: *MAV100300802 | C3: 45728 | D3: $ | E3: 3406250 | G3: PREVISIONADO | H3: UKUMARI SOCIEDAD ANONIMA. | I3: =+TODAY()-C3 -> 429 | U3: {=+_xlfn.UNIQUE(H2:H108)} -> UKUMARI SOCIEDAD ANONIMA. | V3: =+SUMIF(H:H,U3,E:E) -> 6812500
A4: AMOMPY | B4: *MAV250400806 | C4: 45776 | D4: $ | E4: 20000000 | G4: PENDIENTE | H4: FRIGORIFICO H V S A | I4: =+TODAY()-C4 -> 381 | U4: FRIGORIFICO H V S A | V4: =+SUMIF(H:H,U4,E:E) -> 215445000
A5: AMOMPY | B5: *MAV260400819 | C5: 45777 | D5: $ | E5: 20000000 | G5: PENDIENTE | H5: FRIGORIFICO H V S A | I5: =+TODAY()-C5 -> 380 | U5: NIRO CONSTRUYE S. A. | V5: =+SUMIF(H:H,U5,E:E) -> 258370000
A6: AMOMPY | B6: *MAV270400527 | C6: 45777 | D6: $ | E6: 20000000 | G6: PENDIENTE | H6: FRIGORIFICO H V S A | I6: =+TODAY()-C6 -> 380 | U6: EL GUAYMALLEN SA | V6: =+SUMIF(H:H,U6,E:E) -> 113700000
A7: AMOMPY | B7: *MAV280400632 | C7: 45777 | D7: $ | E7: 20000000 | G7: PENDIENTE | H7: FRIGORIFICO H V S A | I7: =+TODAY()-C7 -> 380 | U7: MERCOL RAUL ALBERTO Y MERCOL MAURICIO EDUARDO. | V7: =+SUMIF(H:H,U7,E:E) -> 62500000
A8: AMOMPY | B8: *MAV200500842 | C8: 45799 | D8: $ | E8: 129185000 | G8: PENDIENTE | H8: NIRO CONSTRUYE S. A. | I8: =+TODAY()-C8 -> 358 | K8: Valor Patrimonial del Fondo | L8: =+VLOOKUP(K8,'GESTION MOMENTUM'!A:B,2,0) -> 3.7941963e+10 | U8: F G SANITARIOS S R L | V8: =+SUMIF(H:H,U8,E:E) -> 35000000
A9: AMOMPY | B9: *MAV300500862 | C9: 45811 | D9: $ | E9: 129185000 | G9: PENDIENTE | H9: NIRO CONSTRUYE S. A. | I9: =+TODAY()-C9 -> 346 | U9: AKAI ENERGY LED SRL | V9: =+SUMIF(H:H,U9,E:E) -> 44963000
A10: AMOMPY | B10: *MAV150701156 | C10: 45855 | D10: $ | E10: 22500000 | G10: PENDIENTE | H10: FRIGORIFICO H V S A | I10: =+TODAY()-C10 -> 302 | L10: $ | M10: % PN | U10: COOPERATIVA TAMBERA LAS CAÑITAS LIMITADA | V10: =+SUMIF(H:H,U10,E:E) -> 190000000
A11: AMOMPY | B11: *MAV150701157 | C11: 45855 | D11: $ | E11: 22510000 | G11: PENDIENTE | H11: FRIGORIFICO H V S A | I11: =+TODAY()-C11 -> 302 | K11: PREVISIÓN INCOBRABLES | L11: =+VLOOKUP(K11,'GESTION MOMENTUM'!A:B,2,0) -> -1.6900272e+08 | M11: =+L11/L8 -> -0.0044542429 | U11: FRIGORIFICO GENERAL PICO S A | V11: =+SUMIF(H:H,U11,E:E) -> 70000000
A12: AMOMPY | B12: *MAV160700725 | C12: 45856 | D12: $ | E12: 22482000 | G12: PENDIENTE | H12: FRIGORIFICO H V S A | I12: =+TODAY()-C12 -> 301 | K12: PREVISIONADO | L12: =+SUMIF(G:G,K12,E:E) -> 144512500 | U12: MIANI CLARA A Y MIANI ADA CLELIA | V12: =+SUMIF(H:H,U12,E:E) -> 3125000
A13: AMOMPY | B13: *MAV210700860 | C13: 45861 | D13: $ | E13: 22646000 | G13: PENDIENTE | H13: FRIGORIFICO H V S A | I13: =+TODAY()-C13 -> 296 | K13: Prevision a aplicar | L13: =+L11+L12 -> -24490216 | U13: PORT PLA S.R.L. | V13: =+SUMIF(H:H,U13,E:E) -> 150000000
A14: AMOMPY | B14: *MAV220700935 | C14: 45862 | D14: $ | E14: 22690000 | G14: PENDIENTE | H14: FRIGORIFICO H V S A | I14: =+TODAY()-C14 -> 295 | U14: SOUTHAMERICAN TRENDY S.A. | V14: =+SUMIF(H:H,U14,E:E) -> 332000000
A15: AMOMPY | B15: *MAV230700673 | C15: 45863 | D15: $ | E15: 22617000 | G15: PENDIENTE | H15: FRIGORIFICO H V S A | I15: =+TODAY()-C15 -> 294 | K15: PENDIENTE | L15: =+SUMIF(G:G,K15,E:E)+E2 -> 2087556550 | M15: =+SUMIF(G:G,K15,E:E)/$L$8 -> 0.054929955 | U15: CONEXION SALUD SRL | V15: =+SUMIF(H:H,U15,E:E) -> 27000000
A16: AMOMPY | B16: *MAV091000728 | C16: 45943 | D16: $ | E16: 20000000 | G16: PREVISIONADO | H16: EL GUAYMALLEN SA | I16: =+TODAY()-C16 -> 214 | U16: MASTER DESIGN HOME SRL | V16: =+SUMIF(H:H,U16,E:E) -> 24000000
A17: AMOMPY | B17: *MAV091000727 | C17: 45943 | D17: $ | E17: 12500000 | G17: PENDIENTE | H17: MERCOL RAUL ALBERTO Y MERCOL MAURICIO EDUARDO. | I17: =+TODAY()-C17 -> 214 | U17: BUNYAR S.R.L. | V17: =+SUMIF(H:H,U17,E:E) -> 24800000
A18: AMOMPY | B18: *MAV151000873 | C18: 45947 | D18: $ | E18: 5000000 | G18: PENDIENTE | H18: F G SANITARIOS S R L | I18: =+TODAY()-C18 -> 210 | U18: GROCAL S.A. | V18: =+SUMIF(H:H,U18,E:E) -> 15000000
A19: AMOMPY | B19: *MAV201001014 | C19: 45952 | D19: $ | E19: 5000000 | G19: PENDIENTE | H19: F G SANITARIOS S R L | I19: =+TODAY()-C19 -> 205 | U19: Paccioli Group Sociedad Anonima | V19: =+SUMIF(H:H,U19,E:E) -> 13958000
A20: AMOMPY | B20: *MAV221000795 | C20: 45954 | D20: $ | E20: 18700000 | G20: PREVISIONADO | H20: EL GUAYMALLEN SA | I20: =+TODAY()-C20 -> 203 | K20: LIBRADOR PENDIENTE | L20: $ | M20: % PN | O20: VIGENTE | U20: FINEX CABA S. A. | V20: =+SUMIF(H:H,U20,E:E) -> 55300000
A21: AMOMPY | B21: *MAV231000788 | C21: 45957 | D21: $ | E21: 5000000 | G21: PENDIENTE | H21: F G SANITARIOS S R L | I21: =+TODAY()-C21 -> 200 | K21: {=+_xlfn._xlws.SORT(U3:V34,2,-1)} -> SOUTHAMERICAN TRENDY S.A. | L21: 332000000 | M21: =+L21/$L$8 -> 0.0087502063 | O21: =+SUMIF('Reporte de Cheques'!A:A,'Cheques pendientes'!K21,'Reporte de Cheques'!I:I) -> 0 | U21: TRADICION VALORES S.A. | V21: =+SUMIF(H:H,U21,E:E) -> 25000000
A22: AMOMPY | B22: *MAV271000879 | C22: 45959 | D22: $ | E22: 5000000 | G22: PENDIENTE | H22: F G SANITARIOS S R L | I22: =+TODAY()-C22 -> 198 | K22: NIRO CONSTRUYE S. A. | L22: 258370000 | M22: =+L22/$L$8 -> 0.0068096108 | O22: =+SUMIF('Reporte de Cheques'!A:A,'Cheques pendientes'!K22,'Reporte de Cheques'!I:I) -> 0 | U22: Maradona Wines | V22: =+SUMIF(H:H,U22,E:E) -> 119500000
A23: AMOMPY | B23: *MAV301000860 | C23: 45964 | D23: $ | E23: 5000000 | G23: PENDIENTE | H23: F G SANITARIOS S R L | I23: =+TODAY()-C23 -> 193 | K23: FRIGORIFICO H V S A | L23: 215445000 | M23: =+L23/$L$8 -> 0.0056782777 | O23: =+SUMIF('Reporte de Cheques'!A:A,'Cheques pendientes'!K23,'Reporte de Cheques'!I:I) -> 0 | U23: LOPEZ LUCIA SOLEDAD | V23: =+SUMIF(H:H,U23,E:E) -> 995000
A24: AMOMPY | B24: *MAV031100816 | C24: 45966 | D24: $ | E24: 5000000 | G24: PENDIENTE | H24: F G SANITARIOS S R L | I24: =+TODAY()-C24 -> 191 | K24: COOPERATIVA TAMBERA LAS CAÑITAS LIMITADA | L24: 190000000 | M24: =+L24/$L$8 -> 0.0050076482 | O24: =+SUMIF('Reporte de Cheques'!A:A,'Cheques pendientes'!K24,'Reporte de Cheques'!I:I) -> 0 | U24: RABU INVERSIONES SRL | V24: =+SUMIF(H:H,U24,E:E) -> 7194300
A25: AMOMPY | B25: *MAV031100940 | C25: 45966 | D25: $ | E25: 4400000 | G25: PENDIENTE | H25: AKAI ENERGY LED SRL | I25: =+TODAY()-C25 -> 191 | K25: PORT PLA S.R.L. | L25: 150000000 | M25: =+L25/$L$8 -> 0.0039534065 | O25: =+SUMIF('Reporte de Cheques'!A:A,'Cheques pendientes'!K25,'Reporte de Cheques'!I:I) -> 0 | U25: INC SOCIEDAD ANONIMA | V25: =+SUMIF(H:H,U25,E:E) -> 0
A26: AMOMPY | B26: *MAV041100892 | C26: 45968 | D26: $ | E26: 4400000 | G26: PENDIENTE | H26: AKAI ENERGY LED SRL | I26: =+TODAY()-C26 -> 189 | K26: Maradona Wines | L26: 119500000 | M26: =+L26/$L$8 -> 0.0031495471 | O26: =+SUMIF('Reporte de Cheques'!A:A,'Cheques pendientes'!K26,'Reporte de Cheques'!I:I) -> 0 | V26: =+SUMIF(H:H,U26,E:E) -> 0
A27: AMOMPY | B27: *MAV051100567 | C27: 45971 | D27: $ | E27: 25000000 | G27: PENDIENTE | H27: MERCOL RAUL ALBERTO Y MERCOL MAURICIO EDUARDO. | I27: =+TODAY()-C27 -> 186 | K27: EL GUAYMALLEN SA | L27: 113700000 | M27: =+L27/$L$8 -> 0.0029966821 | O27: =+SUMIF('Reporte de Cheques'!A:A,'Cheques pendientes'!K27,'Reporte de Cheques'!I:I) -> 0 | V27: =+SUMIF(H:H,U27,E:E) -> 0
A28: AMOMPY | B28: *MAV051100566 | C28: 45971 | D28: $ | E28: 37500000 | G28: PREVISIONADO | H28: EL GUAYMALLEN SA | I28: =+TODAY()-C28 -> 186 | K28: FRIGORIFICO GENERAL PICO S A | L28: 70000000 | M28: =+L28/$L$8 -> 0.001844923 | O28: =+SUMIF('Reporte de Cheques'!A:A,'Cheques pendientes'!K28,'Reporte de Cheques'!I:I) -> 0 | V28: =+SUMIF(H:H,U28,E:E) -> 0
A29: AMOMPY | B29: *MAV051100722 | C29: 45971 | D29: $ | E29: 4400000 | G29: PENDIENTE | H29: AKAI ENERGY LED SRL | I29: =+TODAY()-C29 -> 186 | K29: MERCOL RAUL ALBERTO Y MERCOL MAURICIO EDUARDO. | L29: 62500000 | M29: =+L29/$L$8 -> 0.0016472527 | O29: =+SUMIF('Reporte de Cheques'!A:A,'Cheques pendientes'!K29,'Reporte de Cheques'!I:I) -> 0 | V29: =+SUMIF(H:H,U29,E:E) -> 0
A30: AMOMPY | B30: *MAV071100935 | C30: 45972 | D30: $ | E30: 4400000 | G30: PENDIENTE | H30: AKAI ENERGY LED SRL | I30: =+TODAY()-C30 -> 185 | K30: FINEX CABA S. A. | L30: 55300000 | M30: =+L30/$L$8 -> 0.0014574892 | O30: =+SUMIF('Reporte de Cheques'!A:A,'Cheques pendientes'!K30,'Reporte de Cheques'!I:I) -> 0 | V30: =+SUMIF(H:H,U30,E:E) -> 0
A31: AMOMPY | B31: *MAV061100646 | C31: 45972 | D31: $ | E31: 5000000 | G31: PENDIENTE | H31: F G SANITARIOS S R L | I31: =+TODAY()-C31 -> 185 | K31: AKAI ENERGY LED SRL | L31: 44963000 | M31: =+L31/$L$8 -> 0.0011850468 | O31: =+SUMIF('Reporte de Cheques'!A:A,'Cheques pendientes'!K31,'Reporte de Cheques'!I:I) -> 0 | V31: =+SUMIF(H:H,U31,E:E) -> 0
A32: AMOMPY | B32: *MAV111100862 | C32: 45974 | D32: $ | E32: 10000000 | G32: PENDIENTE | H32: COOPERATIVA TAMBERA LAS CAÑITAS LIMITADA | I32: =+TODAY()-C32 -> 183 | K32: F G SANITARIOS S R L | L32: 35000000 | M32: =+L32/$L$8 -> 0.00092246151 | O32: =+SUMIF('Reporte de Cheques'!A:A,'Cheques pendientes'!K32,'Reporte de Cheques'!I:I) -> 0 | V32: =+SUMIF(H:H,U32,E:E) -> 0
A33: AMOMPY | B33: *MAV111100857 | C33: 45974 | D33: $ | E33: 10000000 | G33: PENDIENTE | H33: COOPERATIVA TAMBERA LAS CAÑITAS LIMITADA | I33: =+TODAY()-C33 -> 183 | K33: CONEXION SALUD SRL | L33: 27000000 | M33: =+L33/$L$8 -> 0.00071161316 | O33: =+SUMIF('Reporte de Cheques'!A:A,'Cheques pendientes'!K33,'Reporte de Cheques'!I:I) -> 0 | V33: =+SUMIF(H:H,U33,E:E) -> 0
A34: AMOMPY | B34: *MAV111100890 | C34: 45974 | D34: $ | E34: 963000 | G34: PENDIENTE | H34: AKAI ENERGY LED SRL | I34: =+TODAY()-C34 -> 183 | K34: TRADICION VALORES S.A. | L34: 25000000 | M34: =+L34/$L$8 -> 0.00065890108 | O34: =+SUMIF('Reporte de Cheques'!A:A,'Cheques pendientes'!K34,'Reporte de Cheques'!I:I) -> 0 | V34: =+SUMIF(H:H,U34,E:E) -> 0
A35: AMOMPY | B35: *MAV111100854 | C35: 45974 | D35: $ | E35: 10000000 | G35: PENDIENTE | H35: COOPERATIVA TAMBERA LAS CAÑITAS LIMITADA | I35: =+TODAY()-C35 -> 183 | K35: BUNYAR S.R.L. | L35: 24800000 | M35: =+L35/$L$8 -> 0.00065362987 | O35: =+SUMIF('Reporte de Cheques'!A:A,'Cheques pendientes'!K35,'Reporte de Cheques'!I:I) -> 0
A36: AMOMPY | B36: *MAV111100855 | C36: 45974 | D36: $ | E36: 10000000 | G36: PENDIENTE | H36: COOPERATIVA TAMBERA LAS CAÑITAS LIMITADA | I36: =+TODAY()-C36 -> 183 | K36: MASTER DESIGN HOME SRL | L36: 24000000 | M36: =+L36/$L$8 -> 0.00063254503 | O36: =+SUMIF('Reporte de Cheques'!A:A,'Cheques pendientes'!K36,'Reporte de Cheques'!I:I) -> 0
A37: AMOMPY | B37: *MAV111100856 | C37: 45974 | D37: $ | E37: 10000000 | G37: PENDIENTE | H37: COOPERATIVA TAMBERA LAS CAÑITAS LIMITADA | I37: =+TODAY()-C37 -> 183 | K37: GROCAL S.A. | L37: 15000000 | M37: =+L37/$L$8 -> 0.00039534065 | O37: =+SUMIF('Reporte de Cheques'!A:A,'Cheques pendientes'!K37,'Reporte de Cheques'!I:I) -> 0
A38: AMOMPY | B38: *MAV111100858 | C38: 45974 | D38: $ | E38: 10000000 | G38: PENDIENTE | H38: COOPERATIVA TAMBERA LAS CAÑITAS LIMITADA | I38: =+TODAY()-C38 -> 183 | K38: Paccioli Group Sociedad Anonima | L38: 13958000 | M38: =+L38/$L$8 -> 0.00036787765 | O38: =+SUMIF('Reporte de Cheques'!A:A,'Cheques pendientes'!K38,'Reporte de Cheques'!I:I) -> 0
A39: AMOMPY | B39: *MAV111100859 | C39: 45974 | D39: $ | E39: 10000000 | G39: PENDIENTE | H39: COOPERATIVA TAMBERA LAS CAÑITAS LIMITADA | I39: =+TODAY()-C39 -> 183 | K39: RABU INVERSIONES SRL | L39: 7194300 | M39: =+L39/$L$8 -> 0.00018961328 | O39: =+SUMIF('Reporte de Cheques'!A:A,'Cheques pendientes'!K39,'Reporte de Cheques'!I:I) -> 0
A40: AMOMPY | B40: *MAV111100860 | C40: 45974 | D40: $ | E40: 10000000 | G40: PENDIENTE | H40: COOPERATIVA TAMBERA LAS CAÑITAS LIMITADA | I40: =+TODAY()-C40 -> 183 | K40: UKUMARI SOCIEDAD ANONIMA. | L40: 6812500 | M40: =+L40/$L$8 -> 0.00017955054 | O40: =+SUMIF('Reporte de Cheques'!A:A,'Cheques pendientes'!K40,'Reporte de Cheques'!I:I) -> 0
...

Sheet Concentración
A4: Suma de %
A5: Sociedad de Garantía Recíproca / Librador | B5: Total
A6: CREDICUOTAS CONSUMO SA | B6: 0.050864354
A7: MILLS S.G.R. | B7: 0.044706974
A8: EMOVA MOVILIDAD S.A. | B8: 0.044297684
A9: COOPERATIVA DE VIVIENDA CREDITO Y CONSUMO PARA EL DESARROLLO LIMITADA | B9: 0.043772089
A10: SES SA | B10: 0.038838027
A11: EMPRESA DIST SUR S.A. EDESUR S.A. | B11: 0.03824526
A12: TRANS BOX SRL | B12: 0.031761609
A13: ALLIANCE ONE TOBACCO ARGENTINA | B13: 0.025315676
A14: TARJETA NARANJA SA | B14: 0.025043459
A15: INTEGRA PYMES SGR | B15: 0.023718967
A16: ASOCIACION ATLETICA ARGENTINOS JUNIORS | B16: 0.022789711
A17: Casa Hutton SA | B17: 0.019833211
... A160: Total general | B160: 0.83383783

Sheet Reporte de Cheques
A1: Reporte de Cheques de Pago Diferido | W1: Valor Patrimonial del Fondo
A2: Cheque de Pago Diferido y Pagaré | B2: Moneda | C2: Cheque de Pago Diferido y Pagaré | D2: Fecha | E2: Precio | F2: Tipo de Cambio (Cheque/Fondo) | G2: Moneda Cheque | H2: Moneda Cheque | I2: Moneda Fondo | J2: Moneda Fondo | K2: Compra | L2: Fondo | M2: Compra | N2: Compra | O2: Compra | P2: Compra | Q2: Vendido | R2: Venta | S2: Venta | T2: Venta | U2: Cheque de Pago Diferido y Pagaré | V2: Cheque de Pago Diferido y Pagaré | W2: =+VLOOKUP(W1,'GESTION MOMENTUM'!A:B,2,0) -> 3.7941963e+10
A3: Sociedad de Garantía Recíproca / Librador | B3: Descripción | C3: Fecha de Vencimiento | D3: Fecha | E3: Precio | F3: Tipo de Cambio (Cheque/Fondo) | G3: Importe Nominal | H3: Importe Actual | I3: Importe Nominal | J3: Importe Actual | K3: Nro. de Operación | L3: Nombre | M3: Agente | N3: Fecha Concertación | O3: Fecha Liquidación | P3: Tasa de Descuento | Q3: Vendido | R3: Nro. de Operación | S3: Fecha Concertación | T3: Fecha Liquidación | U3: Abreviatura | V3: Código CAFCI | W3: %
A4: TEXTUM SA | B4: Pesos | C4: 46156 | D4: 14/05/2026 | E4: 1 | G4: 10000000 | H4: 10000000 | I4: 10000000 | J4: 10000000 | K4: 13445369 | L4: AMOMPY | M4: Momentum Capital Investment S.A. | N4: 17/04/2026 | O4: 17/04/2026 | P4: 38 | Q4: No | U4: *MAV120501729 | V4: *MAV120501729 | W4: =+J4/$W$2 -> 0.00026356043
A5: EDITAR SRL | B5: Pesos | C5: 46156 | D5: 14/05/2026 | E5: 1 | G5: 2601958.1 | H5: 2601958.1 | I5: 2601958.1 | J5: 2601958.1 | K5: 123113 | L5: AMOMPY | M5: Momentum Capital Investment S.A. | N5: 17/03/2026 | O5: 17/03/2026 | P5: 43 | Q5: No | U5: *MAV120501493 | V5: *MAV120501493 | W5: =+J5/$W$2 -> 6.857732e-05
A6: TECNOGRAF SA | B6: Pesos | C6: 46156 | D6: 14/05/2026 | E6: 1 | G6: 2778395.1 | H6: 2778395.1 | I6: 2778395.1 | J6: 2778395.1 | K6: 65732098 | L6: AMOMPY | M6: Momentum Capital Investment S.A. | N6: 27/03/2026 | O6: 27/03/2026 | P6: 41 | Q6: No | U6: *MAV120501553 | V6: *MAV120501553 | W6: =+J6/$W$2 -> 7.32275e-05
A7: BROADBANDTECH SA | B7: Pesos | C7: 46156 | D7: 14/05/2026 | E7: 1 | G7: 10000000 | H7: 10000000 | I7: 10000000 | J7: 10000000 | K7: 161 | L7: AMOMPY | M7: Momentum Capital Investment S.A. | N7: 31/03/2026 | O7: 31/03/2026 | P7: 38 | Q7: No | U7: *MAV120501577 | V7: *MAV120501577 | W7: =+J7/$W$2 -> 0.00026356043
A8: PLANTIUM S.A. | B8: Pesos | C8: 46156 | D8: 14/05/2026 | E8: 1 | G8: 5000000 | H8: 5000000 | I8: 5000000 | J8: 5000000 | K8: 60524088 | L8: AMOMPY | M8: Momentum Capital Investment S.A. | N8: 19/03/2026 | O8: 19/03/2026 | P8: 38 | Q8: No | U8: *MAV120501511 | V8: *MAV120501511 | W8: =+J8/$W$2 -> 0.00013178022
A9: PAMPA VIDA S.R.L. | B9: Pesos | C9: 46156 | D9: 14/05/2026 | E9: 1 | G9: 5000000 | H9: 5000000 | I9: 5000000 | J9: 5000000 | K9: 2254 | L9: AMOMPY | M9: Momentum Capital Investment S.A. | N9: 05/03/2026 | O9: 05/03/2026 | P9: 40 | Q9: No | U9: *MAV120501386 | V9: *MAV120501386 | W9: =+J9/$W$2 -> 0.00013178022
A10: MINIGRAF SRL | B10: Pesos | C10: 46156 | D10: 14/05/2026 | E10: 1 | G10: 2714500 | H10: 2714500 | I10: 2714500 | J10: 2714500 | K10: 8838125 | L10: AMOMPY | M10: Momentum Capital Investment S.A. | N10: 17/03/2026 | O10: 17/03/2026 | P10: 43 | Q10: No | U10: *MAV120501494 | V10: *MAV120501494 | W10: =+J10/$W$2 -> 7.1543479e-05
A11: BiBank S.A. | B11: Pesos | C11: 46156 | D11: 14/05/2026 | E11: 1 | G11: 10000000 | H11: 10000000 | I11: 10000000 | J11: 10000000 | K11: 90033755 | L11: AMOMPY | M11: Momentum Capital Investment S.A. | N11: 28/01/2026 | O11: 28/01/2026 | P11: 37 | Q11: No | U11: *BIF120500002 | V11: *BIF120500002 | W11: =+J11/$W$2 -> 0.00026356043
A12: Casa Hutton SA | B12: Pesos | C12: 46156 | D12: 14/05/2026 | E12: 1 | G12: 20000000 | H12: 20000000 | I12: 20000000 | J12: 20000000 | K12: 13237773 | L12: AMOMPY | M12: Momentum Capital Investment S.A. | N12: 03/03/2026 | O12: 03/03/2026 | P12: 43 | Q12: No | U12: *MAV120501374 | V12: *MAV120501374 | W12: =+J12/$W$2 -> 0.00052712086
A13: Movil SGR | B13: Pesos | C13: 46156 | D13: 14/05/2026 | E13: 1 | G13: 1221790.3 | H13: 1221790.3 | I13: 1221790.3 | J13: 1221790.3 | K13: 5719 | L13: AMOMPY | M13: Momentum Capital Investment S.A. | N13: 17/04/2026 | O13: 17/04/2026 | P13: 25 | Q13: No | U13: *MOV120500068 | V13: *MOV120500068 | W13: =+J13/$W$2 -> 3.2201557e-05
A14: Movil SGR | B14: Pesos | C14: 46156 | D14: 14/05/2026 | E14: 1 | G14: 2048050 | H14: 2048050 | I14: 2048050 | J14: 2048050 | K14: 2286 | L14: AMOMPY | M14: Momentum Capital Investment S.A. | N14: 17/04/2026 | O14: 17/04/2026 | P14: 25 | Q14: No | U14: *MOV120500069 | V14: *MOV120500069 | W14: =+J14/$W$2 -> 5.3978494e-05
A15: SA IMP Y EXP DE LA PATAGONIA | B15: Pesos | C15: 46156 | D15: 14/05/2026 | E15: 1 | G15: 86320024 | H15: 86320024 | I15: 86320024 | J15: 86320024 | K15: 304510 | L15: AMOMPY | M15: Momentum Capital Investment S.A. | N15: 17/03/2026 | O15: 17/03/2026 | P15: 43 | Q15: No | U15: *MAV120501495 | V15: *MAV120501495 | W15: =+J15/$W$2 -> 0.0022750543
... A225: I-LED ARGENTINA S.A. | B225: Pesos | C225: 46176 | D225: 14/05/2026 | E225: 0.97960288 | G225: 5450000 | H225: 5338835.7 | I225: 5450000 | J225: 5338835.7 | K225: 28512 | L225: AMOMPY | M225: Momentum Capital Investment S.A. | N225: 08/04/2026 | O225: 08/04/2026 | P225: 38 | Q225: No | U225: *MAV300501529 | V225: *MAV300501529 | W225: =+J225/$W$2 -> 0.00014071058
A226: DEMAGRO SRL | B226: Dolar 3500 | C226: 46176 | D226: 14/05/2026 | E226: 0.99455018 | F226: 1 US3 = 1393,2322905547 $ | G226: 40000 | H226: 39782.01 | I226: 55729292 | J226: 55425581 | K226: 137080 | L226: AMOMPY | M226: Momentum Capital Investment S.A. | N226: 20/01/2026 | O226: 20/01/2026 | P226: 10 | Q226: No | U226: #UMV010660043 | V226: #UMV010660043 | W226: =+J226/$W$2 -> 0.001460799
A227: DANBURY S. A | B227: Pesos | C227: 46176 | D227: 14/05/2026 | E227: 0.97855241 | G227: 39425781 | H227: 38580193 | I227: 39425781 | J227: 38580193 | K227: 66111089 | L227: AMOMPY | M227: Momentum Capital Investment S.A. | N227: 09/04/2026 | O227: 09/04/2026 | P227: 40 | Q227: No | U227: *MAV310501403 | V227: *MAV310501403 | W227: =+J227/$W$2 -> 0.0010168212
A228: DANBURY S. A | B228: Pesos | C228: 46176 | D228: 14/05/2026 | E228: 0.97855241 | G228: 6273580.8 | H228: 6139027.6 | I228: 6273580.8 | J228: 6139027.6 | K228: 66111090 | L228: AMOMPY | M228: Momentum Capital Investment S.A. | N228: 09/04/2026 | O228: 09/04/2026 | P228: 40 | Q228: No | U228: *MAV310501404 | V228: *MAV310501404 | W228: =+J228/$W$2 -> 0.00016180048
A229: AVAL FEDERAL S.G.R. | B229: Pesos | C229: 46176 | D229: 14/05/2026 | E229: 0.98435827 | G229: 30000000 | H229: 29530748 | I229: 30000000 | J229: 29530748 | K229: 90041865 | L229: AMOMPY | M229: Momentum Capital Investment S.A. | N229: 20/04/2026 | O229: 20/04/2026 | P229: 29 | Q229: No | U229: *FED310500139 | V229: *FED310500139 | W229: =+J229/$W$2 -> 0.00077831366
A230: INTEGRA PYMES SGR | B230: Pesos | C230: 46176 | D230: 14/05/2026 | E230: 0.98542127 | G230: 15200000 | H230: 14978403 | I230: 15200000 | J230: 14978403 | K230: 2597 | L230: AMOMPY | M230: Momentum Capital Investment S.A. | N230: 30/04/2026 | O230: 30/04/2026 | P230: 27 | Q230: No | U230: *INP010600019 | V230: *INP010600019 | W230: =+J230/$W$2 -> 0.00039477144
A231: DROGUERIA GARZON SA | B231: Pesos | C231: 46176 | D231: 14/05/2026 | E231: 0.97750404 | G231: 6582395.2 | H231: 6434317.9 | I231: 6582395.2 | J231: 6434317.9 | K231: 5077 | L231: AMOMPY | M231: Momentum Capital Investment S.A. | N231: 17/04/2026 | O231: 17/04/2026 | P231: 42 | Q231: No | U231: *MAV010600936 | V231: *MAV010600936 | W231: =+J231/$W$2 -> 0.00016958316
A232: QUILMES | B232: Pesos | C232: 46176 | D232: 14/05/2026 | E232: 0.98595356 | G232: 7166689.8 | H232: 7066023.3 | I232: 7166689.8 | J232: 7066023.3 | K232: 40011392 | L232: AMOMPY | M232: Momentum Capital Investment S.A. | N232: 10/04/2026 | O232: 10/04/2026 | P232: 26 | Q232: No | U232: *MAV010600896 | V232: *MAV010600896 | W232: =+J232/$W$2 -> 0.00018623241
A233: CUYO AVAL SGR | B233: Pesos | C233: 46176 | D233: 14/05/2026 | E233: 0.98488951 | G233: 8000000 | H233: 7879116.1 | I233: 8000000 | J233: 7879116.1 | K233: 6034637 | L233: AMOMPY | M233: Momentum Capital Investment S.A. | N233: 04/05/2026 | O233: 04/05/2026 | P233: 28 | Q233: No | U233: *CUY010600023 | V233: *CUY010600023 | W233: =+J233/$W$2 -> 0.00020766232
A234: Movil SGR | B234: Pesos | C234: 46176 | D234: 14/05/2026 | E234: 0.9864865 | G234: 696309 | H234: 686899.43 | I234: 696309 | J234: 686899.43 | K234: 18103474 | L234: AMOMPY | M234: Momentum Capital Investment S.A. | N234: 17/04/2026 | O234: 17/04/2026 | P234: 25 | Q234: No | U234: *MOV310500086 | V234: *MOV310500086 | W234: =+J234/$W$2 -> 1.8103951e-05
A235: DOS MATES SA | B235: Pesos | C235: 46176 | D235: 14/05/2026 | E235: 0.98276798 | G235: 45748280 | H235: 44959944 | I235: 45748280 | J235: 44959944 | K235: 7723 | L235: AMOMPY | M235: Momentum Capital Investment S.A. | N235: 13/05/2026 | O235: 13/05/2026 | P235: 32 | Q235: No | U235: *MAV010601240 | V235: *MAV010601240 | W235: =+J235/$W$2 -> 0.0011849662
A236: DOS MATES SA | B236: Pesos | C236: 46176 | D236: 14/05/2026 | E236: 0.98276798 | G236: 45748280 | H236: 44959944 | I236: 45748280 | J236: 44959944 | K236: 8911 | L236: AMOMPY | M236: Momentum Capital Investment S.A. | N236: 13/05/2026 | O236: 13/05/2026 | P236: 32 | Q236: No | U236: *MAV010601241 | V236: *MAV010601241 | W236: =+J236/$W$2 -> 0.0011849662
A237: CELULOSA CAMPANA SA | B237: Pesos | C237: 46176 | D237: 14/05/2026 | E237: 0.97802796 | G237: 10918372 | H237: 10678473 | I237: 10918372 | J237: 10678473 | K237: 30447 | L237: AMOMPY | M237: Momentum Capital Investment S.A. | N237: 01/04/2026 | O237: 01/04/2026 | P237: 41 | Q237: No | U237: *MAV010600842 | V237: *MAV010600842 | W237: =+J237/$W$2 -> 0.00028144229
A238: CELULOSA CAMPANA SA | B238: Pesos | C238: 46176 | D238: 14/05/2026 | E238: 0.97802796 | G238: 11171160 | H238: 10925706 | I238: 11171160 | J238: 10925706 | K238: 30370 | L238: AMOMPY | M238: Momentum Capital Investment S.A. | N238: 01/04/2026 | O238: 01/04/2026 | P238: 41 | Q238: No | U238: *MAV010600843 | V238: *MAV010600843 | W238: =+J238/$W$2 -> 0.00028795839
... A598: DEMAGRO SRL | B598: Pesos | C598: 46206 | D598: 14/05/2026 | E598: 0.95052099 | G598: 22500000 | H598: 21386722 | I598: 22500000 | J598: 21386722 | K598: 65800963 | L598: AMOMPY | M598: Momentum Capital Investment S.A. | N598: 26/03/2026 | O598: 26/03/2026 | P598: 38 | Q598: No | U598: *MAV010701039 | V598: *MAV010701039 | W598: =+J598/$W$2 -> 0.00056366937
A599: DEMAGRO SRL | B599: Dolar 3500 | C599: 46206 | D599: 14/05/2026 | E599: 0.98648655 | F599: 1 US3 = 1393,2322905547 $ | G599: 50000 | H599: 49324.33 | I599: 69661615 | J599: 68720249 | K599: 142720 | L599: AMOMPY | M599: Momentum Capital Investment S.A. | N599: 12/03/2026 | O599: 12/03/2026 | P599: 10 | Q599: No | U599: #UMV010760033 | V599: #UMV010760033 | W599: =+J599/$W$2 -> 0.0018111938
A600: BSP LARTI SA | B600: Dolar 3500 | C600: 46206 | D600: 14/05/2026 | E600: 0.98648635 | F600: 1 US3 = 1393,2322905547 $ | G600: 50000 | H600: 49324.32 | I600: 69661615 | J600: 68720235 | K600: 141980 | L600: AMOMPY | M600: Momentum Capital Investment S.A. | N600: 05/03/2026 | O600: 05/03/2026 | P600: 10 | Q600: No | U600: #UMV010760032 | V600: #UMV010760032 | W600: =+J600/$W$2 -> 0.0018111935
A601: BSP LARTI SA | B601: Dolar 3500 | C601: 46206 | D601: 14/05/2026 | E601: 0.98782135 | F601: 1 US3 = 1393,2322905547 $ | G601: 50000 | H601: 49391.07 | I601: 69661615 | J601: 68813234 | K601: 144915 | L601: AMOMPY | M601: Momentum Capital Investment S.A. | N601: 01/04/2026 | O601: 01/04/2026 | P601: 9 | Q601: No | U601: #UMV010760034 | V601: #UMV010760034 | W601: =+J601/$W$2 -> 0.0018136445
A602: AVAL AR SGR | B602: Pesos | C602: 46206 | D602: 14/05/2026 | E602: 0.96179187 | G602: 15000000 | H602: 14426878 | I602: 15000000 | J602: 14426878 | K602: 801 | L602: AMOMPY | M602: Momentum Capital Investment S.A. | N602: 31/03/2026 | O602: 31/03/2026 | P602: 29 | Q602: No | U602: *AAR010700018 | V602: *AAR010700018 | W602: =+J602/$W$2 -> 0.00038023542
A603: AVAL AR SGR | B603: Pesos | C603: 46206 | D603: 14/05/2026 | E603: 0.96179187 | G603: 12500000 | H603: 12022398 | I603: 12500000 | J603: 12022398 | K603: 28996520 | L603: AMOMPY | M603: Momentum Capital Investment S.A. | N603: 31/03/2026 | O603: 31/03/2026 | P603: 29 | Q603: No | U603: *AAR010700017 | V603: *AAR010700017 | W603: =+J603/$W$2 -> 0.00031686285
A604: VITALCAN S.A. | B604: Pesos | C604: 46206 | D604: 14/05/2026 | E604: 0.95176015 | G604: 100000000 | H604: 95176015 | I604: 100000000 | J604: 95176015 | K604: 7353 | L604: AMOMPY | M604: Momentum Capital Investment S.A. | N604: 31/03/2026 | O604: 31/03/2026 | P604: 37 | Q604: No | U604: *MAV010701052 | V604: *MAV010701052 | W604: =+J604/$W$2 -> 0.0025084631
A605: INTEGRA PYMES SGR | B605: Pesos | C605: 46206 | D605: 14/05/2026 | E605: 0.96179193 | G605: 5000000 | H605: 4808959.6 | I605: 5000000 | J605: 4808959.6 | K605: 16779597 | L605: AMOMPY | M605: Momentum Capital Investment S.A. | N605: 30/04/2026 | O605: 30/04/2026 | P605: 29 | Q605: No | U605: *INP010700054 | V605: *INP010700054 | W605: =+J605/$W$2 -> 0.00012674515
A606: BiBank S.A. | B606: Pesos | C606: 46206 | D606: 14/05/2026 | E606: 0.96306079 | G606: 500000000 | H606: 4.8153039e+08 | I606: 500000000 | J606: 4.8153039e+08 | K606: 147165 | L606: AMOMPY | M606: Momentum Capital Investment S.A. | N606: 23/04/2026 | O606: 23/04/2026 | P606: 28 | Q606: No | U606: #INT020760001 | V606: #INT020760001 | W606: =+J606/$W$2 -> 0.012691236
A607: MILLS S.G.R. | B607: Pesos | C607: 46206 | D607: 14/05/2026 | E607: 0.96433301 | G607: 10000000 | H607: 9643330.1 | I607: 10000000 | J607: 9643330.1 | K607: 32529 | L607: AMOMPY | M607: Momentum Capital Investment S.A. | N607: 27/04/2026 | O607: 27/04/2026 | P607: 27 | Q607: No | U607: *MIL010700023 | V607: *MIL010700023 | W607: =+J607/$W$2 -> 0.00025416002
A608: METALFOR SA | B608: Pesos | C608: 46206 | D608: 14/05/2026 | E608: 0.95300267 | G608: 16500000 | H608: 15724544 | I608: 16500000 | J608: 15724544 | K608: 32225 | L608: AMOMPY | M608: Momentum Capital Investment S.A. | N608: 22/04/2026 | O608: 22/04/2026 | P608: 36 | Q608: No | U608: *MAV010701100 | V608: *MAV010701100 | W608: =+J608/$W$2 -> 0.00041443676
...

Sheet Posicion cuotapartista
A1: Posición de Cuotapartista
A2: Fondo | B2: Cuotapartista | C2: Tipo de Valor Cuotaparte | D2: Cuotapartes | E2: Inversión | F2: Moneda | G2: Fondo | H2: Tipo de Inversor | I2: Fondo | J2: Porcentaje
A3: Nombre | B3: Nombre | F3: Símbolo | G3: Fecha Valor Cuotaparte | I3: Valor Cuotaparte
A4: AMOMPY | B4: ZOFINGEN SECURITIES S.A. (ACDI) | C4: C | D4: 3.3408168e+08 | E4: 5.561765e+08 | F4: $ | G4: 14/05/2026 | H4: Agentes de Colocación y Distribución Integral de FCIs | I4: 1.664792 | J4: 1.9677984
A5: AMOMPY | B5: BANCO DE LA CIUDAD DE BUENOS AIRES | C5: C | D5: 9.1589296e+08 | E5: 1.5247713e+09 | F5: $ | G5: 14/05/2026 | H5: Agentes de Colocación y Distribución Integral de FCIs | I5: 1.664792 | J5: 5.3947667
A6: AMOMPY | B6: MOMENTUM CAPITAL INVESTMENT S.A. (ACDI) | C6: C | D6: 1.5387704e+10 | E6: 2.5617327e+10 | F6: $ | G6: 14/05/2026 | H6: Agentes de Colocación y Distribución Integral de FCIs | I6: 1.664792 | J6: 90.636219
A7: AMOMPY | B7: ALYCBUR S.A. (ACDI) | C7: C | D7: 3.3975516e+08 | E7: 5.6562167e+08 | F7: $ | G7: 14/05/2026 | H7: Agentes de Colocación y Distribución Integral de FCIs | I7: 1.664792 | J7: 2.0012162
A8: AMOMPY | B8: MOMENTUM CAPITAL INVESTMENT S.A. (ACDI) | C8: A | D8: 3.1958101e+09 | E8: 4.4072969e+09 | F8: $ | G8: 14/05/2026 | H8: Agentes de Colocación y Distribución Integral de FCIs | I8: 1.379086 | J8: 87.708343
A9: AMOMPY | B9: ALYCBUR S.A. (ACDI) | C9: A | D9: 4.4786848e+08 | E9: 6.1764916e+08 | F9: $ | G9: 14/05/2026 | H9: Agentes de Colocación y Distribución Integral de FCIs | I9: 1.379086 | J9: 12.291657
A10: AMOMPY | B10: MOMENTUM CAPITAL INVESTMENT S.A. (ACDI) | C10: B | D10: 2.6466364e+09 | E10: 4.3736116e+09 | F10: $ | G10: 14/05/2026 | H10: Agentes de Colocación y Distribución Integral de FCIs | I10: 1.652517 | J10: 93.993105
A11: AMOMPY | B11: ALYCBUR S.A. (ACDI) | C11: B | D11: 1.6914077e+08 | E11: 2.79508e+08 | F11: $ | G11: 14/05/2026 | H11: Agentes de Colocación y Distribución Integral de FCIs | I11: 1.652517 | J11: 6.0068948
D12: 2.343689e+10 | E12: 3.7941962e+10
