Workbook

Sheet GESTION MOMENTUM
A1: FONDOS COMUNES DE INVERSION
A2: 30/9/2026
A3: 10:05:46
A4: Informe de Gestión al 29/9/2026 | K4: MOMENTUM
A5: FCI ABIERTO MOMENTUM PYMES | K5: COMAFI $ Nº 24148/3
A6: Todos los importes están expresados en Pesos | K6: BANCO DEL SOL
C7: (4) | D7: (1) | L7: 46295 | M7: =WORKDAY(L7,1,$R:$R) -> 46296 | N7: =WORKDAY(M7,1,$R:$R) -> 46297 | R7: 45719 | S7: Lista de feriados 2025
A8: ACTIVO | B8: 7.580616e+10 | C8: 100 | K8: Caucion MAV | R8: 45720
A9: INVERSIONES | B9: 7.428339e+10 | C9: 97.99 | D9: 98.76 | K9: Caucion BYMA | R9: 45740
A10: TITULOS PUBLICOS | B10: 1070087272 | C10: 1.41 | D10: 1.42 | K10: Plazo Fijo | L10: =SUMIFS(F:F,A:A,$K$10,B:B,L7) -> 0 | M10: =SUMIFS(G:G,B:B,$K$10,C:C,M7) -> 0 | N10: =SUMIFS(H:H,C:C,$K$10,D:D,N7) -> 0 | R10: 45749
A11: FUTUROS | B11: -3336875500 | C11: -4.4 | D11: -4.44 | K11: Vto. Cheques | L11: =SUMIF($B$100:$B$2570,L7,$D$100:$D$2570) -> 4.8333775e+08 | M11: =SUMIF($B$100:$B$2570,M7,$D$100:$D$2570) -> 3.1391167e+09 | N11: =SUMIF($B$100:$B$2570,N7,$D$100:$D$2570) -> 2.8883542e+09 | P11: =SUMIF($B$99:$B$1908,P7,$D$99:$D$1908) -> 0 | Q11: =SUMIF($B$99:$B$1908,Q7,$D$99:$D$1908) -> 0 | R11: =SUMIF($B$99:$B$1908,R7,$D$99:$D$1908) -> 0 | S11: =SUMIF($B$99:$B$1908,S7,$D$99:$D$1908) -> 0 | T11: =SUMIF($B$99:$B$1908,T7,$D$99:$D$1908) -> 0
A12: DISPONIBILIDADES | B12: 2029277.5 | C12: 0 | D12: 0 | K12: Vto. Pagarés/FCE Dollar Linked | L12: =+SUMIF($B$2574:$B$2618,L7,$F$2574:$F$2618) -> 0 | M12: =+SUMIF($B$2574:$B$2618,M7,$F$2574:$F$2618) -> 0 | N12: =+SUMIF($B$2574:$B$2618,N7,$F$2574:$F$2618) -> 0 | R12: 45778
A13: EN PESOS | B13: 2029338.5 | C13: 0 | D13: 0 | J13: 0.19 | K13: FCI IEB Ahorro - Clase E | L13: =SUMIF(A:A,K13,E:E)*(1+(J13/365*1)) -> 1.6538605e+09 | R13: 45779
A14: EN DOLARES | B14: -60.96 | C14: 0 | D14: 0 | K14: COMAFI $ Nº 24148/3 | L14: =+B13 -> 2029338.5 | R14: 45802
A15: CREDITOS | B15: 1.5207402e+09 | C15: 2.01 | D15: 2.02 | K15: Ctte Momentum | L15: 10853000 | R15: 45824
A16: PASIVO | B16: -5.8747368e+08 | K16: Cheques pendientes | R16: 45828
A17: PROVISIONES | B17: -1.5901604e+08 | K17: Compra/Venta Bonos | R17: 45847
A18: PROV. HONORARIOS SOC. DEPOSITARIA | B18: -9227004.7 | K18: TOTAL | L18: =SUM(L8:L17) -> 2.1500806e+09 | R18: 45884
A19: PROV. HONORARIOS SOCIEDAD GERENTE | B19: -1.3617185e+08 | K19: Neg. Cheques / Pagare | L19: =-1158252548.65 -> -1.1582525e+09 | R19: 45886
A20: PROV. GASTOS SOCIEDAD DEPOSITARIA | B20: -13617185 | K20: Coloca caucion MAV | R20: 45942
A21: DEUDAS EN PESOS | B21: -4.2423421e+08 | K21: Compra/Venta de Bonos | R21: 45982
A22: RESCATES | B22: -51000000 | J22: EGRESOS EN EL DIA Clase B | K22: Suscripciones | R22: 45985
A23: PREVISIÓN INCOBRABLES | B23: -3.7322904e+08 | K23: Rescates | L23: =SUMIF(A:A,K23,B:B) -> -51000000 | R23: 45999
A24: Valor Patrimonial del Fondo | B24: 7.5218686e+10 | K24: Pase | R24: 46016
A25: Liquidez Efectiva (2) | B25: 1.0943118e+09 | D25: 1.45 | K25: Rentas y Amortizaciones
A26: Liquidez Corriente (3) | B26: 9.3529577e+08 | D26: 1.24 | K26: Pago ACDI
K27: Caja cierre | L27: =SUM(L18:L26) -> 9.4082801e+08 | M27: =SUM(M8:M26) -> 3.1391167e+09 | N27: =SUM(N8:N26) -> 2.8883542e+09
A41: Inversiones
A42: TITULO PUBLICO en Pesos
A43: Denominación | B43: IsinCode | C43: Cantidad | D43: Cierre | E43: Total | F43: % (1) | G43: Costo | H43: Var | I43: Vencimiento
A44: Lecap S30N6 | B44: AR0451031345 | C44: 200000000 | D44: 1.2483 | E44: 249656648 | F44: 0.33 | G44: 0 | I44: 30/11/2026
A45: TMG28 - Bono del Tesoro Nacional | B45: AR0175438917 | C45: 600000000 | D45: 1.0768 | E45: 646075548 | F45: 0.86 | G45: 0 | I45: 31/01/2028
C46: 800000000 | E46: 895732196 | F46: 1.19
A48: OBLIGACIONES NEGOCIABLES en Pesos
A49: Denominación | B49: IsinCode | C49: Cantidad | D49: Cierre | E49: Total | F49: % (1) | G49: Costo | H49: Var | I49: Vencimiento
A50: LR8AO - ON Laboratorios Richmond Serie 8 Clase A | B50: AR0266435707 | C50: 300000000 | D50: 1.1029 | E50: 330862383 | F50: 0.44 | G50: 0 | I50: 31/07/2028
A51: MTC3O - ON Mastellone Clase 3 | B51: AR0494875476 | C51: 250000000 | D51: 0.9993 | E51: 249820885 | F51: 0.33 | G51: 1 | H51: -0.07 | I51: 22/06/2027
A52: VBC3O - ON BANCO DE VALORES CL.3 24/10/26 $ | B52: AR0531585807 | C52: 300000000 | D52: 1.1129 | E52: 333868215 | F52: 0.44 | G52: 1 | H52: 11.29 | I52: 24/10/2026
C53: 850000000 | E53: 914551483 | F53: 1.22
A55: FIDEICOMISOS FINANCIEROS en Pesos
...

Sheet Parametros
A1: Min | B1: 0.75 | C1: en Pymes | D1: =+B1*(VLOOKUP($E$1,'GESTION MOMENTUM'!$A$8:$B$32,2,0)) -> 5.6414015e+10 | E1: Valor Patrimonial del Fondo | G1: PN actual | H1: P&L | I1: PN reservado
A2: Max | B2: 0.05 | C2: Money Market | D2: =+B2*(VLOOKUP($E$1,'GESTION MOMENTUM'!$A$8:$B$32,2,0)) -> 3.7609343e+09 | G2: =VLOOKUP(E1,'GESTION MOMENTUM'!A8:B32,2,0) -> 7.5218686e+10 | H2: -0.002 | I2: =+G2*(1+H2) -> 7.5068249e+10
A3: Max | B3: 0.2 | C3: PFRemuneradasCaucion | D3: =+B3*(VLOOKUP($E$1,'GESTION MOMENTUM'!$A$8:$B$32,2,0)) -> 1.5043737e+10 | G3: Money Market | H3: 0.05 | I3: =+I2*H3 -> 3.7534124e+09
A4: Max | B4: 0.2 | C4: cheques x librador | D4: =+B4*(VLOOKUP($E$1,'GESTION MOMENTUM'!$A$8:$B$32,2,0)) -> 1.5043737e+10
A5: Max | B5: 0.25 | C5: x titulo en Pymes | D5: =+B5*(VLOOKUP($E$1,'GESTION MOMENTUM'!$A$8:$B$32,2,0)) -> 1.8804672e+10
B8: Garantías RFX (MOMENTUM)
B9: Bono | C9: VN | D9: Precio | E9: Aforo | F9: $
B10: TMG28 - Bono del Tesoro Nacional | C10: 600000000 | D10: =+VLOOKUP(B10,'GESTION MOMENTUM'!A:D,4,0) -> 1.0768 | E10: 0.8 | F10: =C10*D10*E10 -> 516864000
F11: =C11*D11*E11 -> 0
E13: Garantia | F13: =SUM(F10:F12) -> 516864000
B15: Garantías | C15: Total $ por contrato | D15: Contratos a shortear | E15: Contratos Shorteados | F15: Garantia Requerida
A16: Fut Rofex DLR072026 | B16: Julio | D16: 0 | E16: =_xlfn.IFNA(-VLOOKUP(A16,'GESTION MOMENTUM'!A:C,3,0)/1000,0) -> 0 | F16: =+C16*(E16+D16) -> 0
A17: Fut Rofex DLR082026 | B17: Agosto | D17: 0 | E17: =_xlfn.IFNA(-VLOOKUP(A17,'GESTION MOMENTUM'!A:C,3,0)/1000,0) -> 0 | F17: =+C17*(E17+D17) -> 0
A18: Fut Rofex DLR092026 | B18: Septiembre | C18: 150000 | D18: 0 | E18: =_xlfn.IFNA(-VLOOKUP(A18,'GESTION MOMENTUM'!A:C,3,0)/1000,0) -> 833 | F18: =+C18*(E18+D18) -> 124950000
A19: Fut Rofex DLR102026 | B19: Octubre | C19: 155000 | D19: 0 | E19: =_xlfn.IFNA(-VLOOKUP(A19,'GESTION MOMENTUM'!A:C,3,0)/1000,0) -> 539 | F19: =+C19*(E19+D19) -> 83545000
A20: Fut Rofex DLR112026 | B20: Noviembre | C20: 160000 | D20: 0 | E20: =_xlfn.IFNA(-VLOOKUP(A20,'GESTION MOMENTUM'!A:C,3,0)/1000,0) -> 750 | F20: =+C20*(E20+D20) -> 120000000
A21: Fut Rofex DLR122026 | B21: Diciembre | C21: 165000 | E21: =_xlfn.IFNA(-VLOOKUP(A21,'GESTION MOMENTUM'!A:C,3,0)/1000,0) -> 823 | F21: =+C21*(E21+D21) -> 135795000
D22: 0 | E22: =_xlfn.IFNA(-VLOOKUP(A22,'GESTION MOMENTUM'!A:C,3,0)/1000,0) -> 0 | F22: =+C22*(E22+D22) -> 0
F23: =+SUM(F16:F22) -> 464290000
B24: Saldo de Garantias | C24: =F13-F23 -> 52574000

Sheet Concentración
A4: Suma de %
A5: Sociedad de Garantía Recíproca / Librador | B5: Total
A6: SES SA | B6: 0.050208046
A7: A M F A Y S ASOCIACION MUTUAL | B7: 0.046387313
A8: SIGMA AGRO S.A. | B8: 0.037209423
A9: TRANS BOX SRL | B9: 0.030399207
A10: COOPERATIVA DE VIVIENDA CREDITO Y CONSUMO PARA EL DESARROLLO LIMITADA | B10: 0.025056317
A11: COM & LOG SA | B11: 0.024566633
A12: ESPECIALIDADES AGROPECUARIAS S.A. | B12: 0.023516318
A13: GOBIERNO DE LA CUIDAD DE BUENOS AIRES | B13: 0.021887263
A14: MILLS S.G.R. | B14: 0.021607265
A15: AUTOPISTAS URBANAS SA | B15: 0.021592468
A16: INTEGRA PYMES SGR | B16: 0.018812364
A17: LA MANTOVANA DE SERVICIOS GENERALES SA | B17: 0.017784024
... A396: Total general | B396: 0.91953139

Sheet Cheques pendientes
A1: FONDO | B1: CHPD | C1: VTO | D1: MONEDA | E1: MONTO | F1: MONTO $ | G1: ESTADO | H1: LIBRADOR | I1: DIAS DE MORA
A2: AMOMPY | B2: *MAV030300645 | C2: 45723 | D2: $ | E2: 3406250 | G2: PREVISIONADO | H2: UKUMARI SOCIEDAD ANONIMA. | I2: =+TODAY()-C2 -> 572 | U2: LIBRADORES PENDIENTES
A3: AMOMPY | B3: *MAV100300802 | C3: 45728 | D3: $ | E3: 3406250 | G3: PREVISIONADO | H3: UKUMARI SOCIEDAD ANONIMA. | I3: =+TODAY()-C3 -> 567 | U3: {=+_xlfn.UNIQUE(H2:H78)} -> UKUMARI SOCIEDAD ANONIMA. | V3: =+SUMIF(H:H,U3,E:E) -> 6812500
A4: AMOMPY | B4: *MAV200500842 | C4: 45799 | D4: $ | E4: 129185000 | G4: PENDIENTE | H4: NIRO CONSTRUYE S. A. | I4: =+TODAY()-C4 -> 496 | U4: NIRO CONSTRUYE S. A. | V4: =+SUMIF(H:H,U4,E:E) -> 258370000
A5: AMOMPY | B5: *MAV300500862 | C5: 45811 | D5: $ | E5: 129185000 | G5: PENDIENTE | H5: NIRO CONSTRUYE S. A. | I5: =+TODAY()-C5 -> 484 | U5: MERCOL RAUL ALBERTO Y MERCOL MAURICIO EDUARDO. | V5: =+SUMIF(H:H,U5,E:E) -> 62500000
A6: AMOMPY | B6: *MAV091000727 | C6: 45943 | D6: $ | E6: 12500000 | G6: PENDIENTE | H6: MERCOL RAUL ALBERTO Y MERCOL MAURICIO EDUARDO. | I6: =+TODAY()-C6 -> 352 | U6: AKAI ENERGY LED SRL | V6: =+SUMIF(H:H,U6,E:E) -> 44963000
A7: AMOMPY | B7: *MAV031100940 | C7: 45966 | D7: $ | E7: 4400000 | G7: PENDIENTE | H7: AKAI ENERGY LED SRL | I7: =+TODAY()-C7 -> 329 | U7: FRIGORIFICO GENERAL PICO S A | V7: =+SUMIF(H:H,U7,E:E) -> 70000000
A8: AMOMPY | B8: *MAV041100892 | C8: 45968 | D8: $ | E8: 4400000 | G8: PENDIENTE | H8: AKAI ENERGY LED SRL | I8: =+TODAY()-C8 -> 327 | K8: Valor Patrimonial del Fondo | L8: =+VLOOKUP(K8,'GESTION MOMENTUM'!A:B,2,0) -> 7.5218686e+10 | U8: MIANI CLARA A Y MIANI ADA CLELIA | V8: =+SUMIF(H:H,U8,E:E) -> 3125000
A9: AMOMPY | B9: *MAV051100567 | C9: 45971 | D9: $ | E9: 25000000 | G9: PENDIENTE | H9: MERCOL RAUL ALBERTO Y MERCOL MAURICIO EDUARDO. | I9: =+TODAY()-C9 -> 324 | U9: PORT PLA S.R.L. | V9: =+SUMIF(H:H,U9,E:E) -> 150000000
A10: AMOMPY | B10: *MAV051100722 | C10: 45971 | D10: $ | E10: 4400000 | G10: PENDIENTE | H10: AKAI ENERGY LED SRL | I10: =+TODAY()-C10 -> 324 | L10: $ | M10: % PN | U10: MASTER DESIGN HOME SRL | V10: =+SUMIF(H:H,U10,E:E) -> 24000000
A11: AMOMPY | B11: *MAV071100935 | C11: 45972 | D11: $ | E11: 4400000 | G11: PENDIENTE | H11: AKAI ENERGY LED SRL | I11: =+TODAY()-C11 -> 323 | K11: PREVISIÓN INCOBRABLES | L11: =+VLOOKUP(K11,'GESTION MOMENTUM'!A:B,2,0) -> -3.7322904e+08 | M11: =+L11/L8 -> -0.0049619191 | U11: GROCAL S.A. | V11: =+SUMIF(H:H,U11,E:E) -> 15000000
A12: AMOMPY | B12: *MAV111100890 | C12: 45974 | D12: $ | E12: 963000 | G12: PENDIENTE | H12: AKAI ENERGY LED SRL | I12: =+TODAY()-C12 -> 321 | K12: PREVISIONADO | L12: =+SUMIF(G:G,K12,E:E) -> 100812500 | U12: Paccioli Group Sociedad Anonima | V12: =+SUMIF(H:H,U12,E:E) -> 13958000
A13: AMOMPY | B13: *MAV121100854 | C13: 45975 | D13: $ | E13: 4400000 | G13: PENDIENTE | H13: AKAI ENERGY LED SRL | I13: =+TODAY()-C13 -> 320 | K13: Prevision a aplicar | L13: =+L11+L12 -> -2.7241654e+08 | U13: FINEX CABA S. A. | V13: =+SUMIF(H:H,U13,E:E) -> 55300000
A14: AMOMPY | B14: *MAV121100675 | C14: 45975 | D14: $ | E14: 25000000 | G14: PENDIENTE | H14: MERCOL RAUL ALBERTO Y MERCOL MAURICIO EDUARDO. | I14: =+TODAY()-C14 -> 320 | U14: TRADICION VALORES S.A. | V14: =+SUMIF(H:H,U14,E:E) -> 25000000
A15: AMOMPY | B15: *MAV141101053 | C15: 45979 | D15: $ | E15: 4400000 | G15: PENDIENTE | H15: AKAI ENERGY LED SRL | I15: =+TODAY()-C15 -> 316 | K15: PENDIENTE | L15: =+SUMIF(G:G,K15,E:E)+E2 -> 1.3370253e+09 | M15: =+SUMIF(G:G,K15,E:E)/$L$8 -> 0.01772989 | U15: Maradona Wines | V15: =+SUMIF(H:H,U15,E:E) -> 119500000
A16: AMOMPY | B16: *MAV141101054 | C16: 45979 | D16: $ | E16: 4400000 | G16: PENDIENTE | H16: AKAI ENERGY LED SRL | I16: =+TODAY()-C16 -> 316 | U16: LOPEZ LUCIA SOLEDAD | V16: =+SUMIF(H:H,U16,E:E) -> 995000
A17: AMOMPY | B17: *MAV171100932 | C17: 45980 | D17: $ | E17: 4400000 | G17: PENDIENTE | H17: AKAI ENERGY LED SRL | I17: =+TODAY()-C17 -> 315 | U17: RABU INVERSIONES SRL | V17: =+SUMIF(H:H,U17,E:E) -> 7194300
A18: AMOMPY | B18: *MAV151101337 | C18: 45980 | D18: $ | E18: 4400000 | G18: PENDIENTE | H18: AKAI ENERGY LED SRL | I18: =+TODAY()-C18 -> 315 | U18: GROUP DIEZ S.A. | V18: =+SUMIF(H:H,U18,E:E) -> 425000000
A19: AMOMPY | B19: *MAV181100869 | C19: 45981 | D19: $ | E19: 4400000 | G19: PENDIENTE | H19: AKAI ENERGY LED SRL | I19: =+TODAY()-C19 -> 314 | U19: INVLAC CONSTRUCCIONES S.R.L | V19: =+SUMIF(H:H,U19,E:E) -> 4000000
A20: AMOMPY | B20: *MAV181100773 | C20: 45981 | D20: $ | E20: 20000000 | G20: PREVISIONADO | H20: FRIGORIFICO GENERAL PICO S A | I20: =+TODAY()-C20 -> 314 | K20: LIBRADOR PENDIENTE | L20: $ | M20: % PN | O20: VIGENTE | U20: I-LED ARGENTINA S.A. | V20: =+SUMIF(H:H,U20,E:E) -> 60100000
A21: AMOMPY | B21: *MAV191100661 | C21: 45986 | D21: $ | E21: 20000000 | G21: PREVISIONADO | H21: FRIGORIFICO GENERAL PICO S A | I21: =+TODAY()-C21 -> 309 | K21: {=+_xlfn._xlws.SORT(U3:V34,2,-1)} -> GROUP DIEZ S.A. | L21: 425000000 | M21: =+L21/$L$8 -> 0.0056501917 | O21: =+SUMIF('Reporte de Cheques'!A:A,'Cheques pendientes'!K21,'Reporte de Cheques'!I:I) -> 0 | V21: =+SUMIF(H:H,U21,E:E) -> 0
A22: AMOMPY | B22: *MAV201100887 | C22: 45987 | D22: $ | E22: 10000000 | G22: PREVISIONADO | H22: FRIGORIFICO GENERAL PICO S A | I22: =+TODAY()-C22 -> 308 | K22: NIRO CONSTRUYE S. A. | L22: 258370000 | M22: =+L22/$L$8 -> 0.0034349177 | O22: =+SUMIF('Reporte de Cheques'!A:A,'Cheques pendientes'!K22,'Reporte de Cheques'!I:I) -> 0 | V22: =+SUMIF(H:H,U22,E:E) -> 0
A23: AMOMPY | B23: *MAV211100687 | C23: 45988 | D23: $ | E23: 10000000 | G23: PREVISIONADO | H23: FRIGORIFICO GENERAL PICO S A | I23: =+TODAY()-C23 -> 307 | K23: PORT PLA S.R.L. | L23: 150000000 | M23: =+L23/$L$8 -> 0.0019941853 | O23: =+SUMIF('Reporte de Cheques'!A:A,'Cheques pendientes'!K23,'Reporte de Cheques'!I:I) -> 0 | V23: =+SUMIF(H:H,U23,E:E) -> 0
A24: AMOMPY | B24: *MAV221100992 | C24: 45988 | D24: $ | E24: 10000000 | G24: PREVISIONADO | H24: FRIGORIFICO GENERAL PICO S A | I24: =+TODAY()-C24 -> 307 | K24: Maradona Wines | L24: 119500000 | M24: =+L24/$L$8 -> 0.001588701 | O24: =+SUMIF('Reporte de Cheques'!A:A,'Cheques pendientes'!K24,'Reporte de Cheques'!I:I) -> 0 | V24: =+SUMIF(H:H,U24,E:E) -> 0
A25: AMOMPY | B25: *MAV271100809 | C25: 45992 | D25: $ | E25: 3125000 | G25: PENDIENTE | H25: MIANI CLARA A Y MIANI ADA CLELIA | I25: =+TODAY()-C25 -> 303 | K25: FRIGORIFICO GENERAL PICO S A | L25: 70000000 | M25: =+L25/$L$8 -> 0.00093061982 | O25: =+SUMIF('Reporte de Cheques'!A:A,'Cheques pendientes'!K25,'Reporte de Cheques'!I:I) -> 0 | V25: =+SUMIF(H:H,U25,E:E) -> 0
A26: AMOMPY | B26: *MAV291101201 | C26: 45994 | D26: $ | E26: 25000000 | G26: PENDIENTE | H26: PORT PLA S.R.L. | I26: =+TODAY()-C26 -> 301 | K26: MERCOL RAUL ALBERTO Y MERCOL MAURICIO EDUARDO. | L26: 62500000 | M26: =+L26/$L$8 -> 0.00083091055 | O26: =+SUMIF('Reporte de Cheques'!A:A,'Cheques pendientes'!K26,'Reporte de Cheques'!I:I) -> 0 | V26: =+SUMIF(H:H,U26,E:E) -> 0
A27: AMOMPY | B27: *MAV171200694 | C27: 46010 | D27: $ | E27: 6000000 | G27: PREVISIONADO | H27: MASTER DESIGN HOME SRL | I27: =+TODAY()-C27 -> 285 | K27: I-LED ARGENTINA S.A. | L27: 60100000 | M27: =+L27/$L$8 -> 0.00079900359 | O27: =+SUMIF('Reporte de Cheques'!A:A,'Cheques pendientes'!K27,'Reporte de Cheques'!I:I) -> 33000000 | V27: =+SUMIF(H:H,U27,E:E) -> 0
A28: AMOMPY | B28: *MAV291200938 | C28: 46024 | D28: $ | E28: 25000000 | G28: PENDIENTE | H28: PORT PLA S.R.L. | I28: =+TODAY()-C28 -> 271 | K28: FINEX CABA S. A. | L28: 55300000 | M28: =+L28/$L$8 -> 0.00073518966 | O28: =+SUMIF('Reporte de Cheques'!A:A,'Cheques pendientes'!K28,'Reporte de Cheques'!I:I) -> 0 | V28: =+SUMIF(H:H,U28,E:E) -> 0
A29: AMOMPY | B29: *MAV020100774 | C29: 46028 | D29: $ | E29: 10000000 | G29: PENDIENTE | H29: PORT PLA S.R.L. | I29: =+TODAY()-C29 -> 267 | K29: AKAI ENERGY LED SRL | L29: 44963000 | M29: =+L29/$L$8 -> 0.0005977637 | O29: =+SUMIF('Reporte de Cheques'!A:A,'Cheques pendientes'!K29,'Reporte de Cheques'!I:I) -> 0 | V29: =+SUMIF(H:H,U29,E:E) -> 0
A30: AMOMPY | B30: *MAV311200688 | C30: 46028 | D30: $ | E30: 6000000 | G30: PREVISIONADO | H30: MASTER DESIGN HOME SRL | I30: =+TODAY()-C30 -> 267 | K30: TRADICION VALORES S.A. | L30: 25000000 | M30: =+L30/$L$8 -> 0.00033236422 | O30: =+SUMIF('Reporte de Cheques'!A:A,'Cheques pendientes'!K30,'Reporte de Cheques'!I:I) -> 0 | V30: =+SUMIF(H:H,U30,E:E) -> 0
A31: AMOMPY | B31: *MAV050100914 | C31: 46029 | D31: $ | E31: 10000000 | G31: PENDIENTE | H31: PORT PLA S.R.L. | I31: =+TODAY()-C31 -> 266 | K31: MASTER DESIGN HOME SRL | L31: 24000000 | M31: =+L31/$L$8 -> 0.00031906965 | O31: =+SUMIF('Reporte de Cheques'!A:A,'Cheques pendientes'!K31,'Reporte de Cheques'!I:I) -> 0 | V31: =+SUMIF(H:H,U31,E:E) -> 0
A32: AMOMPY | B32: *MAV090100782 | C32: 46035 | D32: $ | E32: 10000000 | G32: PENDIENTE | H32: PORT PLA S.R.L. | I32: =+TODAY()-C32 -> 260 | K32: GROCAL S.A. | L32: 15000000 | M32: =+L32/$L$8 -> 0.00019941853 | O32: =+SUMIF('Reporte de Cheques'!A:A,'Cheques pendientes'!K32,'Reporte de Cheques'!I:I) -> 0 | V32: =+SUMIF(H:H,U32,E:E) -> 0
A33: AMOMPY | B33: *MAV120100963 | C33: 46036 | D33: $ | E33: 10000000 | G33: PENDIENTE | H33: PORT PLA S.R.L. | I33: =+TODAY()-C33 -> 259 | K33: Paccioli Group Sociedad Anonima | L33: 13958000 | M33: =+L33/$L$8 -> 0.00018556559 | O33: =+SUMIF('Reporte de Cheques'!A:A,'Cheques pendientes'!K33,'Reporte de Cheques'!I:I) -> 0 | V33: =+SUMIF(H:H,U33,E:E) -> 0
A34: AMOMPY | B34: *MAV120101031 | C34: 46036 | D34: $ | E34: 5000000 | G34: PENDIENTE | H34: GROCAL S.A. | I34: =+TODAY()-C34 -> 259 | K34: RABU INVERSIONES SRL | L34: 7194300 | M34: =+L34/$L$8 -> 9.5645116e-05 | O34: =+SUMIF('Reporte de Cheques'!A:A,'Cheques pendientes'!K34,'Reporte de Cheques'!I:I) -> 0 | V34: =+SUMIF(H:H,U34,E:E) -> 0
A35: AMOMPY | B35: *MAV140100871 | C35: 46038 | D35: $ | E35: 5000000 | G35: PENDIENTE | H35: GROCAL S.A. | I35: =+TODAY()-C35 -> 257 | K35: UKUMARI SOCIEDAD ANONIMA. | L35: 6812500 | M35: =+L35/$L$8 -> 9.056925e-05 | O35: =+SUMIF('Reporte de Cheques'!A:A,'Cheques pendientes'!K35,'Reporte de Cheques'!I:I) -> 0
A36: AMOMPY | B36: *MAV160100849 | C36: 46042 | D36: $ | E36: 10000000 | G36: PENDIENTE | H36: PORT PLA S.R.L. | I36: =+TODAY()-C36 -> 253 | K36: INVLAC CONSTRUCCIONES S.R.L | L36: 4000000 | M36: =+L36/$L$8 -> 5.3178275e-05 | O36: =+SUMIF('Reporte de Cheques'!A:A,'Cheques pendientes'!K36,'Reporte de Cheques'!I:I) -> 0
A37: AMOMPY | B37: *MAV160100806 | C37: 46042 | D37: $ | E37: 4000000 | G37: PREVISIONADO | H37: MASTER DESIGN HOME SRL | I37: =+TODAY()-C37 -> 253 | K37: MIANI CLARA A Y MIANI ADA CLELIA | L37: 3125000 | M37: =+L37/$L$8 -> 4.1545528e-05 | O37: =+SUMIF('Reporte de Cheques'!A:A,'Cheques pendientes'!K37,'Reporte de Cheques'!I:I) -> 0
A38: AMOMPY | B38: *MAV190100896 | C38: 46043 | D38: $ | E38: 10000000 | G38: PENDIENTE | H38: PORT PLA S.R.L. | I38: =+TODAY()-C38 -> 252 | K38: LOPEZ LUCIA SOLEDAD | L38: 995000 | M38: =+L38/$L$8 -> 1.3228096e-05 | O38: =+SUMIF('Reporte de Cheques'!A:A,'Cheques pendientes'!K38,'Reporte de Cheques'!I:I) -> 0
A39: AMOMPY | B39: *MAV200101319 | C39: 46044 | D39: $ | E39: 1395800 | G39: PENDIENTE | H39: Paccioli Group Sociedad Anonima | I39: =+TODAY()-C39 -> 251 | K39: 0 | L39: 0 | M39: =+L39/$L$8 -> 0 | O39: =+SUMIF('Reporte de Cheques'!A:A,'Cheques pendientes'!K39,'Reporte de Cheques'!I:I) -> 0
A40: AMOMPY | B40: *MAV200101320 | C40: 46044 | D40: $ | E40: 1395800 | G40: PENDIENTE | H40: Paccioli Group Sociedad Anonima | I40: =+TODAY()-C40 -> 251 | K40: 0 | L40: 0 | M40: =+L40/$L$8 -> 0 | O40: =+SUMIF('Reporte de Cheques'!A:A,'Cheques pendientes'!K40,'Reporte de Cheques'!I:I) -> 0
...

Sheet Reporte de Cheques
A1: Reporte de Cheques de Pago Diferido | W1: Valor Patrimonial del Fondo
A2: Cheque de Pago Diferido y Pagaré | B2: Moneda | C2: Cheque de Pago Diferido y Pagaré | D2: Fecha | E2: Precio | F2: Tipo de Cambio (Cheque/Fondo) | G2: Moneda Cheque | H2: Moneda Cheque | I2: Moneda Fondo | J2: Moneda Fondo | K2: Compra | L2: Fondo | M2: Compra | N2: Compra | O2: Compra | P2: Compra | Q2: Vendido | R2: Venta | S2: Venta | T2: Venta | U2: Cheque de Pago Diferido y Pagaré | V2: Cheque de Pago Diferido y Pagaré | W2: =+VLOOKUP(W1,'GESTION MOMENTUM'!A:B,2,0) -> 7.5218686e+10
A3: Sociedad de Garantía Recíproca / Librador | B3: Descripción | C3: Fecha de Vencimiento | D3: Fecha | E3: Precio | F3: Tipo de Cambio (Cheque/Fondo) | G3: Importe Nominal | H3: Importe Actual | I3: Importe Nominal | J3: Importe Actual | K3: Nro. de Operación | L3: Nombre | M3: Agente | N3: Fecha Concertación | O3: Fecha Liquidación | P3: Tasa de Descuento | Q3: Vendido | R3: Nro. de Operación | S3: Fecha Concertación | T3: Fecha Liquidación | U3: Abreviatura | V3: Código CAFCI | W3: %
A4: PAPEZOPP S.A.S. | B4: Pesos | C4: 46294 | D4: 29/09/2026 | E4: 1 | G4: 2097348.4 | H4: 2097348.4 | I4: 2097348.4 | J4: 2097348.4 | K4: 76510842 | L4: AMOMPY | M4: Momentum Capital Investment S.A. | N4: 22/07/2026 | O4: 22/07/2026 | P4: 32 | Q4: No | U4: *MAV250901366 | V4: *MAV250901366 | W4: =+J4/$W$2 -> 2.7883343e-05
A5: TOYOS CASIMIRO FELIX E HIJOS | B5: Pesos | C5: 46294 | D5: 29/09/2026 | E5: 1 | G5: 12000000 | H5: 12000000 | I5: 12000000 | J5: 12000000 | K5: 29830738 | L5: AMOMPY | M5: Momentum Capital Investment S.A. | N5: 10/08/2026 | O5: 10/08/2026 | P5: 28 | Q5: No | U5: *MAV250901494 | V5: *MAV250901494 | W5: =+J5/$W$2 -> 0.00015953483
A6: Casa Hutton SA | B6: Pesos | C6: 46294 | D6: 29/09/2026 | E6: 1 | G6: 40000000 | H6: 40000000 | I6: 40000000 | J6: 40000000 | K6: 13662791 | L6: AMOMPY | M6: Momentum Capital Investment S.A. | N6: 12/06/2026 | O6: 12/06/2026 | P6: 32 | Q6: No | U6: *MAV250901177 | V6: *MAV250901177 | W6: =+J6/$W$2 -> 0.00053178275
A7: HENDEL HOGAR SA | B7: Pesos | C7: 46294 | D7: 29/09/2026 | E7: 1 | G7: 7560000 | H7: 7560000 | I7: 7560000 | J7: 7560000 | K7: 10537648 | L7: AMOMPY | M7: Momentum Capital Investment S.A. | N7: 10/08/2026 | O7: 10/08/2026 | P7: 28 | Q7: No | U7: *MAV250901491 | V7: *MAV250901491 | W7: =+J7/$W$2 -> 0.00010050694
A8: TRANSPORTES C Y S 2011 SRL | B8: Pesos | C8: 46294 | D8: 29/09/2026 | E8: 1 | G8: 1382744 | H8: 1382744 | I8: 1382744 | J8: 1382744 | K8: 5365 | L8: AMOMPY | M8: Momentum Capital Investment S.A. | N8: 08/09/2026 | O8: 08/09/2026 | P8: 31 | Q8: No | U8: *MAV250901852 | V8: *MAV250901852 | W8: =+J8/$W$2 -> 1.8382985e-05
A9: TRAN SER SA | B9: Pesos | C9: 46294 | D9: 29/09/2026 | E9: 1 | G9: 1509475 | H9: 1509475 | I9: 1509475 | J9: 1509475 | K9: 3848023 | L9: AMOMPY | M9: Momentum Capital Investment S.A. | N9: 15/09/2026 | O9: 15/09/2026 | P9: 32 | Q9: No | U9: *MAV250901938 | V9: *MAV250901938 | W9: =+J9/$W$2 -> 2.0067819e-05
A10: LOS GROBO SGR | B10: Pesos | C10: 46294 | D10: 29/09/2026 | E10: 1 | G10: 4000000 | H10: 4000000 | I10: 4000000 | J10: 4000000 | K10: 16821013 | L10: AMOMPY | M10: Momentum Capital Investment S.A. | N10: 17/07/2026 | O10: 17/07/2026 | P10: 24 | Q10: No | U10: *PRO250900021 | V10: *PRO250900021 | W10: =+J10/$W$2 -> 5.3178275e-05
A11: LOS GROBO SGR | B11: Pesos | C11: 46294 | D11: 29/09/2026 | E11: 1 | G11: 10950000 | H11: 10950000 | I11: 10950000 | J11: 10950000 | K11: 90000869 | L11: AMOMPY | M11: Momentum Capital Investment S.A. | N11: 13/08/2026 | O11: 13/08/2026 | P11: 28 | Q11: No | U11: *PRO250900023 | V11: *PRO250900023 | W11: =+J11/$W$2 -> 0.00014557553
A12: LOS GROBO SGR | B12: Pesos | C12: 46294 | D12: 29/09/2026 | E12: 1 | G12: 20000000 | H12: 20000000 | I12: 20000000 | J12: 20000000 | K12: 67970141 | L12: AMOMPY | M12: Momentum Capital Investment S.A. | N12: 29/06/2026 | O12: 29/06/2026 | P12: 27 | Q12: No | U12: *PRO250900016 | V12: *PRO250900016 | W12: =+J12/$W$2 -> 0.00026589138
A13: GENERAC TECHNOLOGY MANAGEMENT | B13: Pesos | C13: 46294 | D13: 29/09/2026 | E13: 1 | G13: 100000000 | H13: 100000000 | I13: 100000000 | J13: 100000000 | K13: 83 | L13: AMOMPY | M13: Momentum Capital Investment S.A. | N13: 12/08/2026 | O13: 12/08/2026 | P13: 28 | Q13: No | U13: *MAV250901519 | V13: *MAV250901519 | W13: =+J13/$W$2 -> 0.0013294569
A14: MILLS S.G.R. | B14: Pesos | C14: 46294 | D14: 29/09/2026 | E14: 1 | G14: 5000000 | H14: 5000000 | I14: 5000000 | J14: 5000000 | K14: 8743 | L14: AMOMPY | M14: Momentum Capital Investment S.A. | N14: 17/07/2026 | O14: 17/07/2026 | P14: 25 | Q14: No | U14: *MIL250900034 | V14: *MIL250900034 | W14: =+J14/$W$2 -> 6.6472844e-05
A15: MILLS S.G.R. | B15: Pesos | C15: 46294 | D15: 29/09/2026 | E15: 1 | G15: 9000000 | H15: 9000000 | I15: 9000000 | J15: 9000000 | K15: 68958371 | L15: AMOMPY | M15: Momentum Capital Investment S.A. | N15: 14/08/2026 | O15: 14/08/2026 | P15: 28 | Q15: No | U15: *MIL250900037 | V15: *MIL250900037 | W15: =+J15/$W$2 -> 0.00011965112
... A169: TEXTUM SA | B169: Pesos | C169: 46300 | D169: 29/09/2026 | E169: 0.99476729 | G169: 10000000 | H169: 9947672.9 | I169: 10000000 | J169: 9947672.9 | K169: 14422562 | L169: AMOMPY | M169: Momentum Capital Investment S.A. | N169: 01/09/2026 | O169: 01/09/2026 | P169: 32 | Q169: No | U169: *MAV011001420 | V169: *MAV011001420 | W169: =+J169/$W$2 -> 0.00013225002
A170: BSP LARTI SA | B170: Dolar 3500 | C170: 46300 | D170: 29/09/2026 | E170: 0.998359 | F170: 1 US3 = 1523,9697583441 $ | G170: 70000 | H170: 69885.13 | I170: 1.0667788e+08 | J170: 1.0650282e+08 | K170: 163087 | L170: AMOMPY | M170: Momentum Capital Investment S.A. | N170: 31/08/2026 | O170: 31/08/2026 | P170: 10 | Q170: No | U170: #UMV011060031 | V170: #UMV011060031 | W170: =+J170/$W$2 -> 0.0014159091
A171: COOPERATIVA DE TABACALEROS DE JUJUY LTDA | B171: Dolar 3500 | C171: 46300 | D171: 29/09/2026 | E171: 0.9986866 | F171: 1 US3 = 1523,9697583441 $ | G171: 188100 | H171: 187852.95 | I171: 2.8665871e+08 | J171: 2.8628221e+08 | K171: 160721 | L171: AMOMPY | M171: Momentum Capital Investment S.A. | N171: 12/08/2026 | O171: 12/08/2026 | P171: 8 | Q171: No | U171: #UMV011060030 | V171: #UMV011060030 | W171: =+J171/$W$2 -> 0.0038059986
A172: COOPERATIVA DE TABACALEROS DE JUJUY LTDA | B172: Dolar 3500 | C172: 46300 | D172: 29/09/2026 | E172: 0.9988506 | F172: 1 US3 = 1523,9697583441 $ | G172: 50000 | H172: 49942.53 | I172: 76198488 | J172: 76110905 | K172: 150093 | L172: AMOMPY | M172: Momentum Capital Investment S.A. | N172: 15/05/2026 | O172: 15/05/2026 | P172: 7 | Q172: No | U172: #UMV011060013 | V172: #UMV011060013 | W172: =+J172/$W$2 -> 0.0010118617
A173: COOPERATIVA DE TABACALEROS DE JUJUY LTDA | B173: Dolar 3500 | C173: 46300 | D173: 29/09/2026 | E173: 0.9985228 | F173: 1 US3 = 1523,9697583441 $ | G173: 25000 | H173: 24963.07 | I173: 38099244 | J173: 38042964 | K173: 150614 | L173: AMOMPY | M173: Momentum Capital Investment S.A. | N173: 19/05/2026 | O173: 19/05/2026 | P173: 9 | Q173: No | U173: #UMV011060014 | V173: #UMV011060014 | W173: =+J173/$W$2 -> 0.0005057648
A174: ESPECIALIDADES AGROPECUARIAS S.A. | B174: Pesos | C174: 46300 | D174: 29/09/2026 | E174: 0.99476729 | G174: 3000000 | H174: 2984301.9 | I174: 3000000 | J174: 2984301.9 | K174: 1034 | L174: AMOMPY | M174: Momentum Capital Investment S.A. | N174: 25/08/2026 | O174: 25/08/2026 | P174: 32 | Q174: No | U174: *MAV011001354 | V174: *MAV011001354 | W174: =+J174/$W$2 -> 3.9675007e-05
A175: ESPECIALIDADES AGROPECUARIAS S.A. | B175: Pesos | C175: 46300 | D175: 29/09/2026 | E175: 0.99476726 | G175: 2000000 | H175: 1989534.5 | I175: 2000000 | J175: 1989534.5 | K175: 1081 | L175: AMOMPY | M175: Momentum Capital Investment S.A. | N175: 26/08/2026 | O175: 26/08/2026 | P175: 32 | Q175: No | U175: *MAV011001375 | V175: *MAV011001375 | W175: =+J175/$W$2 -> 2.6450003e-05
A176: ESPECIALIDADES AGROPECUARIAS S.A. | B176: Pesos | C176: 46300 | D176: 29/09/2026 | E176: 0.99509272 | G176: 3300000 | H176: 3283806 | I176: 3300000 | J176: 3283806 | K176: 922 | L176: AMOMPY | M176: Momentum Capital Investment S.A. | N176: 11/08/2026 | O176: 11/08/2026 | P176: 30 | Q176: No | U176: *MAV011001284 | V176: *MAV011001284 | W176: =+J176/$W$2 -> 4.3656785e-05
A177: ESPECIALIDADES AGROPECUARIAS S.A. | B177: Pesos | C177: 46300 | D177: 29/09/2026 | E177: 0.99509272 | G177: 2500000 | H177: 2487731.8 | I177: 2500000 | J177: 2487731.8 | K177: 904 | L177: AMOMPY | M177: Momentum Capital Investment S.A. | N177: 07/08/2026 | O177: 07/08/2026 | P177: 30 | Q177: No | U177: *MAV011001237 | V177: *MAV011001237 | W177: =+J177/$W$2 -> 3.3073321e-05
A178: INTEGRA PYMES SGR | B178: Pesos | C178: 46301 | D178: 29/09/2026 | E178: 0.99541837 | G178: 5000000 | H178: 4977091.8 | I178: 5000000 | J178: 4977091.8 | K178: 16831529 | L178: AMOMPY | M178: Momentum Capital Investment S.A. | N178: 21/07/2026 | O178: 21/07/2026 | P178: 24 | Q178: No | U178: *INP021000033 | V178: *INP021000033 | W178: =+J178/$W$2 -> 6.616829e-05
A179: NEXTRANS SRL | B179: Pesos | C179: 46301 | D179: 29/09/2026 | E179: 0.9942795 | G179: 5577023 | H179: 5545119.7 | I179: 5577023 | J179: 5545119.7 | K179: 90017209 | L179: AMOMPY | M179: Momentum Capital Investment S.A. | N179: 11/09/2026 | O179: 11/09/2026 | P179: 30 | Q179: No | U179: *MAV021001538 | V179: *MAV021001538 | W179: =+J179/$W$2 -> 7.3719975e-05
A180: SIGMA AGRO S.A. | B180: Pesos | C180: 46301 | D180: 29/09/2026 | E180: 0.99427949 | G180: 100000000 | H180: 99427949 | I180: 100000000 | J180: 99427949 | K180: 90003952 | L180: AMOMPY | M180: Momentum Capital Investment S.A. | N180: 29/07/2026 | O180: 29/07/2026 | P180: 30 | Q180: No | U180: *MAV021001096 | V180: *MAV021001096 | W180: =+J180/$W$2 -> 0.0013218517
A181: CAL/WEST SEEDS SRL | B181: Dolar Link | C181: 46301 | D181: 29/09/2026 | E181: 0.99713139 | F181: 1 BNA = 1544,9999783700 $ | G181: 6619.93 | H181: 6600.94 | I181: 10227792 | J181: 10198452 | K181: 65 | L181: AMOMPY | M181: Momentum Capital Investment S.A. | N181: 17/09/2026 | O181: 17/09/2026 | P181: 15 | Q181: No | U181: %UZV041000001 | V181: %UZV041000001 | W181: =+J181/$W$2 -> 0.00013558402
A182: ESPECIALIDADES AGROPECUARIAS S.A. | B182: Pesos | C182: 46301 | D182: 29/09/2026 | E182: 0.99390051 | G182: 4000000 | H182: 3975602 | I182: 4000000 | J182: 3975602 | K182: 1144 | L182: AMOMPY | M182: Momentum Capital Investment S.A. | N182: 03/09/2026 | O182: 03/09/2026 | P182: 32 | Q182: No | U182: *MAV021001360 | V182: *MAV021001360 | W182: =+J182/$W$2 -> 5.2853915e-05
A183: ESPECIALIDADES AGROPECUARIAS S.A. | B183: Pesos | C183: 46301 | D183: 29/09/2026 | E183: 0.9942795 | G183: 5000000 | H183: 4971397.5 | I183: 5000000 | J183: 4971397.5 | K183: 1215 | L183: AMOMPY | M183: Momentum Capital Investment S.A. | N183: 11/09/2026 | O183: 11/09/2026 | P183: 30 | Q183: No | U183: *MAV021001525 | V183: *MAV021001525 | W183: =+J183/$W$2 -> 6.6092586e-05
A184: ESPECIALIDADES AGROPECUARIAS S.A. | B184: Pesos | C184: 46301 | D184: 29/09/2026 | E184: 0.99427958 | G184: 5000000 | H184: 4971397.9 | I184: 5000000 | J184: 4971397.9 | K184: 1221 | L184: AMOMPY | M184: Momentum Capital Investment S.A. | N184: 14/09/2026 | O184: 14/09/2026 | P184: 30 | Q184: No | U184: *MAV021001541 | V184: *MAV021001541 | W184: =+J184/$W$2 -> 6.6092592e-05
A185: ESPECIALIDADES AGROPECUARIAS S.A. | B185: Pesos | C185: 46301 | D185: 29/09/2026 | E185: 0.99427954 | G185: 5000000 | H185: 4971397.7 | I185: 5000000 | J185: 4971397.7 | K185: 1225 | L185: AMOMPY | M185: Momentum Capital Investment S.A. | N185: 16/09/2026 | O185: 16/09/2026 | P185: 30 | Q185: No | U185: *MAV021001569 | V185: *MAV021001569 | W185: =+J185/$W$2 -> 6.6092589e-05
A186: ESPECIALIDADES AGROPECUARIAS S.A. | B186: Pesos | C186: 46301 | D186: 29/09/2026 | E186: 0.99390047 | G186: 3000000 | H186: 2981701.4 | I186: 3000000 | J186: 2981701.4 | K186: 1035 | L186: AMOMPY | M186: Momentum Capital Investment S.A. | N186: 25/08/2026 | O186: 25/08/2026 | P186: 32 | Q186: No | U186: *MAV021001284 | V186: *MAV021001284 | W186: =+J186/$W$2 -> 3.9640435e-05
A187: TARJETA NARANJA SA | B187: Pesos | C187: 46301 | D187: 29/09/2026 | E187: 0.99465883 | G187: 8584261 | H187: 8538411 | I187: 8584261 | J187: 8538411 | K187: 629236 | L187: AMOMPY | M187: Momentum Capital Investment S.A. | N187: 10/08/2026 | O187: 10/08/2026 | P187: 28 | Q187: No | U187: *MAV021001181 | V187: *MAV021001181 | W187: =+J187/$W$2 -> 0.00011351449
A188: TARJETA NARANJA SA | B188: Pesos | C188: 46301 | D188: 29/09/2026 | E188: 0.99465883 | G188: 8584261 | H188: 8538411 | I188: 8584261 | J188: 8538411 | K188: 629242 | L188: AMOMPY | M188: Momentum Capital Investment S.A. | N188: 10/08/2026 | O188: 10/08/2026 | P188: 28 | Q188: No | U188: *MAV021001182 | V188: *MAV021001182 | W188: =+J188/$W$2 -> 0.00011351449
A189: TARJETA NARANJA SA | B189: Pesos | C189: 46301 | D189: 29/09/2026 | E189: 0.99465883 | G189: 8584261 | H189: 8538411 | I189: 8584261 | J189: 8538411 | K189: 629234 | L189: AMOMPY | M189: Momentum Capital Investment S.A. | N189: 10/08/2026 | O189: 10/08/2026 | P189: 28 | Q189: No | U189: *MAV021001183 | V189: *MAV021001183 | W189: =+J189/$W$2 -> 0.00011351449
A190: DROGUERIA GARZON SA | B190: Pesos | C190: 46301 | D190: 29/09/2026 | E190: 0.99371117 | G190: 34382424 | H190: 34166199 | I190: 34382424 | J190: 34166199 | K190: 90022563 | L190: AMOMPY | M190: Momentum Capital Investment S.A. | N190: 24/09/2026 | O190: 24/09/2026 | P190: 33 | Q190: No | U190: *MAV021001704 | V190: *MAV021001704 | W190: =+J190/$W$2 -> 0.00045422488
A191: BEROLI SAS | B191: Pesos | C191: 46301 | D191: 29/09/2026 | E191: 0.9942795 | G191: 6150126.3 | H191: 6114944.5 | I191: 6150126.3 | J191: 6114944.5 | K191: 57 | L191: AMOMPY | M191: Momentum Capital Investment S.A. | N191: 11/09/2026 | O191: 11/09/2026 | P191: 30 | Q191: No | U191: *MAV021001539 | V191: *MAV021001539 | W191: =+J191/$W$2 -> 8.1295551e-05
A192: LOS GROBO SGR | B192: Pesos | C192: 46301 | D192: 29/09/2026 | E192: 0.99541837 | G192: 2500000 | H192: 2488545.9 | I192: 2500000 | J192: 2488545.9 | K192: 16821015 | L192: AMOMPY | M192: Momentum Capital Investment S.A. | N192: 17/07/2026 | O192: 17/07/2026 | P192: 24 | Q192: No | U192: *PRO021000009 | V192: *PRO021000009 | W192: =+J192/$W$2 -> 3.3084145e-05
A193: PAMPA VIDA S.R.L. | B193: Pesos | C193: 46301 | D193: 29/09/2026 | E193: 0.99371106 | G193: 5000000 | H193: 4968555.3 | I193: 5000000 | J193: 4968555.3 | K193: 3040 | L193: AMOMPY | M193: Momentum Capital Investment S.A. | N193: 21/07/2026 | O193: 21/07/2026 | P193: 33 | Q193: No | U193: *MAV021001048 | V193: *MAV021001048 | W193: =+J193/$W$2 -> 6.60548e-05
...

Sheet Posicion cuotapartista
A1: Posición de Cuotapartista
A2: Fondo | B2: Cuotapartista | C2: Tipo de Valor Cuotaparte | D2: Cuotapartes | E2: Inversión | F2: Moneda | G2: Fondo | H2: Tipo de Inversor | I2: Fondo | J2: Porcentaje
A3: Nombre | B3: Nombre | F3: Símbolo | G3: Fecha Valor Cuotaparte | I3: Valor Cuotaparte
A4: AMOMPY | B4: ZOFINGEN SECURITIES S.A. (ACDI) | C4: C | D4: 1.4303235e+09 | E4: 2.6192799e+09 | F4: $ | G4: 29/09/2026 | H4: Agentes de Colocación y Distribución Integral de FCIs | I4: 1.83125 | J4: 4.5658608
A5: AMOMPY | B5: BANCO DE LA CIUDAD DE BUENOS AIRES | C5: C | D5: 1.8078341e+09 | E5: 3.3105962e+09 | F5: $ | G5: 29/09/2026 | H5: Agentes de Colocación y Distribución Integral de FCIs | I5: 1.83125 | J5: 5.7709456
A6: AMOMPY | B6: MOMENTUM CAPITAL INVESTMENT S.A. (ACDI) | C6: C | D6: 2.5797363e+10 | E6: 4.724142e+10 | F6: $ | G6: 29/09/2026 | H6: Agentes de Colocación y Distribución Integral de FCIs | I6: 1.83125 | J6: 82.35002
A7: AMOMPY | B7: ALYCBUR S.A. (ACDI) | C7: C | D7: 3.1629211e+08 | E7: 5.7920992e+08 | F7: $ | G7: 29/09/2026 | H7: Agentes de Colocación y Distribución Integral de FCIs | I7: 1.83125 | J7: 1.0096637
A8: AMOMPY | B8: BANCO DE SAN JUAN SA ( ACDI ) | C8: C | D8: 1.683916e+09 | E8: 3.0836712e+09 | F8: $ | G8: 29/09/2026 | H8: Agentes de Colocación y Distribución Integral de FCIs | I8: 1.83125 | J8: 5.3753757
A9: AMOMPY | B9: BANCO DE SANTA CRUZ SA (ACDI) | C9: C | D9: 2.9075177e+08 | E9: 5.3243917e+08 | F9: $ | G9: 29/09/2026 | H9: Agentes de Colocación y Distribución Integral de FCIs | I9: 1.83125 | J9: 0.92813418
A10: AMOMPY | B10: MOMENTUM CAPITAL INVESTMENT S.A. (ACDI) | C10: A | D10: 4.2636536e+09 | E10: 6.467873e+09 | F10: $ | G10: 29/09/2026 | H10: Agentes de Colocación y Distribución Integral de FCIs | I10: 1.516979 | J10: 93.939655
A11: AMOMPY | B11: ALYCBUR S.A. (ACDI) | C11: A | D11: 2.7506183e+08 | E11: 4.1726302e+08 | F11: $ | G11: 29/09/2026 | H11: Agentes de Colocación y Distribución Integral de FCIs | I11: 1.516979 | J11: 6.0603454
A12: AMOMPY | B12: MOMENTUM CAPITAL INVESTMENT S.A. (ACDI) | C12: B | D12: 5.8641128e+09 | E12: 1.0659479e+10 | F12: $ | G12: 29/09/2026 | H12: Agentes de Colocación y Distribución Integral de FCIs | I12: 1.817748 | J12: 97.196525
A13: AMOMPY | B13: ALYCBUR S.A. (ACDI) | C13: B | D13: 1.6914077e+08 | E13: 3.074553e+08 | F13: $ | G13: 29/09/2026 | H13: Agentes de Colocación y Distribución Integral de FCIs | I13: 1.817748 | J13: 2.8034753
D14: 4.1898449e+10 | E14: 7.5218687e+10
